Workbook

Sheet Portada

Sheet Inicio
B2: DustRisk V1
B3: Evaluación y control del riesgo por polvos minerales, metales y humos metálicos
B4: Herramienta gratuita · Sociedad Colombiana de Higienistas Ocupacionales (SCHO) · Autor: Álvaro Araque García (Comité Académico) · Versión 1.0 · 2026
B6: Propósito | C6: Evaluar y controlar la exposición por inhalación a polvos minerales no fibrogénicos, partículas no especificadas (PNOS), metales y humos metálicos: identificación, valoración cualitativa, muestreo por GES y agente, estadística, decisión, mezclas con efecto aditivo, controles, protección respiratoria y vigilancia médica con indicadores biológicos (BEI). Complementa a NeumoRisk (sílice cristalina, carbón y asbesto).
B7: Flujo de trabajo | C7: 1) Agentes y TLV → 2) GES × agente (valoración cualitativa y ajuste del TLV) → 3) Muestreo → 4) Estadística (decisión) → 5) Mezclas (efecto aditivo) → 6) Plan de Control (con Biblioteca) → 7) Protección Respiratoria → 8) Vigilancia Médica y BEI.
B8: Fracciones por tamaño | C8: Cada TLV se expresa en una fracción: inhalable (I, deposición en todo el tracto respiratorio), torácica (T) o respirable (R, región de intercambio gaseoso), según el Apéndice C de la ACGIH e ISO 7708. El muestreador debe corresponder a la fracción del TLV: la hoja Muestreo advierte si no coincide (por ejemplo, el casete cerrado de 37 mm subestima la fracción inhalable).
B9: Criterio de decisión | C9: Estrategia AIHA de evaluación de la exposición: índice de riesgo IR = P95 / TLV ajustado y categoría de control de exposición AIHA: 0 (≤ 1 %), 1 (≤ 10 %), 2 (≤ 50 %), 3 (50–100 %) y 4 (> 100 % del TLV). Con una sola muestra se usa el valor máximo. Validez del GES con DEG ≤ 3,0 (parámetro editable).
B10: Ajuste de jornada | C10: Brief & Scala: factor diario 8/hd·(24−hd)/16 y semanal 40/hs·(168−hs)/128; se aplica el más restrictivo. Nunca se incrementa el TLV para jornadas cortas. No se ajustan los valores techo (C).
B11: Mezclas | C11: Para agentes con el mismo efecto u órgano blanco, medidos en la misma muestra o jornada, se aplica la regla de efectos aditivos de la ACGIH: Σ Cᵢ / TLVᵢ ajustado ≤ 1.
B12: Humos de soldadura | C12: La ACGIH no tiene un TLV único para humos de soldadura: se evalúa cada componente (óxido de hierro, manganeso, cromo hexavalente, níquel, zinc, cobre) con su propio TLV y se aplica la regla de mezclas cuando comparten efecto. La IARC clasifica los humos de soldadura como cancerígenos (Grupo 1): mantener la exposición tan baja como sea posible.
B13: Leyenda de celdas | C13: Amarillo con texto azul: datos que usted diligencia. Gris: cálculo automático (no editar). Las listas desplegables evitan errores de digitación.
B14: Valores límite | C14: TLV y BEI de la ACGIH, edición 2026, editables en la hoja Agentes. Verifíquelos cada año contra la publicación vigente. En Colombia se aplican los valores ACGIH a falta de valores nacionales (Resolución 2400 de 1979).
B15: Advertencia | C15: La herramienta apoya, pero no reemplaza, el criterio del higienista ocupacional con licencia en SST. Las mediciones deben hacerse con métodos validados (NIOSH, OSHA) y laboratorios acreditados ISO/IEC 17025.
B16: Referencias | C16: ACGIH TLVs and BEIs 2026 · AIHA, A Strategy for Assessing and Managing Occupational Exposures · NIOSH Manual of Analytical Methods (0500, 0600, 7300, 7303, 7605) · OSHA 29 CFR 1910.134 · HSE COSHH essentials · Decreto 1072 de 2015 · Res. 2400 de 1979 · Araque G.A., Aerosoles: evaluación y control de la exposición (SCHO).
B18: Datos de la evaluación (ejemplo)
B19: Empresa | C19: Metalmecánica y Materiales del Ejemplo S.A.S.
B20: NIT | C20: 900.111.222-3
B21: Centro de trabajo / ciudad | C21: Planta industrial – Bogotá
B22: Actividad económica | C22: Fabricación de estructuras metálicas, ensacado de cemento y molienda de caolín
B23: Higienista responsable (licencia SST) | C23: Higienista Ocupacional (Lic. SST 0000)
B24: Fecha del estudio | C24: 46287
B25: Laboratorio (acreditación) | C25: Laboratorio acreditado ISO/IEC 17025

Sheet Agentes
A1: 1. Polvos minerales, metales y valores límite permisibles
A2: TLV ACGIH 2026 (8 h/día – 40 h/semana). Columnas F, G y N editables: actualícelas con la publicación ACGIH vigente. Filas amarillas al final para agregar agentes.
A3: DustRisk V1 · Polvos minerales, metales y humos metálicos · SCHO · Celdas amarillas con texto azul = datos a diligenciar; celdas grises = cálculo automático (no editar).
A5: Código | B5: Agente | C5: CAS | D5: Fracción | E5: Unidad | F5: TLV-TWA ACGIH | G5: TLV-STEL / C | H5: Familia | I5: Grupo de efecto (mezclas) | J5: Efecto crítico (base del TLV) | K5: Notaciones | L5: Método de muestreo y análisis | M5: Muestreador y caudal | N5: Indicador biológico (BEI) | O5: Valor BEI | P5: Banda de peligro (VE) | Q5: Vigilancia médica sugerida | R5: Nota
A6: PNOS-I | B6: Partículas insolubles o poco solubles no especificadas (PNOS) – inhalable | C6: — | D6: Inhalable | E6: mg/m³ | F6: 10 | H6: PNOS | I6: Respiratorio – irritación y función pulmonar | J6: Efectos respiratorios inespecíficos (sobrecarga pulmonar) | K6: Apéndice B | L6: NIOSH 0500 (gravimétrico) o MDHS 14/4 (HSE) | M6: IOM inhalable, 2,0 L/min; filtro PVC 25 mm | P6: =IF(F6="","",IF(OR(ISNUMBER(SEARCH("A1",K6)),ISNUMBER(SEARCH("A2",K6)),N(F6)<0.05),4,IF(N(F6)<0.5,3,IF(N(F6)<3,2,1)))) | Q6: Examen periódico; cuestionario de síntomas respiratorios y espirometría si hay exposición sobre el nivel de acción | R6: Apéndice B ACGIH: solo si el polvo no tiene TLV propio, sílice cristalina < 1 % y sin asbesto. Si la sílice es ≥ 1 %, use NeumoRisk.
A7: PNOS-R | B7: Partículas insolubles o poco solubles no especificadas (PNOS) – respirable | C7: — | D7: Respirable | E7: mg/m³ | F7: 3 | H7: PNOS | I7: Respiratorio – neumoconiosis no fibrogénica | J7: Sobrecarga pulmonar e inflamación crónica | K7: Apéndice B | L7: NIOSH 0600 (gravimétrico, fracción respirable) | M7: Ciclón nylon 10 mm, 1,7 L/min; filtro PVC 37 mm 5 µm | P7: =IF(F7="","",IF(OR(ISNUMBER(SEARCH("A1",K7)),ISNUMBER(SEARCH("A2",K7)),N(F7)<0.05),4,IF(N(F7)<0.5,3,IF(N(F7)<3,2,1)))) | Q7: Examen periódico; cuestionario de síntomas respiratorios y espirometría si hay exposición sobre el nivel de acción | R7: Apéndice B ACGIH (valor recomendado).
A8: BASO4 | B8: Sulfato de bario | C8: 7727-43-7 | D8: Inhalable | E8: mg/m³ | F8: 5 | H8: Mineral | I8: Respiratorio – neumoconiosis no fibrogénica | J8: Neumoconiosis (baritosis) | K8: (E) | L8: NIOSH 0500 (gravimétrico) o MDHS 14/4 (HSE) | M8: IOM inhalable, 2,0 L/min; filtro PVC 25 mm | P8: =IF(F8="","",IF(OR(ISNUMBER(SEARCH("A1",K8)),ISNUMBER(SEARCH("A2",K8)),N(F8)<0.05),4,IF(N(F8)<0.5,3,IF(N(F8)<3,2,1)))) | Q8: Examen periódico con énfasis respiratorio y espirometría; Rx de tórax según criterio médico | R8: (E): material sin asbesto y con sílice cristalina < 1 %.
A9: CAO | B9: Óxido de calcio (cal viva) | C9: 1305-78-8 | D9: Total | E9: mg/m³ | F9: 2 | H9: Mineral | I9: Respiratorio – irritación y función pulmonar | J9: Irritación de vías respiratorias superiores (VRS) | K9: — | L9: NIOSH 0500 (gravimétrico, polvo total) | M9: Casete 37 mm cerrado, 1,5–2 L/min; filtro PVC | P9: =IF(F9="","",IF(OR(ISNUMBER(SEARCH("A1",K9)),ISNUMBER(SEARCH("A2",K9)),N(F9)<0.05),4,IF(N(F9)<0.5,3,IF(N(F9)<3,2,1)))) | Q9: Examen periódico; cuestionario de síntomas respiratorios y espirometría si hay exposición sobre el nivel de acción
A10: CAOH2 | B10: Hidróxido de calcio (cal apagada) | C10: 1305-62-0 | D10: Total | E10: mg/m³ | F10: 5 | H10: Mineral | I10: Respiratorio – irritación y función pulmonar | J10: Irritación de ojos, VRS y piel | K10: — | L10: NIOSH 0500 (gravimétrico, polvo total) | M10: Casete 37 mm cerrado, 1,5–2 L/min; filtro PVC | P10: =IF(F10="","",IF(OR(ISNUMBER(SEARCH("A1",K10)),ISNUMBER(SEARCH("A2",K10)),N(F10)<0.05),4,IF(N(F10)<0.5,3,IF(N(F10)<3,2,1)))) | Q10: Examen periódico; cuestionario de síntomas respiratorios y espirometría si hay exposición sobre el nivel de acción
A11: CASO4 | B11: Sulfato de calcio (yeso) | C11: 7778-18-9 | D11: Inhalable | E11: mg/m³ | F11: 10 | H11: Mineral | I11: Respiratorio – irritación y función pulmonar | J11: Síntomas nasales | K11: — | L11: NIOSH 0500 (gravimétrico) o MDHS 14/4 (HSE) | M11: IOM inhalable, 2,0 L/min; filtro PVC 25 mm | P11: =IF(F11="","",IF(OR(ISNUMBER(SEARCH("A1",K11)),ISNUMBER(SEARCH("A2",K11)),N(F11)<0.05),4,IF(N(F11)<0.5,3,IF(N(F11)<3,2,1)))) | Q11: Examen periódico; cuestionario de síntomas respiratorios y espirometría si hay exposición sobre el nivel de acción
A12: WOL | B12: Silicato de calcio – wollastonita | C12: 13983-17-0 | D12: Inhalable | E12: mg/m³ | F12: 1 | H12: Mineral | I12: Respiratorio – neumoconiosis no fibrogénica | J12: Neumoconiosis; función pulmonar | K12: A4 (E) | L12: NIOSH 0500 (gravimétrico) o MDHS 14/4 (HSE) | M12: IOM inhalable, 2,0 L/min; filtro PVC 25 mm | P12: =IF(F12="","",IF(OR(ISNUMBER(SEARCH("A1",K12)),ISNUMBER(SEARCH("A2",K12)),N(F12)<0.05),4,IF(N(F12)<0.5,3,IF(N(F12)<3,2,1)))) | Q12: Examen periódico con énfasis respiratorio y espirometría; Rx de tórax según criterio médico
A13: CEM | B13: Cemento Portland | C13: 65997-15-1 | D13: Respirable | E13: mg/m³ | F13: 1 | H13: Mineral | I13: Respiratorio – irritación y función pulmonar | J13: Función pulmonar; síntomas respiratorios; asma | K13: A4 (E) | L13: NIOSH 0600 (gravimétrico, fracción respirable) | M13: Ciclón nylon 10 mm, 1,7 L/min; filtro PVC 37 mm 5 µm | P13: =IF(F13="","",IF(OR(ISNUMBER(SEARCH("A1",K13)),ISNUMBER(SEARCH("A2",K13)),N(F13)<0.05),4,IF(N(F13)<0.5,3,IF(N(F13)<3,2,1)))) | Q13: Examen periódico con énfasis respiratorio y espirometría; Rx de tórax según criterio médico; valorar dermatitis por cromo
A14: GRAF | B14: Grafito (todas las formas excepto fibras) | C14: 7782-42-5 | D14: Respirable | E14: mg/m³ | F14: 2 | H14: Mineral | I14: Respiratorio – neumoconiosis no fibrogénica | J14: Neumoconiosis | K14: — | L14: NIOSH 0600 (gravimétrico, fracción respirable) | M14: Ciclón nylon 10 mm, 1,7 L/min; filtro PVC 37 mm 5 µm | P14: =IF(F14="","",IF(OR(ISNUMBER(SEARCH("A1",K14)),ISNUMBER(SEARCH("A2",K14)),N(F14)<0.05),4,IF(N(F14)<0.5,3,IF(N(F14)<3,2,1)))) | Q14: Examen periódico con énfasis respiratorio y espirometría; Rx de tórax según criterio médico
A15: KAO | B15: Caolín | C15: 1332-58-7 | D15: Respirable | E15: mg/m³ | F15: 2 | H15: Mineral | I15: Respiratorio – neumoconiosis no fibrogénica | J15: Neumoconiosis | K15: A4 (E) | L15: NIOSH 0600 (gravimétrico, fracción respirable) | M15: Ciclón nylon 10 mm, 1,7 L/min; filtro PVC 37 mm 5 µm | P15: =IF(F15="","",IF(OR(ISNUMBER(SEARCH("A1",K15)),ISNUMBER(SEARCH("A2",K15)),N(F15)<0.05),4,IF(N(F15)<0.5,3,IF(N(F15)<3,2,1)))) | Q15: Examen periódico con énfasis respiratorio y espirometría; Rx de tórax según criterio médico
A16: MICA | B16: Mica | C16: 12001-26-2 | D16: Respirable | E16: mg/m³ | F16: 0.1 | H16: Mineral | I16: Respiratorio – neumoconiosis no fibrogénica | J16: Neumoconiosis | K16: — | L16: NIOSH 0600 (gravimétrico, fracción respirable) | M16: Ciclón nylon 10 mm, 1,7 L/min; filtro PVC 37 mm 5 µm | P16: =IF(F16="","",IF(OR(ISNUMBER(SEARCH("A1",K16)),ISNUMBER(SEARCH("A2",K16)),N(F16)<0.05),4,IF(N(F16)<0.5,3,IF(N(F16)<3,2,1)))) | Q16: Examen periódico con énfasis respiratorio y espirometría; Rx de tórax según criterio médico
A17: TALCO | B17: Talco sin fibras de asbesto | C17: 14807-96-6 | D17: Respirable | E17: mg/m³ | F17: 2 | H17: Mineral | I17: Respiratorio – neumoconiosis no fibrogénica | J17: Fibrosis pulmonar; función pulmonar | K17: A4 (E) | L17: NIOSH 0600 (gravimétrico, fracción respirable) | M17: Ciclón nylon 10 mm, 1,7 L/min; filtro PVC 37 mm 5 µm | P17: =IF(F17="","",IF(OR(ISNUMBER(SEARCH("A1",K17)),ISNUMBER(SEARCH("A2",K17)),N(F17)<0.05),4,IF(N(F17)<0.5,3,IF(N(F17)<3,2,1)))) | Q17: Examen periódico con énfasis respiratorio y espirometría; Rx de tórax según criterio médico | R17: Si contiene fibras de asbesto, use el TLV de asbesto (NeumoRisk).
A18: SIC-I | B18: Carburo de silicio no fibroso – inhalable | C18: 409-21-2 | D18: Inhalable | E18: mg/m³ | F18: 10 | H18: Mineral | I18: Respiratorio – neumoconiosis no fibrogénica | J18: Daño pulmonar | K18: — | L18: NIOSH 0500 (gravimétrico) o MDHS 14/4 (HSE) | M18: IOM inhalable, 2,0 L/min; filtro PVC 25 mm | P18: =IF(F18="","",IF(OR(ISNUMBER(SEARCH("A1",K18)),ISNUMBER(SEARCH("A2",K18)),N(F18)<0.05),4,IF(N(F18)<0.5,3,IF(N(F18)<3,2,1)))) | Q18: Examen periódico con énfasis respiratorio y espirometría; Rx de tórax según criterio médico | R18: La forma fibrosa (whiskers) tiene TLV de 0,1 f/cc y es A2.
A19: SIC-R | B19: Carburo de silicio no fibroso – respirable | C19: 409-21-2 | D19: Respirable | E19: mg/m³ | F19: 3 | H19: Mineral | I19: Respiratorio – neumoconiosis no fibrogénica | J19: Daño pulmonar | K19: — | L19: NIOSH 0600 (gravimétrico, fracción respirable) | M19: Ciclón nylon 10 mm, 1,7 L/min; filtro PVC 37 mm 5 µm | P19: =IF(F19="","",IF(OR(ISNUMBER(SEARCH("A1",K19)),ISNUMBER(SEARCH("A2",K19)),N(F19)<0.05),4,IF(N(F19)<0.5,3,IF(N(F19)<3,2,1)))) | Q19: Examen periódico con énfasis respiratorio y espirometría; Rx de tórax según criterio médico
A20: TIO2 | B20: Dióxido de titanio – partículas de escala fina | C20: 13463-67-7 | D20: Respirable | E20: mg/m³ | F20: 2.5 | H20: Mineral | I20: Respiratorio – neumoconiosis no fibrogénica | J20: Irritación de vías respiratorias inferiores; neumoconiosis | K20: A3 | L20: NIOSH 0600 (gravimétrico, fracción respirable) | M20: Ciclón nylon 10 mm, 1,7 L/min; filtro PVC 37 mm 5 µm | P20: =IF(F20="","",IF(OR(ISNUMBER(SEARCH("A1",K20)),ISNUMBER(SEARCH("A2",K20)),N(F20)<0.05),4,IF(N(F20)<0.5,3,IF(N(F20)<3,2,1)))) | Q20: Examen periódico con énfasis respiratorio y espirometría; Rx de tórax según criterio médico | R20: Partículas de escala nanométrica: 0,2 mg/m³ (R).
A21: AL | B21: Aluminio metálico y compuestos insolubles | C21: 7429-90-5 | D21: Respirable | E21: mg/m³ | F21: 1 | H21: Metal | I21: Respiratorio – neumoconiosis no fibrogénica | J21: Neumoconiosis; irritación de VRI; neurotoxicidad | K21: A4 | L21: NIOSH 7303 / 7300 (ICP-AES) sobre muestra respirable | M21: Ciclón nylon 10 mm, 1,7 L/min; filtro MCE 0,8 µm | P21: =IF(F21="","",IF(OR(ISNUMBER(SEARCH("A1",K21)),ISNUMBER(SEARCH("A2",K21)),N(F21)<0.05),4,IF(N(F21)<0.5,3,IF(N(F21)<3,2,1)))) | Q21: Examen periódico con énfasis respiratorio y espirometría; Rx de tórax según criterio médico
A22: FE2O3 | B22: Óxido de hierro (Fe₂O₃) | C22: 1309-37-1 | D22: Respirable | E22: mg/m³ | F22: 5 | H22: Metal | I22: Respiratorio – neumoconiosis no fibrogénica | J22: Neumoconiosis (siderosis) | K22: A4 | L22: NIOSH 7303 / 7300 (ICP-AES) sobre muestra respirable | M22: Ciclón nylon 10 mm, 1,7 L/min; filtro MCE 0,8 µm | P22: =IF(F22="","",IF(OR(ISNUMBER(SEARCH("A1",K22)),ISNUMBER(SEARCH("A2",K22)),N(F22)<0.05),4,IF(N(F22)<0.5,3,IF(N(F22)<3,2,1)))) | Q22: Examen periódico con énfasis respiratorio y espirometría; Rx de tórax según criterio médico | R22: Componente principal de los humos de soldadura de acero al carbono.
A23: MN-R | B23: Manganeso, elemental y compuestos inorgánicos – respirable | C23: 7439-96-5 | D23: Respirable | E23: mg/m³ | F23: 0.02 | H23: Metal | I23: Sistema nervioso central | J23: Alteración del sistema nervioso central | K23: A4 | L23: NIOSH 7303 / 7300 (ICP-AES) sobre muestra respirable | M23: Ciclón nylon 10 mm, 1,7 L/min; filtro MCE 0,8 µm | P23: =IF(F23="","",IF(OR(ISNUMBER(SEARCH("A1",K23)),ISNUMBER(SEARCH("A2",K23)),N(F23)<0.05),4,IF(N(F23)<0.5,3,IF(N(F23)<3,2,1)))) | Q23: Examen neurológico periódico (temblor, alteraciones de la marcha, cuestionario neuroconductual) | R23: Soldadura, aceros al manganeso, ferroaleaciones. Evaluar en el mismo filtro que el óxido de hierro.
A24: MN-I | B24: Manganeso, elemental y compuestos inorgánicos – inhalable | C24: 7439-96-5 | D24: Inhalable | E24: mg/m³ | F24: 0.1 | H24: Metal | I24: Sistema nervioso central | J24: Alteración del sistema nervioso central | K24: A4 | L24: NIOSH 7303 / 7300 (ICP-AES) u OSHA ID-125G; laboratorio acreditado | M24: IOM inhalable, 2,0 L/min; filtro MCE 0,8 µm (humos: casete abierto bajo la careta) | P24: =IF(F24="","",IF(OR(ISNUMBER(SEARCH("A1",K24)),ISNUMBER(SEARCH("A2",K24)),N(F24)<0.05),4,IF(N(F24)<0.5,3,IF(N(F24)<3,2,1)))) | Q24: Examen neurológico periódico (temblor, alteraciones de la marcha, cuestionario neuroconductual)
A25: PB | B25: Plomo y compuestos inorgánicos, como Pb | C25: 7439-92-1 | D25: Total | E25: mg/m³ | F25: 0.05 | H25: Metal | I25: Hematológico y renal | J25: Alteración del SNC y SNP; efectos hematológicos | K25: A3; BEI | L25: NIOSH 7303 / 7300 (ICP-AES) | M25: Casete 37 mm, 2 L/min; filtro MCE 0,8 µm | N25: Plomo en sangre (µg/L) | O25: 200 | P25: =IF(F25="","",IF(OR(ISNUMBER(SEARCH("A1",K25)),ISNUMBER(SEARCH("A2",K25)),N(F25)<0.05),4,IF(N(F25)<0.5,3,IF(N(F25)<3,2,1)))) | Q25: Plombemia periódica; hemograma; función renal; examen neurológico. Asesorar a trabajadoras en edad fértil.
A26: CD | B26: Cadmio y compuestos, como Cd | C26: 7440-43-9 | D26: Total | E26: mg/m³ | F26: 0.01 | H26: Metal carcinógeno | I26: Hematológico y renal | J26: Daño renal | K26: A2; BEI | L26: NIOSH 7303 / 7300 (ICP-AES) | M26: Casete 37 mm, 2 L/min; filtro MCE 0,8 µm | N26: Cadmio en orina (µg/g creatinina) | O26: 5 | P26: =IF(F26="","",IF(OR(ISNUMBER(SEARCH("A1",K26)),ISNUMBER(SEARCH("A2",K26)),N(F26)<0.05),4,IF(N(F26)<0.5,3,IF(N(F26)<3,2,1)))) | Q26: Cadmio en orina o sangre; función renal (β2-microglobulina); espirometría | R26: Fracción respirable: 0,002 mg/m³ (R).
A27: CD-R | B27: Cadmio y compuestos, como Cd – respirable | C27: 7440-43-9 | D27: Respirable | E27: mg/m³ | F27: 0.002 | H27: Metal carcinógeno | I27: Hematológico y renal | J27: Daño renal | K27: A2; BEI | L27: NIOSH 7303 / 7300 (ICP-AES) sobre muestra respirable | M27: Ciclón nylon 10 mm, 1,7 L/min; filtro MCE 0,8 µm | N27: Cadmio en orina (µg/g creatinina) | O27: 5 | P27: =IF(F27="","",IF(OR(ISNUMBER(SEARCH("A1",K27)),ISNUMBER(SEARCH("A2",K27)),N(F27)<0.05),4,IF(N(F27)<0.5,3,IF(N(F27)<3,2,1)))) | Q27: Cadmio en orina o sangre; función renal (β2-microglobulina); espirometría
A28: CR0 | B28: Cromo metálico, como Cr(0) | C28: 7440-47-3 | D28: Inhalable | E28: mg/m³ | F28: 0.5 | H28: Metal | I28: Respiratorio – irritación y función pulmonar | J28: Irritación del tracto respiratorio | K28: — | L28: NIOSH 7303 / 7300 (ICP-AES) u OSHA ID-125G; laboratorio acreditado | M28: IOM inhalable, 2,0 L/min; filtro MCE 0,8 µm (humos: casete abierto bajo la careta) | P28: =IF(F28="","",IF(OR(ISNUMBER(SEARCH("A1",K28)),ISNUMBER(SEARCH("A2",K28)),N(F28)<0.05),4,IF(N(F28)<0.5,3,IF(N(F28)<3,2,1)))) | Q28: Examen periódico; cuestionario de síntomas respiratorios y espirometría si hay exposición sobre el nivel de acción
A29: CR3 | B29: Compuestos de cromo trivalente, como Cr(III) | C29: 7440-47-3 | D29: Inhalable | E29: mg/m³ | F29: 0.003 | H29: Metal | I29: Sensibilización (piel o respiratoria) | J29: Irritación respiratoria; asma | K29: A4; DSEN y RSEN (solubles) | L29: NIOSH 7303 / 7300 (ICP-AES) u OSHA ID-125G; laboratorio acreditado | M29: IOM inhalable, 2,0 L/min; filtro MCE 0,8 µm (humos: casete abierto bajo la careta) | P29: =IF(F29="","",IF(OR(ISNUMBER(SEARCH("A1",K29)),ISNUMBER(SEARCH("A2",K29)),N(F29)<0.05),4,IF(N(F29)<0.5,3,IF(N(F29)<3,2,1)))) | Q29: Cuestionario de asma; espirometría; examen de piel
A30: CR6 | B30: Compuestos de cromo hexavalente, como Cr(VI) | C30: 18540-29-9 | D30: Inhalable | E30: mg/m³ | F30: 0.0002 | G30: 0.0005 | H30: Metal carcinógeno | I30: Cáncer de pulmón | J30: Cáncer de pulmón y senonasal; irritación respiratoria; asma | K30: A1; DSEN; RSEN; BEI | L30: NIOSH 7605 u OSHA ID-215 (cromatografía iónica) | M30: IOM inhalable, 2,0 L/min; filtro PVC 5 µm | N30: Cromo total en orina (µg/L) – valor poblacional (Pop) | O30: 0.7 | P30: =IF(F30="","",IF(OR(ISNUMBER(SEARCH("A1",K30)),ISNUMBER(SEARCH("A2",K30)),N(F30)<0.05),4,IF(N(F30)<0.5,3,IF(N(F30)<3,2,1)))) | Q30: Examen de tabique nasal y piel; espirometría; cromo en orina (valor poblacional) | R30: Soldadura y corte de acero inoxidable, cromado, pigmentos. Carcinógeno: mantener la exposición tan baja como sea posible.
A31: NI-E | B31: Níquel elemental | C31: 7440-02-0 | D31: Inhalable | E31: mg/m³ | F31: 1.5 | H31: Metal | I31: Respiratorio – neumoconiosis no fibrogénica | J31: Dermatitis; neumoconiosis | K31: A5; BEI | L31: NIOSH 7303 / 7300 (ICP-AES) u OSHA ID-125G; laboratorio acreditado | M31: IOM inhalable, 2,0 L/min; filtro MCE 0,8 µm (humos: casete abierto bajo la careta) | N31: Níquel en orina (µg/L) | O31: 5 | P31: =IF(F31="","",IF(OR(ISNUMBER(SEARCH("A1",K31)),ISNUMBER(SEARCH("A2",K31)),N(F31)<0.05),4,IF(N(F31)<0.5,3,IF(N(F31)<3,2,1)))) | Q31: Níquel en orina; examen de piel; espirometría
A32: NI-S | B32: Níquel, compuestos inorgánicos solubles, como Ni | C32: 7440-02-0 | D32: Inhalable | E32: mg/m³ | F32: 0.1 | H32: Metal | I32: Respiratorio – irritación y función pulmonar | J32: Daño pulmonar; cáncer nasal | K32: A4; BEI | L32: NIOSH 7303 / 7300 (ICP-AES) u OSHA ID-125G; laboratorio acreditado | M32: IOM inhalable, 2,0 L/min; filtro MCE 0,8 µm (humos: casete abierto bajo la careta) | N32: Níquel en orina (µg/L) | O32: 30 | P32: =IF(F32="","",IF(OR(ISNUMBER(SEARCH("A1",K32)),ISNUMBER(SEARCH("A2",K32)),N(F32)<0.05),4,IF(N(F32)<0.5,3,IF(N(F32)<3,2,1)))) | Q32: Níquel en orina; examen nasal y de piel; espirometría
A33: NI-I | B33: Níquel, compuestos inorgánicos insolubles, como Ni | C33: 7440-02-0 | D33: Inhalable | E33: mg/m³ | F33: 0.2 | H33: Metal carcinógeno | I33: Cáncer de pulmón | J33: Cáncer de pulmón | K33: A1; BEI | L33: NIOSH 7303 / 7300 (ICP-AES) u OSHA ID-125G; laboratorio acreditado | M33: IOM inhalable, 2,0 L/min; filtro MCE 0,8 µm (humos: casete abierto bajo la careta) | N33: Níquel en orina (µg/L) | O33: 5 | P33: =IF(F33="","",IF(OR(ISNUMBER(SEARCH("A1",K33)),ISNUMBER(SEARCH("A2",K33)),N(F33)<0.05),4,IF(N(F33)<0.5,3,IF(N(F33)<3,2,1)))) | Q33: Níquel en orina; examen de piel; espirometría y vigilancia respiratoria
A34: CO | B34: Cobalto y compuestos inorgánicos, como Co | C34: 7440-48-4 | D34: Inhalable | E34: mg/m³ | F34: 0.02 | H34: Metal | I34: Sensibilización (piel o respiratoria) | J34: Cambios en la función pulmonar | K34: A3; DSEN; RSEN; BEI | L34: NIOSH 7303 / 7300 (ICP-AES) u OSHA ID-125G; laboratorio acreditado | M34: IOM inhalable, 2,0 L/min; filtro MCE 0,8 µm (humos: casete abierto bajo la careta) | N34: Cobalto en orina (µg/L) | O34: 15 | P34: =IF(F34="","",IF(OR(ISNUMBER(SEARCH("A1",K34)),ISNUMBER(SEARCH("A2",K34)),N(F34)<0.05),4,IF(N(F34)<0.5,3,IF(N(F34)<3,2,1)))) | Q34: Cobalto en orina; cuestionario de asma; espirometría
A35: METDUR | B35: Metales duros con cobalto y carburo de tungsteno, como Co | C35: 12070-12-1 | D35: Torácica | E35: mg/m³ | F35: 0.005 | H35: Metal carcinógeno | I35: Sensibilización (piel o respiratoria) | J35: Neumonitis (enfermedad por metales duros) | K35: A2; RSEN | L35: NIOSH 7303 (ICP-AES) sobre muestra torácica | M35: Selector torácico, según fabricante; filtro MCE | P35: =IF(F35="","",IF(OR(ISNUMBER(SEARCH("A1",K35)),ISNUMBER(SEARCH("A2",K35)),N(F35)<0.05),4,IF(N(F35)<0.5,3,IF(N(F35)<3,2,1)))) | Q35: Cuestionario de asma; espirometría; Rx de tórax según criterio médico
A36: CU-H | B36: Cobre – humo, como Cu | C36: 7440-50-8 | D36: Humo | E36: mg/m³ | F36: 0.2 | H36: Metal | I36: Fiebre de humos metálicos | J36: Irritación; efectos gastrointestinales; fiebre de humos metálicos | K36: — | L36: NIOSH 7303 / 7300 (ICP-AES) | M36: Casete 37 mm, 2 L/min; filtro MCE 0,8 µm | P36: =IF(F36="","",IF(OR(ISNUMBER(SEARCH("A1",K36)),ISNUMBER(SEARCH("A2",K36)),N(F36)<0.05),4,IF(N(F36)<0.5,3,IF(N(F36)<3,2,1)))) | Q36: Examen periódico; cuestionario de síntomas respiratorios y espirometría si hay exposición sobre el nivel de acción
A37: CU-P | B37: Cobre – polvos y nieblas, como Cu | C37: 7440-50-8 | D37: Total | E37: mg/m³ | F37: 1 | H37: Metal | I37: Respiratorio – irritación y función pulmonar | J37: Irritación; efectos gastrointestinales | K37: — | L37: NIOSH 7303 / 7300 (ICP-AES) | M37: Casete 37 mm, 2 L/min; filtro MCE 0,8 µm | P37: =IF(F37="","",IF(OR(ISNUMBER(SEARCH("A1",K37)),ISNUMBER(SEARCH("A2",K37)),N(F37)<0.05),4,IF(N(F37)<0.5,3,IF(N(F37)<3,2,1)))) | Q37: Examen periódico; cuestionario de síntomas respiratorios y espirometría si hay exposición sobre el nivel de acción
A38: ZNO | B38: Óxido de zinc | C38: 1314-13-2 | D38: Respirable | E38: mg/m³ | F38: 2 | G38: 10 | H38: Metal | I38: Fiebre de humos metálicos | J38: Fiebre de humos metálicos | K38: — | L38: NIOSH 7303 / 7300 (ICP-AES) sobre muestra respirable | M38: Ciclón nylon 10 mm, 1,7 L/min; filtro MCE 0,8 µm | P38: =IF(F38="","",IF(OR(ISNUMBER(SEARCH("A1",K38)),ISNUMBER(SEARCH("A2",K38)),N(F38)<0.05),4,IF(N(F38)<0.5,3,IF(N(F38)<3,2,1)))) | Q38: Examen periódico; cuestionario de síntomas respiratorios y espirometría si hay exposición sobre el nivel de acción | R38: Galvanizado, soldadura de acero galvanizado, fundición de latón.
A39: MGO | B39: Óxido de magnesio | C39: 1309-48-4 | D39: Inhalable | E39: mg/m³ | F39: 10 | H39: Metal | I39: Fiebre de humos metálicos | J39: Irritación de VRS; fiebre de humos metálicos | K39: A4 | L39: NIOSH 7303 / 7300 (ICP-AES) u OSHA ID-125G; laboratorio acreditado | M39: IOM inhalable, 2,0 L/min; filtro MCE 0,8 µm (humos: casete abierto bajo la careta) | P39: =IF(F39="","",IF(OR(ISNUMBER(SEARCH("A1",K39)),ISNUMBER(SEARCH("A2",K39)),N(F39)<0.05),4,IF(N(F39)<0.5,3,IF(N(F39)<3,2,1)))) | Q39: Examen periódico; cuestionario de síntomas respiratorios y espirometría si hay exposición sobre el nivel de acción
A40: SN | B40: Estaño y compuestos inorgánicos, como Sn | C40: 7440-31-5 | D40: Inhalable | E40: mg/m³ | F40: 2 | H40: Metal | I40: Respiratorio – neumoconiosis no fibrogénica | J40: Neumoconiosis (estannosis) | K40: — | L40: NIOSH 7303 / 7300 (ICP-AES) u OSHA ID-125G; laboratorio acreditado | M40: IOM inhalable, 2,0 L/min; filtro MCE 0,8 µm (humos: casete abierto bajo la careta) | P40: =IF(F40="","",IF(OR(ISNUMBER(SEARCH("A1",K40)),ISNUMBER(SEARCH("A2",K40)),N(F40)<0.05),4,IF(N(F40)<0.5,3,IF(N(F40)<3,2,1)))) | Q40: Examen periódico con énfasis respiratorio y espirometría; Rx de tórax según criterio médico
A41: W | B41: Tungsteno y compuestos (sin cobalto), como W | C41: 7440-33-7 | D41: Respirable | E41: mg/m³ | F41: 3 | H41: Metal | I41: Respiratorio – neumoconiosis no fibrogénica | J41: Daño pulmonar | K41: — | L41: NIOSH 7303 / 7300 (ICP-AES) sobre muestra respirable | M41: Ciclón nylon 10 mm, 1,7 L/min; filtro MCE 0,8 µm | P41: =IF(F41="","",IF(OR(ISNUMBER(SEARCH("A1",K41)),ISNUMBER(SEARCH("A2",K41)),N(F41)<0.05),4,IF(N(F41)<0.5,3,IF(N(F41)<3,2,1)))) | Q41: Examen periódico con énfasis respiratorio y espirometría; Rx de tórax según criterio médico
...

Sheet GES
A1: 2. GES × agente – identificación, valoración cualitativa y ajuste del TLV
A2: Una fila por cada combinación GES–agente (un mismo GES puede repetirse con varios agentes). Matriz VE × VC (AIHA); VE según la banda de peligro del agente; VC según el tiempo de exposición y la pulverulencia.
A3: DustRisk V1 · Polvos minerales, metales y humos metálicos · SCHO · Celdas amarillas con texto azul = datos a diligenciar; celdas grises = cálculo automático (no editar).
A5: Código GES | B5: Cargos / oficios del GES | C5: Área / proceso | D5: Fuentes y actividades generadoras | E5: Agente (código) | F5: Nº trabajadores | G5: Controles existentes | H5: Horas / día | I5: Horas / semana | J5: Minutos de exposición por jornada | K5: Pulverulencia del proceso | L5: VC (circunstancia) | M5: VE (efecto) | N5: Riesgo potencial VE×VC | O5: Interpretación | P5: Muestras mínimas | Q5: Categoría cualitativa (juicio del higienista) | R5: Clave GES|agente | S5: TLV base | T5: Factor diario | U5: Factor semanal | V5: Factor aplicado | W5: TLV ajustado (B&S) | X5: Unidad | Y5: Fracción
A6: G01 | B6: Soldadores de acero al carbono | C6: Taller de estructuras | D6: Soldadura SMAW y MIG de perfiles; esmerilado de cordones | E6: MN-R | F6: 10 | G6: Ventilación general; sin extracción localizada | H6: 8 | I6: 48 | J6: 360 | K6: Alta | L6: =IF(J6="","",MAX(IF(N(J6)=0,0,1),MIN(4,IF(J6>=360,4,IF(J6>=120,3,IF(J6>=30,2,IF(J6>0,1,0))))+IF(K6="Alta",1,IF(AND(K6="Baja",J6>0),-1,0))))) | M6: =IF(E6="","",IFERROR(INDEX(Agentes!$P$6:$P$60,MATCH(E6,Agentes!$A$6:$A$60,0)),"")) | N6: =IF(OR(L6="",M6=""),"",L6*M6) | O6: =IF(N6="","",IF(N6=0,"Incipiente",IF(N6<=4,"Bajo",IF(N6<=8,"Moderado",IF(N6<=12,"Alto","Muy alto"))))) | P6: =IF(A6="","",IF(N(F6)>50,ROUNDUP(SQRT(F6),0),6)) | Q6: Alto | R6: =IF(OR(A6="",E6=""),"",A6&"|"&E6) | S6: =IF(E6="","",IFERROR(INDEX(Agentes!$F$6:$F$60,MATCH(E6,Agentes!$A$6:$A$60,0)),"Agente?")) | T6: =IF(N(H6)=0,"",8/H6*(24-H6)/16) | U6: =IF(N(I6)=0,"",40/I6*(168-I6)/128) | V6: =IF(E6="","",MIN(1,IF(T6="",1,T6),IF(U6="",1,U6))) | W6: =IF(OR(NOT(ISNUMBER(S6)),V6=""),"",S6*V6) | X6: =IF(E6="","",IFERROR(INDEX(Agentes!$E$6:$E$60,MATCH(E6,Agentes!$A$6:$A$60,0)),"")) | Y6: =IF(E6="","",IFERROR(INDEX(Agentes!$D$6:$D$60,MATCH(E6,Agentes!$A$6:$A$60,0)),""))
A7: G01 | B7: Soldadores de acero al carbono | C7: Taller de estructuras | D7: Soldadura SMAW y MIG de perfiles; esmerilado de cordones | E7: FE2O3 | F7: 10 | G7: Ventilación general; sin extracción localizada | H7: 8 | I7: 48 | J7: 360 | K7: Alta | L7: =IF(J7="","",MAX(IF(N(J7)=0,0,1),MIN(4,IF(J7>=360,4,IF(J7>=120,3,IF(J7>=30,2,IF(J7>0,1,0))))+IF(K7="Alta",1,IF(AND(K7="Baja",J7>0),-1,0))))) | M7: =IF(E7="","",IFERROR(INDEX(Agentes!$P$6:$P$60,MATCH(E7,Agentes!$A$6:$A$60,0)),"")) | N7: =IF(OR(L7="",M7=""),"",L7*M7) | O7: =IF(N7="","",IF(N7=0,"Incipiente",IF(N7<=4,"Bajo",IF(N7<=8,"Moderado",IF(N7<=12,"Alto","Muy alto"))))) | P7: =IF(A7="","",IF(N(F7)>50,ROUNDUP(SQRT(F7),0),6)) | Q7: Moderado | R7: =IF(OR(A7="",E7=""),"",A7&"|"&E7) | S7: =IF(E7="","",IFERROR(INDEX(Agentes!$F$6:$F$60,MATCH(E7,Agentes!$A$6:$A$60,0)),"Agente?")) | T7: =IF(N(H7)=0,"",8/H7*(24-H7)/16) | U7: =IF(N(I7)=0,"",40/I7*(168-I7)/128) | V7: =IF(E7="","",MIN(1,IF(T7="",1,T7),IF(U7="",1,U7))) | W7: =IF(OR(NOT(ISNUMBER(S7)),V7=""),"",S7*V7) | X7: =IF(E7="","",IFERROR(INDEX(Agentes!$E$6:$E$60,MATCH(E7,Agentes!$A$6:$A$60,0)),"")) | Y7: =IF(E7="","",IFERROR(INDEX(Agentes!$D$6:$D$60,MATCH(E7,Agentes!$A$6:$A$60,0)),""))
A8: G02 | B8: Soldadores de acero inoxidable | C8: Línea de tanques | D8: Soldadura TIG y MIG de inoxidable 304/316; corte con plasma | E8: CR6 | F8: 6 | G8: Brazo de extracción en 2 de 4 puestos | H8: 8 | I8: 48 | J8: 300 | K8: Media | L8: =IF(J8="","",MAX(IF(N(J8)=0,0,1),MIN(4,IF(J8>=360,4,IF(J8>=120,3,IF(J8>=30,2,IF(J8>0,1,0))))+IF(K8="Alta",1,IF(AND(K8="Baja",J8>0),-1,0))))) | M8: =IF(E8="","",IFERROR(INDEX(Agentes!$P$6:$P$60,MATCH(E8,Agentes!$A$6:$A$60,0)),"")) | N8: =IF(OR(L8="",M8=""),"",L8*M8) | O8: =IF(N8="","",IF(N8=0,"Incipiente",IF(N8<=4,"Bajo",IF(N8<=8,"Moderado",IF(N8<=12,"Alto","Muy alto"))))) | P8: =IF(A8="","",IF(N(F8)>50,ROUNDUP(SQRT(F8),0),6)) | Q8: Crítico | R8: =IF(OR(A8="",E8=""),"",A8&"|"&E8) | S8: =IF(E8="","",IFERROR(INDEX(Agentes!$F$6:$F$60,MATCH(E8,Agentes!$A$6:$A$60,0)),"Agente?")) | T8: =IF(N(H8)=0,"",8/H8*(24-H8)/16) | U8: =IF(N(I8)=0,"",40/I8*(168-I8)/128) | V8: =IF(E8="","",MIN(1,IF(T8="",1,T8),IF(U8="",1,U8))) | W8: =IF(OR(NOT(ISNUMBER(S8)),V8=""),"",S8*V8) | X8: =IF(E8="","",IFERROR(INDEX(Agentes!$E$6:$E$60,MATCH(E8,Agentes!$A$6:$A$60,0)),"")) | Y8: =IF(E8="","",IFERROR(INDEX(Agentes!$D$6:$D$60,MATCH(E8,Agentes!$A$6:$A$60,0)),""))
A9: G02 | B9: Soldadores de acero inoxidable | C9: Línea de tanques | D9: Soldadura TIG y MIG de inoxidable 304/316; corte con plasma | E9: NI-I | F9: 6 | G9: Brazo de extracción en 2 de 4 puestos | H9: 8 | I9: 48 | J9: 300 | K9: Media | L9: =IF(J9="","",MAX(IF(N(J9)=0,0,1),MIN(4,IF(J9>=360,4,IF(J9>=120,3,IF(J9>=30,2,IF(J9>0,1,0))))+IF(K9="Alta",1,IF(AND(K9="Baja",J9>0),-1,0))))) | M9: =IF(E9="","",IFERROR(INDEX(Agentes!$P$6:$P$60,MATCH(E9,Agentes!$A$6:$A$60,0)),"")) | N9: =IF(OR(L9="",M9=""),"",L9*M9) | O9: =IF(N9="","",IF(N9=0,"Incipiente",IF(N9<=4,"Bajo",IF(N9<=8,"Moderado",IF(N9<=12,"Alto","Muy alto"))))) | P9: =IF(A9="","",IF(N(F9)>50,ROUNDUP(SQRT(F9),0),6)) | Q9: Alto | R9: =IF(OR(A9="",E9=""),"",A9&"|"&E9) | S9: =IF(E9="","",IFERROR(INDEX(Agentes!$F$6:$F$60,MATCH(E9,Agentes!$A$6:$A$60,0)),"Agente?")) | T9: =IF(N(H9)=0,"",8/H9*(24-H9)/16) | U9: =IF(N(I9)=0,"",40/I9*(168-I9)/128) | V9: =IF(E9="","",MIN(1,IF(T9="",1,T9),IF(U9="",1,U9))) | W9: =IF(OR(NOT(ISNUMBER(S9)),V9=""),"",S9*V9) | X9: =IF(E9="","",IFERROR(INDEX(Agentes!$E$6:$E$60,MATCH(E9,Agentes!$A$6:$A$60,0)),"")) | Y9: =IF(E9="","",IFERROR(INDEX(Agentes!$D$6:$D$60,MATCH(E9,Agentes!$A$6:$A$60,0)),""))
A10: G03 | B10: Operarios de ensacado de cemento | C10: Planta de cemento | D10: Llenado de sacos de 50 kg, paletizado y limpieza | E10: CEM | F10: 8 | G10: Campana en la ensacadora | H10: 8 | I10: 44 | J10: 420 | K10: Alta | L10: =IF(J10="","",MAX(IF(N(J10)=0,0,1),MIN(4,IF(J10>=360,4,IF(J10>=120,3,IF(J10>=30,2,IF(J10>0,1,0))))+IF(K10="Alta",1,IF(AND(K10="Baja",J10>0),-1,0))))) | M10: =IF(E10="","",IFERROR(INDEX(Agentes!$P$6:$P$60,MATCH(E10,Agentes!$A$6:$A$60,0)),"")) | N10: =IF(OR(L10="",M10=""),"",L10*M10) | O10: =IF(N10="","",IF(N10=0,"Incipiente",IF(N10<=4,"Bajo",IF(N10<=8,"Moderado",IF(N10<=12,"Alto","Muy alto"))))) | P10: =IF(A10="","",IF(N(F10)>50,ROUNDUP(SQRT(F10),0),6)) | Q10: Alto | R10: =IF(OR(A10="",E10=""),"",A10&"|"&E10) | S10: =IF(E10="","",IFERROR(INDEX(Agentes!$F$6:$F$60,MATCH(E10,Agentes!$A$6:$A$60,0)),"Agente?")) | T10: =IF(N(H10)=0,"",8/H10*(24-H10)/16) | U10: =IF(N(I10)=0,"",40/I10*(168-I10)/128) | V10: =IF(E10="","",MIN(1,IF(T10="",1,T10),IF(U10="",1,U10))) | W10: =IF(OR(NOT(ISNUMBER(S10)),V10=""),"",S10*V10) | X10: =IF(E10="","",IFERROR(INDEX(Agentes!$E$6:$E$60,MATCH(E10,Agentes!$A$6:$A$60,0)),"")) | Y10: =IF(E10="","",IFERROR(INDEX(Agentes!$D$6:$D$60,MATCH(E10,Agentes!$A$6:$A$60,0)),""))
A11: G04 | B11: Operadores de molino de caolín | C11: Planta de minerales | D11: Molienda, clasificación y transporte neumático de caolín | E11: KAO | F11: 5 | G11: Molino encerrado; colector de mangas | H11: 8 | I11: 44 | J11: 240 | K11: Media | L11: =IF(J11="","",MAX(IF(N(J11)=0,0,1),MIN(4,IF(J11>=360,4,IF(J11>=120,3,IF(J11>=30,2,IF(J11>0,1,0))))+IF(K11="Alta",1,IF(AND(K11="Baja",J11>0),-1,0))))) | M11: =IF(E11="","",IFERROR(INDEX(Agentes!$P$6:$P$60,MATCH(E11,Agentes!$A$6:$A$60,0)),"")) | N11: =IF(OR(L11="",M11=""),"",L11*M11) | O11: =IF(N11="","",IF(N11=0,"Incipiente",IF(N11<=4,"Bajo",IF(N11<=8,"Moderado",IF(N11<=12,"Alto","Muy alto"))))) | P11: =IF(A11="","",IF(N(F11)>50,ROUNDUP(SQRT(F11),0),6)) | Q11: Moderado | R11: =IF(OR(A11="",E11=""),"",A11&"|"&E11) | S11: =IF(E11="","",IFERROR(INDEX(Agentes!$F$6:$F$60,MATCH(E11,Agentes!$A$6:$A$60,0)),"Agente?")) | T11: =IF(N(H11)=0,"",8/H11*(24-H11)/16) | U11: =IF(N(I11)=0,"",40/I11*(168-I11)/128) | V11: =IF(E11="","",MIN(1,IF(T11="",1,T11),IF(U11="",1,U11))) | W11: =IF(OR(NOT(ISNUMBER(S11)),V11=""),"",S11*V11) | X11: =IF(E11="","",IFERROR(INDEX(Agentes!$E$6:$E$60,MATCH(E11,Agentes!$A$6:$A$60,0)),"")) | Y11: =IF(E11="","",IFERROR(INDEX(Agentes!$D$6:$D$60,MATCH(E11,Agentes!$A$6:$A$60,0)),""))
A12: G05 | B12: Operarios de fundición de plomo | C12: Recuperación de baterías | D12: Fusión de plomo y vaciado de lingotes | E12: PB | F12: 6 | G12: Campana sobre el horno | H12: 8 | I12: 40 | J12: 300 | K12: Media | L12: =IF(J12="","",MAX(IF(N(J12)=0,0,1),MIN(4,IF(J12>=360,4,IF(J12>=120,3,IF(J12>=30,2,IF(J12>0,1,0))))+IF(K12="Alta",1,IF(AND(K12="Baja",J12>0),-1,0))))) | M12: =IF(E12="","",IFERROR(INDEX(Agentes!$P$6:$P$60,MATCH(E12,Agentes!$A$6:$A$60,0)),"")) | N12: =IF(OR(L12="",M12=""),"",L12*M12) | O12: =IF(N12="","",IF(N12=0,"Incipiente",IF(N12<=4,"Bajo",IF(N12<=8,"Moderado",IF(N12<=12,"Alto","Muy alto"))))) | P12: =IF(A12="","",IF(N(F12)>50,ROUNDUP(SQRT(F12),0),6)) | Q12: Alto | R12: =IF(OR(A12="",E12=""),"",A12&"|"&E12) | S12: =IF(E12="","",IFERROR(INDEX(Agentes!$F$6:$F$60,MATCH(E12,Agentes!$A$6:$A$60,0)),"Agente?")) | T12: =IF(N(H12)=0,"",8/H12*(24-H12)/16) | U12: =IF(N(I12)=0,"",40/I12*(168-I12)/128) | V12: =IF(E12="","",MIN(1,IF(T12="",1,T12),IF(U12="",1,U12))) | W12: =IF(OR(NOT(ISNUMBER(S12)),V12=""),"",S12*V12) | X12: =IF(E12="","",IFERROR(INDEX(Agentes!$E$6:$E$60,MATCH(E12,Agentes!$A$6:$A$60,0)),"")) | Y12: =IF(E12="","",IFERROR(INDEX(Agentes!$D$6:$D$60,MATCH(E12,Agentes!$A$6:$A$60,0)),""))
A13: G06 | B13: Pulidores y lijadores | C13: Acabados | D13: Lijado y pulido de piezas pintadas (sin sílice) | E13: PNOS-I | F13: 7 | G13: Ninguno | H13: 8 | I13: 44 | J13: 240 | K13: Media | L13: =IF(J13="","",MAX(IF(N(J13)=0,0,1),MIN(4,IF(J13>=360,4,IF(J13>=120,3,IF(J13>=30,2,IF(J13>0,1,0))))+IF(K13="Alta",1,IF(AND(K13="Baja",J13>0),-1,0))))) | M13: =IF(E13="","",IFERROR(INDEX(Agentes!$P$6:$P$60,MATCH(E13,Agentes!$A$6:$A$60,0)),"")) | N13: =IF(OR(L13="",M13=""),"",L13*M13) | O13: =IF(N13="","",IF(N13=0,"Incipiente",IF(N13<=4,"Bajo",IF(N13<=8,"Moderado",IF(N13<=12,"Alto","Muy alto"))))) | P13: =IF(A13="","",IF(N(F13)>50,ROUNDUP(SQRT(F13),0),6)) | Q13: Moderado | R13: =IF(OR(A13="",E13=""),"",A13&"|"&E13) | S13: =IF(E13="","",IFERROR(INDEX(Agentes!$F$6:$F$60,MATCH(E13,Agentes!$A$6:$A$60,0)),"Agente?")) | T13: =IF(N(H13)=0,"",8/H13*(24-H13)/16) | U13: =IF(N(I13)=0,"",40/I13*(168-I13)/128) | V13: =IF(E13="","",MIN(1,IF(T13="",1,T13),IF(U13="",1,U13))) | W13: =IF(OR(NOT(ISNUMBER(S13)),V13=""),"",S13*V13) | X13: =IF(E13="","",IFERROR(INDEX(Agentes!$E$6:$E$60,MATCH(E13,Agentes!$A$6:$A$60,0)),"")) | Y13: =IF(E13="","",IFERROR(INDEX(Agentes!$D$6:$D$60,MATCH(E13,Agentes!$A$6:$A$60,0)),""))
L14: =IF(J14="","",MAX(IF(N(J14)=0,0,1),MIN(4,IF(J14>=360,4,IF(J14>=120,3,IF(J14>=30,2,IF(J14>0,1,0))))+IF(K14="Alta",1,IF(AND(K14="Baja",J14>0),-1,0))))) | M14: =IF(E14="","",IFERROR(INDEX(Agentes!$P$6:$P$60,MATCH(E14,Agentes!$A$6:$A$60,0)),"")) | N14: =IF(OR(L14="",M14=""),"",L14*M14) | O14: =IF(N14="","",IF(N14=0,"Incipiente",IF(N14<=4,"Bajo",IF(N14<=8,"Moderado",IF(N14<=12,"Alto","Muy alto"))))) | P14: =IF(A14="","",IF(N(F14)>50,ROUNDUP(SQRT(F14),0),6)) | R14: =IF(OR(A14="",E14=""),"",A14&"|"&E14) | S14: =IF(E14="","",IFERROR(INDEX(Agentes!$F$6:$F$60,MATCH(E14,Agentes!$A$6:$A$60,0)),"Agente?")) | T14: =IF(N(H14)=0,"",8/H14*(24-H14)/16) | U14: =IF(N(I14)=0,"",40/I14*(168-I14)/128) | V14: =IF(E14="","",MIN(1,IF(T14="",1,T14),IF(U14="",1,U14))) | W14: =IF(OR(NOT(ISNUMBER(S14)),V14=""),"",S14*V14) | X14: =IF(E14="","",IFERROR(INDEX(Agentes!$E$6:$E$60,MATCH(E14,Agentes!$A$6:$A$60,0)),"")) | Y14: =IF(E14="","",IFERROR(INDEX(Agentes!$D$6:$D$60,MATCH(E14,Agentes!$A$6:$A$60,0)),""))
L15: =IF(J15="","",MAX(IF(N(J15)=0,0,1),MIN(4,IF(J15>=360,4,IF(J15>=120,3,IF(J15>=30,2,IF(J15>0,1,0))))+IF(K15="Alta",1,IF(AND(K15="Baja",J15>0),-1,0))))) | M15: =IF(E15="","",IFERROR(INDEX(Agentes!$P$6:$P$60,MATCH(E15,Agentes!$A$6:$A$60,0)),"")) | N15: =IF(OR(L15="",M15=""),"",L15*M15) | O15: =IF(N15="","",IF(N15=0,"Incipiente",IF(N15<=4,"Bajo",IF(N15<=8,"Moderado",IF(N15<=12,"Alto","Muy alto"))))) | P15: =IF(A15="","",IF(N(F15)>50,ROUNDUP(SQRT(F15),0),6)) | R15: =IF(OR(A15="",E15=""),"",A15&"|"&E15) | S15: =IF(E15="","",IFERROR(INDEX(Agentes!$F$6:$F$60,MATCH(E15,Agentes!$A$6:$A$60,0)),"Agente?")) | T15: =IF(N(H15)=0,"",8/H15*(24-H15)/16) | U15: =IF(N(I15)=0,"",40/I15*(168-I15)/128) | V15: =IF(E15="","",MIN(1,IF(T15="",1,T15),IF(U15="",1,U15))) | W15: =IF(OR(NOT(ISNUMBER(S15)),V15=""),"",S15*V15) | X15: =IF(E15="","",IFERROR(INDEX(Agentes!$E$6:$E$60,MATCH(E15,Agentes!$A$6:$A$60,0)),"")) | Y15: =IF(E15="","",IFERROR(INDEX(Agentes!$D$6:$D$60,MATCH(E15,Agentes!$A$6:$A$60,0)),""))
L16: =IF(J16="","",MAX(IF(N(J16)=0,0,1),MIN(4,IF(J16>=360,4,IF(J16>=120,3,IF(J16>=30,2,IF(J16>0,1,0))))+IF(K16="Alta",1,IF(AND(K16="Baja",J16>0),-1,0))))) | M16: =IF(E16="","",IFERROR(INDEX(Agentes!$P$6:$P$60,MATCH(E16,Agentes!$A$6:$A$60,0)),"")) | N16: =IF(OR(L16="",M16=""),"",L16*M16) | O16: =IF(N16="","",IF(N16=0,"Incipiente",IF(N16<=4,"Bajo",IF(N16<=8,"Moderado",IF(N16<=12,"Alto","Muy alto"))))) | P16: =IF(A16="","",IF(N(F16)>50,ROUNDUP(SQRT(F16),0),6)) | R16: =IF(OR(A16="",E16=""),"",A16&"|"&E16) | S16: =IF(E16="","",IFERROR(INDEX(Agentes!$F$6:$F$60,MATCH(E16,Agentes!$A$6:$A$60,0)),"Agente?")) | T16: =IF(N(H16)=0,"",8/H16*(24-H16)/16) | U16: =IF(N(I16)=0,"",40/I16*(168-I16)/128) | V16: =IF(E16="","",MIN(1,IF(T16="",1,T16),IF(U16="",1,U16))) | W16: =IF(OR(NOT(ISNUMBER(S16)),V16=""),"",S16*V16) | X16: =IF(E16="","",IFERROR(INDEX(Agentes!$E$6:$E$60,MATCH(E16,Agentes!$A$6:$A$60,0)),"")) | Y16: =IF(E16="","",IFERROR(INDEX(Agentes!$D$6:$D$60,MATCH(E16,Agentes!$A$6:$A$60,0)),""))
L17: =IF(J17="","",MAX(IF(N(J17)=0,0,1),MIN(4,IF(J17>=360,4,IF(J17>=120,3,IF(J17>=30,2,IF(J17>0,1,0))))+IF(K17="Alta",1,IF(AND(K17="Baja",J17>0),-1,0))))) | M17: =IF(E17="","",IFERROR(INDEX(Agentes!$P$6:$P$60,MATCH(E17,Agentes!$A$6:$A$60,0)),"")) | N17: =IF(OR(L17="",M17=""),"",L17*M17) | O17: =IF(N17="","",IF(N17=0,"Incipiente",IF(N17<=4,"Bajo",IF(N17<=8,"Moderado",IF(N17<=12,"Alto","Muy alto"))))) | P17: =IF(A17="","",IF(N(F17)>50,ROUNDUP(SQRT(F17),0),6)) | R17: =IF(OR(A17="",E17=""),"",A17&"|"&E17) | S17: =IF(E17="","",IFERROR(INDEX(Agentes!$F$6:$F$60,MATCH(E17,Agentes!$A$6:$A$60,0)),"Agente?")) | T17: =IF(N(H17)=0,"",8/H17*(24-H17)/16) | U17: =IF(N(I17)=0,"",40/I17*(168-I17)/128) | V17: =IF(E17="","",MIN(1,IF(T17="",1,T17),IF(U17="",1,U17))) | W17: =IF(OR(NOT(ISNUMBER(S17)),V17=""),"",S17*V17) | X17: =IF(E17="","",IFERROR(INDEX(Agentes!$E$6:$E$60,MATCH(E17,Agentes!$A$6:$A$60,0)),"")) | Y17: =IF(E17="","",IFERROR(INDEX(Agentes!$D$6:$D$60,MATCH(E17,Agentes!$A$6:$A$60,0)),""))
L18: =IF(J18="","",MAX(IF(N(J18)=0,0,1),MIN(4,IF(J18>=360,4,IF(J18>=120,3,IF(J18>=30,2,IF(J18>0,1,0))))+IF(K18="Alta",1,IF(AND(K18="Baja",J18>0),-1,0))))) | M18: =IF(E18="","",IFERROR(INDEX(Agentes!$P$6:$P$60,MATCH(E18,Agentes!$A$6:$A$60,0)),"")) | N18: =IF(OR(L18="",M18=""),"",L18*M18) | O18: =IF(N18="","",IF(N18=0,"Incipiente",IF(N18<=4,"Bajo",IF(N18<=8,"Moderado",IF(N18<=12,"Alto","Muy alto"))))) | P18: =IF(A18="","",IF(N(F18)>50,ROUNDUP(SQRT(F18),0),6)) | R18: =IF(OR(A18="",E18=""),"",A18&"|"&E18) | S18: =IF(E18="","",IFERROR(INDEX(Agentes!$F$6:$F$60,MATCH(E18,Agentes!$A$6:$A$60,0)),"Agente?")) | T18: =IF(N(H18)=0,"",8/H18*(24-H18)/16) | U18: =IF(N(I18)=0,"",40/I18*(168-I18)/128) | V18: =IF(E18="","",MIN(1,IF(T18="",1,T18),IF(U18="",1,U18))) | W18: =IF(OR(NOT(ISNUMBER(S18)),V18=""),"",S18*V18) | X18: =IF(E18="","",IFERROR(INDEX(Agentes!$E$6:$E$60,MATCH(E18,Agentes!$A$6:$A$60,0)),"")) | Y18: =IF(E18="","",IFERROR(INDEX(Agentes!$D$6:$D$60,MATCH(E18,Agentes!$A$6:$A$60,0)),""))
L19: =IF(J19="","",MAX(IF(N(J19)=0,0,1),MIN(4,IF(J19>=360,4,IF(J19>=120,3,IF(J19>=30,2,IF(J19>0,1,0))))+IF(K19="Alta",1,IF(AND(K19="Baja",J19>0),-1,0))))) | M19: =IF(E19="","",IFERROR(INDEX(Agentes!$P$6:$P$60,MATCH(E19,Agentes!$A$6:$A$60,0)),"")) | N19: =IF(OR(L19="",M19=""),"",L19*M19) | O19: =IF(N19="","",IF(N19=0,"Incipiente",IF(N19<=4,"Bajo",IF(N19<=8,"Moderado",IF(N19<=12,"Alto","Muy alto"))))) | P19: =IF(A19="","",IF(N(F19)>50,ROUNDUP(SQRT(F19),0),6)) | R19: =IF(OR(A19="",E19=""),"",A19&"|"&E19) | S19: =IF(E19="","",IFERROR(INDEX(Agentes!$F$6:$F$60,MATCH(E19,Agentes!$A$6:$A$60,0)),"Agente?")) | T19: =IF(N(H19)=0,"",8/H19*(24-H19)/16) | U19: =IF(N(I19)=0,"",40/I19*(168-I19)/128) | V19: =IF(E19="","",MIN(1,IF(T19="",1,T19),IF(U19="",1,U19))) | W19: =IF(OR(NOT(ISNUMBER(S19)),V19=""),"",S19*V19) | X19: =IF(E19="","",IFERROR(INDEX(Agentes!$E$6:$E$60,MATCH(E19,Agentes!$A$6:$A$60,0)),"")) | Y19: =IF(E19="","",IFERROR(INDEX(Agentes!$D$6:$D$60,MATCH(E19,Agentes!$A$6:$A$60,0)),""))
L20: =IF(J20="","",MAX(IF(N(J20)=0,0,1),MIN(4,IF(J20>=360,4,IF(J20>=120,3,IF(J20>=30,2,IF(J20>0,1,0))))+IF(K20="Alta",1,IF(AND(K20="Baja",J20>0),-1,0))))) | M20: =IF(E20="","",IFERROR(INDEX(Agentes!$P$6:$P$60,MATCH(E20,Agentes!$A$6:$A$60,0)),"")) | N20: =IF(OR(L20="",M20=""),"",L20*M20) | O20: =IF(N20="","",IF(N20=0,"Incipiente",IF(N20<=4,"Bajo",IF(N20<=8,"Moderado",IF(N20<=12,"Alto","Muy alto"))))) | P20: =IF(A20="","",IF(N(F20)>50,ROUNDUP(SQRT(F20),0),6)) | R20: =IF(OR(A20="",E20=""),"",A20&"|"&E20) | S20: =IF(E20="","",IFERROR(INDEX(Agentes!$F$6:$F$60,MATCH(E20,Agentes!$A$6:$A$60,0)),"Agente?")) | T20: =IF(N(H20)=0,"",8/H20*(24-H20)/16) | U20: =IF(N(I20)=0,"",40/I20*(168-I20)/128) | V20: =IF(E20="","",MIN(1,IF(T20="",1,T20),IF(U20="",1,U20))) | W20: =IF(OR(NOT(ISNUMBER(S20)),V20=""),"",S20*V20) | X20: =IF(E20="","",IFERROR(INDEX(Agentes!$E$6:$E$60,MATCH(E20,Agentes!$A$6:$A$60,0)),"")) | Y20: =IF(E20="","",IFERROR(INDEX(Agentes!$D$6:$D$60,MATCH(E20,Agentes!$A$6:$A$60,0)),""))
L21: =IF(J21="","",MAX(IF(N(J21)=0,0,1),MIN(4,IF(J21>=360,4,IF(J21>=120,3,IF(J21>=30,2,IF(J21>0,1,0))))+IF(K21="Alta",1,IF(AND(K21="Baja",J21>0),-1,0))))) | M21: =IF(E21="","",IFERROR(INDEX(Agentes!$P$6:$P$60,MATCH(E21,Agentes!$A$6:$A$60,0)),"")) | N21: =IF(OR(L21="",M21=""),"",L21*M21) | O21: =IF(N21="","",IF(N21=0,"Incipiente",IF(N21<=4,"Bajo",IF(N21<=8,"Moderado",IF(N21<=12,"Alto","Muy alto"))))) | P21: =IF(A21="","",IF(N(F21)>50,ROUNDUP(SQRT(F21),0),6)) | R21: =IF(OR(A21="",E21=""),"",A21&"|"&E21) | S21: =IF(E21="","",IFERROR(INDEX(Agentes!$F$6:$F$60,MATCH(E21,Agentes!$A$6:$A$60,0)),"Agente?")) | T21: =IF(N(H21)=0,"",8/H21*(24-H21)/16) | U21: =IF(N(I21)=0,"",40/I21*(168-I21)/128) | V21: =IF(E21="","",MIN(1,IF(T21="",1,T21),IF(U21="",1,U21))) | W21: =IF(OR(NOT(ISNUMBER(S21)),V21=""),"",S21*V21) | X21: =IF(E21="","",IFERROR(INDEX(Agentes!$E$6:$E$60,MATCH(E21,Agentes!$A$6:$A$60,0)),"")) | Y21: =IF(E21="","",IFERROR(INDEX(Agentes!$D$6:$D$60,MATCH(E21,Agentes!$A$6:$A$60,0)),""))
L22: =IF(J22="","",MAX(IF(N(J22)=0,0,1),MIN(4,IF(J22>=360,4,IF(J22>=120,3,IF(J22>=30,2,IF(J22>0,1,0))))+IF(K22="Alta",1,IF(AND(K22="Baja",J22>0),-1,0))))) | M22: =IF(E22="","",IFERROR(INDEX(Agentes!$P$6:$P$60,MATCH(E22,Agentes!$A$6:$A$60,0)),"")) | N22: =IF(OR(L22="",M22=""),"",L22*M22) | O22: =IF(N22="","",IF(N22=0,"Incipiente",IF(N22<=4,"Bajo",IF(N22<=8,"Moderado",IF(N22<=12,"Alto","Muy alto"))))) | P22: =IF(A22="","",IF(N(F22)>50,ROUNDUP(SQRT(F22),0),6)) | R22: =IF(OR(A22="",E22=""),"",A22&"|"&E22) | S22: =IF(E22="","",IFERROR(INDEX(Agentes!$F$6:$F$60,MATCH(E22,Agentes!$A$6:$A$60,0)),"Agente?")) | T22: =IF(N(H22)=0,"",8/H22*(24-H22)/16) | U22: =IF(N(I22)=0,"",40/I22*(168-I22)/128) | V22: =IF(E22="","",MIN(1,IF(T22="",1,T22),IF(U22="",1,U22))) | W22: =IF(OR(NOT(ISNUMBER(S22)),V22=""),"",S22*V22) | X22: =IF(E22="","",IFERROR(INDEX(Agentes!$E$6:$E$60,MATCH(E22,Agentes!$A$6:$A$60,0)),"")) | Y22: =IF(E22="","",IFERROR(INDEX(Agentes!$D$6:$D$60,MATCH(E22,Agentes!$A$6:$A$60,0)),""))
L23: =IF(J23="","",MAX(IF(N(J23)=0,0,1),MIN(4,IF(J23>=360,4,IF(J23>=120,3,IF(J23>=30,2,IF(J23>0,1,0))))+IF(K23="Alta",1,IF(AND(K23="Baja",J23>0),-1,0))))) | M23: =IF(E23="","",IFERROR(INDEX(Agentes!$P$6:$P$60,MATCH(E23,Agentes!$A$6:$A$60,0)),"")) | N23: =IF(OR(L23="",M23=""),"",L23*M23) | O23: =IF(N23="","",IF(N23=0,"Incipiente",IF(N23<=4,"Bajo",IF(N23<=8,"Moderado",IF(N23<=12,"Alto","Muy alto"))))) | P23: =IF(A23="","",IF(N(F23)>50,ROUNDUP(SQRT(F23),0),6)) | R23: =IF(OR(A23="",E23=""),"",A23&"|"&E23) | S23: =IF(E23="","",IFERROR(INDEX(Agentes!$F$6:$F$60,MATCH(E23,Agentes!$A$6:$A$60,0)),"Agente?")) | T23: =IF(N(H23)=0,"",8/H23*(24-H23)/16) | U23: =IF(N(I23)=0,"",40/I23*(168-I23)/128) | V23: =IF(E23="","",MIN(1,IF(T23="",1,T23),IF(U23="",1,U23))) | W23: =IF(OR(NOT(ISNUMBER(S23)),V23=""),"",S23*V23) | X23: =IF(E23="","",IFERROR(INDEX(Agentes!$E$6:$E$60,MATCH(E23,Agentes!$A$6:$A$60,0)),"")) | Y23: =IF(E23="","",IFERROR(INDEX(Agentes!$D$6:$D$60,MATCH(E23,Agentes!$A$6:$A$60,0)),""))
L24: =IF(J24="","",MAX(IF(N(J24)=0,0,1),MIN(4,IF(J24>=360,4,IF(J24>=120,3,IF(J24>=30,2,IF(J24>0,1,0))))+IF(K24="Alta",1,IF(AND(K24="Baja",J24>0),-1,0))))) | M24: =IF(E24="","",IFERROR(INDEX(Agentes!$P$6:$P$60,MATCH(E24,Agentes!$A$6:$A$60,0)),"")) | N24: =IF(OR(L24="",M24=""),"",L24*M24) | O24: =IF(N24="","",IF(N24=0,"Incipiente",IF(N24<=4,"Bajo",IF(N24<=8,"Moderado",IF(N24<=12,"Alto","Muy alto"))))) | P24: =IF(A24="","",IF(N(F24)>50,ROUNDUP(SQRT(F24),0),6)) | R24: =IF(OR(A24="",E24=""),"",A24&"|"&E24) | S24: =IF(E24="","",IFERROR(INDEX(Agentes!$F$6:$F$60,MATCH(E24,Agentes!$A$6:$A$60,0)),"Agente?")) | T24: =IF(N(H24)=0,"",8/H24*(24-H24)/16) | U24: =IF(N(I24)=0,"",40/I24*(168-I24)/128) | V24: =IF(E24="","",MIN(1,IF(T24="",1,T24),IF(U24="",1,U24))) | W24: =IF(OR(NOT(ISNUMBER(S24)),V24=""),"",S24*V24) | X24: =IF(E24="","",IFERROR(INDEX(Agentes!$E$6:$E$60,MATCH(E24,Agentes!$A$6:$A$60,0)),"")) | Y24: =IF(E24="","",IFERROR(INDEX(Agentes!$D$6:$D$60,MATCH(E24,Agentes!$A$6:$A$60,0)),""))
L25: =IF(J25="","",MAX(IF(N(J25)=0,0,1),MIN(4,IF(J25>=360,4,IF(J25>=120,3,IF(J25>=30,2,IF(J25>0,1,0))))+IF(K25="Alta",1,IF(AND(K25="Baja",J25>0),-1,0))))) | M25: =IF(E25="","",IFERROR(INDEX(Agentes!$P$6:$P$60,MATCH(E25,Agentes!$A$6:$A$60,0)),"")) | N25: =IF(OR(L25="",M25=""),"",L25*M25) | O25: =IF(N25="","",IF(N25=0,"Incipiente",IF(N25<=4,"Bajo",IF(N25<=8,"Moderado",IF(N25<=12,"Alto","Muy alto"))))) | P25: =IF(A25="","",IF(N(F25)>50,ROUNDUP(SQRT(F25),0),6)) | R25: =IF(OR(A25="",E25=""),"",A25&"|"&E25) | S25: =IF(E25="","",IFERROR(INDEX(Agentes!$F$6:$F$60,MATCH(E25,Agentes!$A$6:$A$60,0)),"Agente?")) | T25: =IF(N(H25)=0,"",8/H25*(24-H25)/16) | U25: =IF(N(I25)=0,"",40/I25*(168-I25)/128) | V25: =IF(E25="","",MIN(1,IF(T25="",1,T25),IF(U25="",1,U25))) | W25: =IF(OR(NOT(ISNUMBER(S25)),V25=""),"",S25*V25) | X25: =IF(E25="","",IFERROR(INDEX(Agentes!$E$6:$E$60,MATCH(E25,Agentes!$A$6:$A$60,0)),"")) | Y25: =IF(E25="","",IFERROR(INDEX(Agentes!$D$6:$D$60,MATCH(E25,Agentes!$A$6:$A$60,0)),""))
... L35: =IF(J35="","",MAX(IF(N(J35)=0,0,1),MIN(4,IF(J35>=360,4,IF(J35>=120,3,IF(J35>=30,2,IF(J35>0,1,0))))+IF(K35="Alta",1,IF(AND(K35="Baja",J35>0),-1,0))))) | M35: =IF(E35="","",IFERROR(INDEX(Agentes!$P$6:$P$60,MATCH(E35,Agentes!$A$6:$A$60,0)),"")) | N35: =IF(OR(L35="",M35=""),"",L35*M35) | O35: =IF(N35="","",IF(N35=0,"Incipiente",IF(N35<=4,"Bajo",IF(N35<=8,"Moderado",IF(N35<=12,"Alto","Muy alto"))))) | P35: =IF(A35="","",IF(N(F35)>50,ROUNDUP(SQRT(F35),0),6)) | R35: =IF(OR(A35="",E35=""),"",A35&"|"&E35) | S35: =IF(E35="","",IFERROR(INDEX(Agentes!$F$6:$F$60,MATCH(E35,Agentes!$A$6:$A$60,0)),"Agente?")) | T35: =IF(N(H35)=0,"",8/H35*(24-H35)/16) | U35: =IF(N(I35)=0,"",40/I35*(168-I35)/128) | V35: =IF(E35="","",MIN(1,IF(T35="",1,T35),IF(U35="",1,U35))) | W35: =IF(OR(NOT(ISNUMBER(S35)),V35=""),"",S35*V35) | X35: =IF(E35="","",IFERROR(INDEX(Agentes!$E$6:$E$60,MATCH(E35,Agentes!$A$6:$A$60,0)),"")) | Y35: =IF(E35="","",IFERROR(INDEX(Agentes!$D$6:$D$60,MATCH(E35,Agentes!$A$6:$A$60,0)),""))

Sheet Muestreo
A1: 3. Registro de muestras personales
A2: Una fila por agente y muestra. Ingrese masa + caudal + tiempo, o la concentración reportada por el laboratorio (columna M). Valores < LD: registre LD/2. Para evaluar mezclas, use el mismo ID en los agentes medidos al mismo trabajador en la misma jornada.
A3: DustRisk V1 · Polvos minerales, metales y humos metálicos · SCHO · Celdas amarillas con texto azul = datos a diligenciar; celdas grises = cálculo automático (no editar).
A5: Nº | B5: Código GES | C5: Agente | D5: Fecha | E5: Trabajador / cargo | F5: ID muestra / jornada | G5: Tipo de muestra | H5: Muestreador | I5: Caudal (L/min) | J5: Tiempo de muestreo (min) | K5: Volumen (m³) | L5: Masa del analito (mg) | M5: Concentración reportada por laboratorio (mg/m³) | N5: Concentración (mg/m³) | O5: Fracción del TLV | P5: Coherencia muestreador / fracción | Q5: TLV ajustado | R5: Índice C / TLV aj. | S5: Grupo de efecto (aux) | T5: Observaciones | U5: ln C (aux) | V5: (ln C − ln MG)² (aux) | W5: (C − MA)² (aux) | X5: > TLV (aux) | Y5: Clave (aux)
A6: 1 | B6: G01 | C6: MN-R | D6: 46279 | E6: Soldador 1 | F6: G01-D1 | G6: Personal | H6: Ciclón nylon 10 mm | I6: 1.7 | J6: 420 | K6: =IF(OR(I6="",J6=""),"",I6*J6/1000) | L6: 0.01248 | N6: =IF(OR(B6="",C6=""),"",IF(M6<>"",M6,IF(AND(N(L6)>0,N(K6)>0),L6/K6,""))) | O6: =IF(C6="","",IFERROR(INDEX(Agentes!$D$6:$D$60,MATCH(C6,Agentes!$A$6:$A$60,0)),"")) | P6: =IF(OR(H6="",O6=""),"",IF(AND(O6="Inhalable",LEFT(H6,6)="Casete"),"Subestima: el casete cerrado no colecta toda la fracción inhalable",IF(AND(O6="Respirable",LEFT(H6,6)<>"Ciclón"),"Requiere ciclón (fracción respirable)",IF(AND(O6="Inhalable",ISNUMBER(SEARCH("Respirable",IFERROR(INDEX(Agentes!$C$80:$C$87,MATCH(H6,Agentes!$B$80:$B$87,0)),"")))),"El ciclón no colecta la fracción inhalable","Coherente")))) | Q6: =IF(Y6="","",IFERROR(INDEX(GES!$W$6:$W$35,MATCH(Y6,GES!$R$6:$R$35,0)),"")) | R6: =IF(AND(ISNUMBER(N6),ISNUMBER(Q6)),N6/Q6,"") | S6: =IF(C6="","",IFERROR(INDEX(Agentes!$I$6:$I$60,MATCH(C6,Agentes!$A$6:$A$60,0)),"")) | U6: =IF(ISNUMBER(N6),IF(N6>0,LN(N6),""),"") | V6: =IF(ISNUMBER(U6),IFERROR((U6-LN(IFERROR(INDEX(Estadística!$K$6:$K$35,MATCH(Y6,Estadística!$Y$6:$Y$35,0)),0)))^2,""),"") | W6: =IF(ISNUMBER(N6),IFERROR((N6-IFERROR(INDEX(Estadística!$I$6:$I$35,MATCH(Y6,Estadística!$Y$6:$Y$35,0)),0))^2,""),"") | X6: =IF(ISNUMBER(R6),IF(R6>1,1,0),"") | Y6: =IF(OR(B6="",C6=""),"",B6&"|"&C6)
A7: 2 | B7: G01 | C7: MN-R | D7: 46280 | E7: Soldador 2 | F7: G01-D2 | G7: Personal | H7: Ciclón nylon 10 mm | I7: 1.7 | J7: 470 | K7: =IF(OR(I7="",J7=""),"",I7*J7/1000) | L7: 0.00426 | N7: =IF(OR(B7="",C7=""),"",IF(M7<>"",M7,IF(AND(N(L7)>0,N(K7)>0),L7/K7,""))) | O7: =IF(C7="","",IFERROR(INDEX(Agentes!$D$6:$D$60,MATCH(C7,Agentes!$A$6:$A$60,0)),"")) | P7: =IF(OR(H7="",O7=""),"",IF(AND(O7="Inhalable",LEFT(H7,6)="Casete"),"Subestima: el casete cerrado no colecta toda la fracción inhalable",IF(AND(O7="Respirable",LEFT(H7,6)<>"Ciclón"),"Requiere ciclón (fracción respirable)",IF(AND(O7="Inhalable",ISNUMBER(SEARCH("Respirable",IFERROR(INDEX(Agentes!$C$80:$C$87,MATCH(H7,Agentes!$B$80:$B$87,0)),"")))),"El ciclón no colecta la fracción inhalable","Coherente")))) | Q7: =IF(Y7="","",IFERROR(INDEX(GES!$W$6:$W$35,MATCH(Y7,GES!$R$6:$R$35,0)),"")) | R7: =IF(AND(ISNUMBER(N7),ISNUMBER(Q7)),N7/Q7,"") | S7: =IF(C7="","",IFERROR(INDEX(Agentes!$I$6:$I$60,MATCH(C7,Agentes!$A$6:$A$60,0)),"")) | U7: =IF(ISNUMBER(N7),IF(N7>0,LN(N7),""),"") | V7: =IF(ISNUMBER(U7),IFERROR((U7-LN(IFERROR(INDEX(Estadística!$K$6:$K$35,MATCH(Y7,Estadística!$Y$6:$Y$35,0)),0)))^2,""),"") | W7: =IF(ISNUMBER(N7),IFERROR((N7-IFERROR(INDEX(Estadística!$I$6:$I$35,MATCH(Y7,Estadística!$Y$6:$Y$35,0)),0))^2,""),"") | X7: =IF(ISNUMBER(R7),IF(R7>1,1,0),"") | Y7: =IF(OR(B7="",C7=""),"",B7&"|"&C7)
A8: 3 | B8: G01 | C8: MN-R | D8: 46281 | E8: Soldador 3 | F8: G01-D3 | G8: Personal | H8: Ciclón nylon 10 mm | I8: 1.7 | J8: 420 | K8: =IF(OR(I8="",J8=""),"",I8*J8/1000) | L8: 0.01928 | N8: =IF(OR(B8="",C8=""),"",IF(M8<>"",M8,IF(AND(N(L8)>0,N(K8)>0),L8/K8,""))) | O8: =IF(C8="","",IFERROR(INDEX(Agentes!$D$6:$D$60,MATCH(C8,Agentes!$A$6:$A$60,0)),"")) | P8: =IF(OR(H8="",O8=""),"",IF(AND(O8="Inhalable",LEFT(H8,6)="Casete"),"Subestima: el casete cerrado no colecta toda la fracción inhalable",IF(AND(O8="Respirable",LEFT(H8,6)<>"Ciclón"),"Requiere ciclón (fracción respirable)",IF(AND(O8="Inhalable",ISNUMBER(SEARCH("Respirable",IFERROR(INDEX(Agentes!$C$80:$C$87,MATCH(H8,Agentes!$B$80:$B$87,0)),"")))),"El ciclón no colecta la fracción inhalable","Coherente")))) | Q8: =IF(Y8="","",IFERROR(INDEX(GES!$W$6:$W$35,MATCH(Y8,GES!$R$6:$R$35,0)),"")) | R8: =IF(AND(ISNUMBER(N8),ISNUMBER(Q8)),N8/Q8,"") | S8: =IF(C8="","",IFERROR(INDEX(Agentes!$I$6:$I$60,MATCH(C8,Agentes!$A$6:$A$60,0)),"")) | U8: =IF(ISNUMBER(N8),IF(N8>0,LN(N8),""),"") | V8: =IF(ISNUMBER(U8),IFERROR((U8-LN(IFERROR(INDEX(Estadística!$K$6:$K$35,MATCH(Y8,Estadística!$Y$6:$Y$35,0)),0)))^2,""),"") | W8: =IF(ISNUMBER(N8),IFERROR((N8-IFERROR(INDEX(Estadística!$I$6:$I$35,MATCH(Y8,Estadística!$Y$6:$Y$35,0)),0))^2,""),"") | X8: =IF(ISNUMBER(R8),IF(R8>1,1,0),"") | Y8: =IF(OR(B8="",C8=""),"",B8&"|"&C8)
A9: 4 | B9: G01 | C9: MN-R | D9: 46282 | E9: Soldador 4 | F9: G01-D4 | G9: Personal | H9: Ciclón nylon 10 mm | I9: 1.7 | J9: 450 | K9: =IF(OR(I9="",J9=""),"",I9*J9/1000) | L9: 0.01033 | N9: =IF(OR(B9="",C9=""),"",IF(M9<>"",M9,IF(AND(N(L9)>0,N(K9)>0),L9/K9,""))) | O9: =IF(C9="","",IFERROR(INDEX(Agentes!$D$6:$D$60,MATCH(C9,Agentes!$A$6:$A$60,0)),"")) | P9: =IF(OR(H9="",O9=""),"",IF(AND(O9="Inhalable",LEFT(H9,6)="Casete"),"Subestima: el casete cerrado no colecta toda la fracción inhalable",IF(AND(O9="Respirable",LEFT(H9,6)<>"Ciclón"),"Requiere ciclón (fracción respirable)",IF(AND(O9="Inhalable",ISNUMBER(SEARCH("Respirable",IFERROR(INDEX(Agentes!$C$80:$C$87,MATCH(H9,Agentes!$B$80:$B$87,0)),"")))),"El ciclón no colecta la fracción inhalable","Coherente")))) | Q9: =IF(Y9="","",IFERROR(INDEX(GES!$W$6:$W$35,MATCH(Y9,GES!$R$6:$R$35,0)),"")) | R9: =IF(AND(ISNUMBER(N9),ISNUMBER(Q9)),N9/Q9,"") | S9: =IF(C9="","",IFERROR(INDEX(Agentes!$I$6:$I$60,MATCH(C9,Agentes!$A$6:$A$60,0)),"")) | U9: =IF(ISNUMBER(N9),IF(N9>0,LN(N9),""),"") | V9: =IF(ISNUMBER(U9),IFERROR((U9-LN(IFERROR(INDEX(Estadística!$K$6:$K$35,MATCH(Y9,Estadística!$Y$6:$Y$35,0)),0)))^2,""),"") | W9: =IF(ISNUMBER(N9),IFERROR((N9-IFERROR(INDEX(Estadística!$I$6:$I$35,MATCH(Y9,Estadística!$Y$6:$Y$35,0)),0))^2,""),"") | X9: =IF(ISNUMBER(R9),IF(R9>1,1,0),"") | Y9: =IF(OR(B9="",C9=""),"",B9&"|"&C9)
A10: 5 | B10: G01 | C10: MN-R | D10: 46283 | E10: Soldador 5 | F10: G01-D5 | G10: Personal | H10: Ciclón nylon 10 mm | I10: 1.7 | J10: 470 | K10: =IF(OR(I10="",J10=""),"",I10*J10/1000) | L10: 0.006582 | N10: =IF(OR(B10="",C10=""),"",IF(M10<>"",M10,IF(AND(N(L10)>0,N(K10)>0),L10/K10,""))) | O10: =IF(C10="","",IFERROR(INDEX(Agentes!$D$6:$D$60,MATCH(C10,Agentes!$A$6:$A$60,0)),"")) | P10: =IF(OR(H10="",O10=""),"",IF(AND(O10="Inhalable",LEFT(H10,6)="Casete"),"Subestima: el casete cerrado no colecta toda la fracción inhalable",IF(AND(O10="Respirable",LEFT(H10,6)<>"Ciclón"),"Requiere ciclón (fracción respirable)",IF(AND(O10="Inhalable",ISNUMBER(SEARCH("Respirable",IFERROR(INDEX(Agentes!$C$80:$C$87,MATCH(H10,Agentes!$B$80:$B$87,0)),"")))),"El ciclón no colecta la fracción inhalable","Coherente")))) | Q10: =IF(Y10="","",IFERROR(INDEX(GES!$W$6:$W$35,MATCH(Y10,GES!$R$6:$R$35,0)),"")) | R10: =IF(AND(ISNUMBER(N10),ISNUMBER(Q10)),N10/Q10,"") | S10: =IF(C10="","",IFERROR(INDEX(Agentes!$I$6:$I$60,MATCH(C10,Agentes!$A$6:$A$60,0)),"")) | U10: =IF(ISNUMBER(N10),IF(N10>0,LN(N10),""),"") | V10: =IF(ISNUMBER(U10),IFERROR((U10-LN(IFERROR(INDEX(Estadística!$K$6:$K$35,MATCH(Y10,Estadística!$Y$6:$Y$35,0)),0)))^2,""),"") | W10: =IF(ISNUMBER(N10),IFERROR((N10-IFERROR(INDEX(Estadística!$I$6:$I$35,MATCH(Y10,Estadística!$Y$6:$Y$35,0)),0))^2,""),"") | X10: =IF(ISNUMBER(R10),IF(R10>1,1,0),"") | Y10: =IF(OR(B10="",C10=""),"",B10&"|"&C10)
A11: 6 | B11: G01 | C11: MN-R | D11: 46284 | E11: Soldador 6 | F11: G01-D6 | G11: Personal | H11: Ciclón nylon 10 mm | I11: 1.7 | J11: 420 | K11: =IF(OR(I11="",J11=""),"",I11*J11/1000) | L11: 0.00762 | N11: =IF(OR(B11="",C11=""),"",IF(M11<>"",M11,IF(AND(N(L11)>0,N(K11)>0),L11/K11,""))) | O11: =IF(C11="","",IFERROR(INDEX(Agentes!$D$6:$D$60,MATCH(C11,Agentes!$A$6:$A$60,0)),"")) | P11: =IF(OR(H11="",O11=""),"",IF(AND(O11="Inhalable",LEFT(H11,6)="Casete"),"Subestima: el casete cerrado no colecta toda la fracción inhalable",IF(AND(O11="Respirable",LEFT(H11,6)<>"Ciclón"),"Requiere ciclón (fracción respirable)",IF(AND(O11="Inhalable",ISNUMBER(SEARCH("Respirable",IFERROR(INDEX(Agentes!$C$80:$C$87,MATCH(H11,Agentes!$B$80:$B$87,0)),"")))),"El ciclón no colecta la fracción inhalable","Coherente")))) | Q11: =IF(Y11="","",IFERROR(INDEX(GES!$W$6:$W$35,MATCH(Y11,GES!$R$6:$R$35,0)),"")) | R11: =IF(AND(ISNUMBER(N11),ISNUMBER(Q11)),N11/Q11,"") | S11: =IF(C11="","",IFERROR(INDEX(Agentes!$I$6:$I$60,MATCH(C11,Agentes!$A$6:$A$60,0)),"")) | U11: =IF(ISNUMBER(N11),IF(N11>0,LN(N11),""),"") | V11: =IF(ISNUMBER(U11),IFERROR((U11-LN(IFERROR(INDEX(Estadística!$K$6:$K$35,MATCH(Y11,Estadística!$Y$6:$Y$35,0)),0)))^2,""),"") | W11: =IF(ISNUMBER(N11),IFERROR((N11-IFERROR(INDEX(Estadística!$I$6:$I$35,MATCH(Y11,Estadística!$Y$6:$Y$35,0)),0))^2,""),"") | X11: =IF(ISNUMBER(R11),IF(R11>1,1,0),"") | Y11: =IF(OR(B11="",C11=""),"",B11&"|"&C11)
