Workbook

Sheet Portada

Sheet Evaluación
A1: HeatStressRisk - Método de Evaluación (Método 1)
A3: INSTRUCCIONES DE ENTRADA
A4: WBGT (°C) | C4: °C (medido o estimado)
A5: Tasa Metabólica (W) | C5: W (ver 'Datos de Referencia')
A6: Aclimatación | C6: Lista desplegable
A7: CAV de Ropa (°C) | C7: °C (ver 'Datos de Referencia')
A8: Patrón de Trabajo (%) | C8: % del turno (informativo)
A11: RESULTADOS CALCULADOS
A12: TLV (°C-WBGT) | B12: =IF(N(B5)>0,56.7-11.5*LOG10(B5),"")
A13: AL (°C-WBGT) | B13: =IF(N(B5)>0,59.9-14.1*LOG10(B5),"")
A14: Aclimatación Ajuste (°C) | B14: =IF(B6="Aclimatado",0,-3)
A15: TLV Ajustado | B15: =IF(B12="","",B12+B14)
A16: AL Ajustado | B16: =IF(B13="","",B13+B14)
A17: WBGT Efectivo (con ropa) | B17: =IF(ISNUMBER(B4),B4+N(B7),"")
A19: CLASIFICACIÓN DE SEVERIDAD
A20: Severidad | B20: =IF(OR(B15="",B17=""),"SIN DATOS",IF(B17<B16,"ACEPTABLE",IF(B17<B15,"PRECAUCIÓN",IF(B17<B15+3,"MODERADO",IF(B17<B15+6,"ALTO","EXTREMADAMENTE ALTO")))))
A22: RECOMENDACIONES
A23: Nivel 1 (General) | B23: Siempre
A24: Nivel 2 (Específico) | B24: =IF(B20="MODERADO","Sí",IF(B20="ALTO","Sí",IF(B20="EXTREMADAMENTE ALTO","Sí","No")))
A25: Nivel 3 (Monitoreo) | B25: =IF(B20="ALTO","Sí",IF(B20="EXTREMADAMENTE ALTO","Sí","No"))
A27: PLAN DE CONTROL Y PHS (NUEVO EN V2)
A28: Recomendaciones automáticas | B28: Hoja 'Plan de Control'
A29: Tensión térmica predicha (PHS) | B29: Hoja 'PHS' (usa 'Análisis Detallado')

Sheet Datos de Referencia
A1: TASAS METABÓLICAS | D1: VALORES DE ROPA
A2: Categoría | B2: Tasa (W) | D2: Tipo de Ropa | E2: CAV (°C) | G2: ESTADOS DE ACLIMATACIÓN | H2: Ajuste TLV/AL (°C)
A3: Descanso (sentado) | B3: 115 | D3: Estándar (mangas largas) | E3: 0 | G3: Aclimatado | H3: 0
A4: Trabajo Ligero | B4: 180 | D4: Verano Ligero | E4: -1 | G4: Parcialmente aclimatado (75%) | H4: -3
A5: Ligero-Moderado | B5: 235 | D5: Monos Ligeros | E5: 0.5 | G5: Parcialmente aclimatado (50%) | H5: -3
A6: Moderado | B6: 300 | D6: Protección Pesada | E6: 3 | G6: No aclimatado (25%) | H6: -3
A7: Pesado | B7: 415 | D7: Barrera de Vapor | E7: 10 | G7: La hoja aplica −3 °C a TLV y AL con cualquier estado distinto de 'Aclimatado' (criterio conservador). PHS lo interpreta como aclimatado (Sí/No).
A8: Muy Pesado | B8: 520
G11: POSTURA (PHS)
A12: NIVELES DE SEVERIDAD | G12: De pie
A13: Nivel | B13: Rango | C13: Acción | G13: Sentado
A14: ACEPTABLE | B14: <AL | C14: Conciencia General | G14: En cuclillas
A15: PRECAUCIÓN | B15: AL-TLV | C15: Nivel 1
A16: MODERADO | B16: TLV a +3°C | C16: Nivel 1+2 | G16: TIPO DE EXPOSICIÓN (Plan de Control)
A17: ALTO | B17: +3°C a +6°C | C17: Nivel 1+2+3 | G17: Exterior con radiación solar
A18: EXTREMADAMENTE ALTO | B18: >+6°C | C18: Todos los Niveles | G18: Interior con fuente radiante
G19: Interior sin fuente radiante
G20: Interior húmedo (vapor/procesos)
A21: LÍMITES DE VALIDEZ ISO 7933:2023 (PHS)
A22: Variable | B22: Mín | C22: Máx | G22: SÍ / NO
A23: Temperatura de aire Tbs (°C) | B23: 15 | C23: 50 | G23: Sí
A24: Tr − Tbs (°C) | B24: 0 | C24: 60 | G24: No
A25: Velocidad del aire (m/s) | B25: 0 | C25: 3
A26: Presión de vapor Pa (kPa) | B26: 0.5 | C26: 4.5
A27: Tasa metabólica M (W/m²) | B27: 56 | C27: 250
A28: Aislamiento de ropa (clo) | B28: 0.1 | C28: 1
A29: Fuente: Anexo A de ISO 7933:2023, según la implementación de referencia de código abierto (pythermalcomfort 4.6.0).
A31: AISLAMIENTO DE ROPA (clo) – orientativo
A32: Conjunto de ropa | B32: clo
A33: Pantalón corto y camisa manga corta | B33: 0.36
A34: Pantalón largo y camisa manga corta | B34: 0.57
A35: Pantalón largo y camisa manga larga | B35: 0.61
A36: Anterior + chaqueta | B36: 0.96
A37: Valores típicos ASHRAE 55 / ISO 9920 (incluyen ropa interior, medias y zapatos). Verifique con ISO 9920 o el fabricante para ropa de trabajo específica.

Sheet Análisis Detallado
A1: HeatStressRisk - Método de Análisis Detallado
G2: Datos ambientales para PHS (opcionales si no usa PHS)
A3: DESGLOSE DE TAREAS | B3: ACTIVIDAD | C3: DURACION ( Hr ) | D3: WBGT | E3: TASA METABOLICA (W) | F3: DURACION X WBGT | G3: Tbs (°C) | H3: Tg (°C) | I3: HR (%) | J3: Vel. aire (m/s)
F4: =C4*D4
F5: =C5*D5
F6: =C6*D6
F7: =C7*D7
F8: =C8*D8
F9: =C9*D9
F10: =C10*D10
F11: =C11*D11
A12: PROMEDIOS PONDERADOS POR TIEMPO
A13: Duración Total (h) | B13: =SUM(C4:C11)
A14: PPA-WBGT (°C) | B14: =IF(B13>0,SUM(F4:F11)/B13,0)
A15: PPA-Tasa Metabólica (W) | B15: =IF(B13>0,SUMPRODUCT(C4:C11,E4:E11)/B13,0)
A17: CLASIFICACIÓN ACGIH (con promedios ponderados)
A18: Aclimatación | C18: Se usan en la clasificación ACGIH y en PHS (aclimatación) y en el Plan de Control.
A19: CAV de Ropa (°C)
A20: TLV (°C-WBGT) con PPA-M | B20: =IF(N(B15)>0,56.7-11.5*LOG10(B15),"")
A21: AL (°C-WBGT) con PPA-M | B21: =IF(N(B15)>0,59.9-14.1*LOG10(B15),"")
A22: Aclimatación Ajuste (°C) | B22: =IF(B18="Aclimatado",0,-3)
A23: TLV Ajustado | B23: =IF(B20="","",B20+B22)
A24: AL Ajustado | B24: =IF(B21="","",B21+B22)
A25: WBGT Efectivo (PPA-WBGT + CAV) | B25: =IF(AND(B13>0,COUNT(D4:D11)>0),B14+N(B19),"")
A26: Severidad | B26: =IF(OR(B23="",B25=""),"SIN DATOS",IF(B25<B24,"ACEPTABLE",IF(B25<B23,"PRECAUCIÓN",IF(B25<B23+3,"MODERADO",IF(B25<B23+6,"ALTO","EXTREMADAMENTE ALTO")))))
A27: Nivel 2 (Específico) | B27: =IF(OR(B26="MODERADO",B26="ALTO",B26="EXTREMADAMENTE ALTO"),"Sí","No")
A28: Nivel 3 (Monitoreo) | B28: =IF(OR(B26="ALTO",B26="EXTREMADAMENTE ALTO"),"Sí","No")

Sheet PHS
A1: HeatStressRisk – Tensión Térmica Predicha (PHS, ISO 7933:2023)
A2: Simula minuto a minuto la temperatura rectal y la pérdida de agua de una persona promedio para la secuencia de tareas de la hoja 'Análisis Detallado' (columnas C, E y G–J). Para una exposición homogénea use una sola fila (p. ej., 8 h).
A4: PARÁMETROS DEL TRABAJADOR Y DE LA ROPA (celdas amarillas)
A5: Peso corporal (kg) | B5: 75 | C5: Referencia ISO 7933: 75 kg. Ajuste a su población.
A6: Estatura (m) | B6: 1.8 | C6: Referencia ISO 7933: 1.80 m.
A7: Postura | B7: De pie | C7: Lista desplegable.
A8: Aclimatación | B8: =IF('Análisis Detallado'!B18="","",'Análisis Detallado'!B18) | C8: Se toma de la hoja 'Análisis Detallado' (celda B18). Se interpreta como aclimatado solo si dice 'Aclimatado'.
A9: Aislamiento de la ropa (clo) | B9: 0.6 | C9: Ver tabla en 'Datos de Referencia'. Con CAV ≥ 3 °C use un clo mayor. Rango válido 0.1–1.0.
A10: Velocidad de caminata (m/s) | B10: 0 | C10: 0 = estimada automáticamente a partir de la tasa metabólica (según la norma).
A11: Diámetro del globo (mm) | B11: 150 | C11: Para calcular Tr desde Tg (ISO 7726). Globo estándar 150 mm; globos pequeños 50–75 mm.
A12: Emisividad del globo | B12: 0.95 | C12: Globo negro ≈ 0.95.
A14: ESTADO DEL ANÁLISIS
A15: Duración total simulada (min) | B15: ='Motor PHS'!B25 | C15: Suma de las duraciones de 'Análisis Detallado'. Máximo 720 min (12 h).
A16: Estado de los datos | B16: =IF('Motor PHS'!B25=0,"Sin tareas: ingrese duración, tasa metabólica y condiciones ambientales en 'Análisis Detallado'.",IF('Motor PHS'!B25>720,"La duración total excede 720 min (12 h): reduzca la secuencia.",IF('Motor PHS'!B39>0,"Faltan datos en: "&IF(AND('Motor PHS'!E61=1,'Motor PHS'!F61=0),"T1 ","")&IF(AND('Motor PHS'!E62=1,'Motor PHS'!F62=0),"T2 ","")&IF(AND('Motor PHS'!E63=1,'Motor PHS'!F63=0),"T3 ","")&IF(AND('Motor PHS'!E64=1,'Motor PHS'!F64=0),"T4 ","")&IF(AND('Motor PHS'!E65=1,'Motor PHS'!F65=0),"T5 ","")&IF(AND('Motor PHS'!E66=1,'Motor PHS'!F66=0),"T6 ","")&IF(AND('Motor PHS'!E67=1,'Motor PHS'!F67=0),"T7 ","")&IF(AND('Motor PHS'!E68=1,'Motor PHS'!F68=0),"T8 ","")&"(complete duración, Tbs, Tg, HR, v y M).",IF(OR(N(B5)<=0,N(B6)<=0),"Complete peso y estatura.","Datos completos"))))
A17: Validez según ISO 7933:2023 | B17: =IF('Motor PHS'!B45=0,"—",IF('Motor PHS'!B45=3,"NO APLICABLE: "&IF('Motor PHS'!B41>0,"variables fuera del rango de validez en alguna tarea (ver detalle). ","")&IF('Motor PHS'!B42=0,"Aislamiento de ropa fuera de 0.1–1.0 clo. ","")&IF('Motor PHS'!B43=1,"Ropa con barrera de vapor: PHS no aplica. ",""),IF('Motor PHS'!B45=2,"Válido con advertencia: tareas con M < 56 W/m² (límite inferior de la norma; típico de reposo).","Dentro del rango de validez")))
A19: RESULTADOS PHS
A20: Temperatura rectal al final de la exposición (°C) | B20: =IF(OR('Motor PHS'!B45=1,'Motor PHS'!B45=2),'Motor PHS'!B52,"") | C20: Límite de referencia ISO 7933: 38.0 °C.
A21: Temperatura rectal máxima alcanzada (°C) | B21: =IF(OR('Motor PHS'!B45=1,'Motor PHS'!B45=2),'Motor PHS'!B53,"")
A22: Pérdida de agua total estimada (g) | B22: =IF(OR('Motor PHS'!B45=1,'Motor PHS'!B45=2),'Motor PHS'!B54,"") | C22: Incluye sudor y evaporación respiratoria.
A23: Pérdida de agua (% del peso corporal) | B23: =IF(OR('Motor PHS'!B45=1,'Motor PHS'!B45=2),'Motor PHS'!B57,"") | C23: Límite de referencia: 5 % con hidratación libre.
A24: Pérdida de agua promedio (L/h) | B24: =IF(OR('Motor PHS'!B45=1,'Motor PHS'!B45=2),'Motor PHS'!B56,"") | C24: Ingesta oral recomendada ≈ 1.4 L/h como máximo.
A25: Tiempo hasta Tre ≥ 38 °C – Dlim,Tre (min) | B25: =IF(OR('Motor PHS'!B45=1,'Motor PHS'!B45=2),IF('Motor PHS'!B48=1,'Motor PHS'!B46,"No alcanzado"),"")
A26: Tiempo hasta pérdida de agua límite – Dlim,agua (min) | B26: =IF(OR('Motor PHS'!B45=1,'Motor PHS'!B45=2),IF('Motor PHS'!B49=1,'Motor PHS'!B47,"No alcanzado"),"")
A27: Tiempo máximo de exposición – Dlim (min) | B27: =IF(OR('Motor PHS'!B45=1,'Motor PHS'!B45=2),'Motor PHS'!B50,"") | C27: Menor de los dos tiempos, o la duración total si no se alcanzan.
A28: Factor limitante | B28: =IF(OR('Motor PHS'!B45=1,'Motor PHS'!B45=2),IF(AND('Motor PHS'!B48=0,'Motor PHS'!B49=0),"Ninguno (límites no alcanzados)",IF(AND('Motor PHS'!B48=1,OR('Motor PHS'!B49=0,'Motor PHS'!B46<='Motor PHS'!B47)),"Temperatura rectal","Pérdida de agua")),"")
A29: CONCLUSIÓN PHS | B29: =IF('Motor PHS'!B45=0,"Sin resultados: complete los datos indicados arriba.",IF('Motor PHS'!B45=3,"NO APLICABLE: PHS no debe interpretarse con estos datos (ver validez).",IF('Motor PHS'!B51=1,"LÍMITE ALCANZADO a los "&'Motor PHS'!B50&" min de exposición continua (factor limitante: "&B28&"). La exposición no es tolerable durante los "&'Motor PHS'!B25&" min simulados.","TOLERABLE: no se alcanzan los límites de temperatura rectal ni de pérdida de agua durante los "&'Motor PHS'!B25&" min simulados (Tre máx. "&ROUND('Motor PHS'!B53,1)&" °C).")))
A31: DETALLE POR TAREA (desde 'Análisis Detallado')
A32: Tarea | B32: Duración (min) | C32: Tr (°C) | D32: Pa (kPa) | E32: M (W/m²) | F32: Validez ISO 7933
A33: =IF('Motor PHS'!E61=1,"T1 – "&'Motor PHS'!B61,"") | B33: =IF('Motor PHS'!E61=1,'Motor PHS'!C61,"") | C33: =IF('Motor PHS'!E61=1,IF('Motor PHS'!F61=1,'Motor PHS'!L61,""),"") | D33: =IF('Motor PHS'!E61=1,IF('Motor PHS'!F61=1,'Motor PHS'!M61,""),"") | E33: =IF('Motor PHS'!E61=1,IF('Motor PHS'!F61=1,'Motor PHS'!N61,""),"") | F33: ='Motor PHS'!AQ61
A34: =IF('Motor PHS'!E62=1,"T2 – "&'Motor PHS'!B62,"") | B34: =IF('Motor PHS'!E62=1,'Motor PHS'!C62,"") | C34: =IF('Motor PHS'!E62=1,IF('Motor PHS'!F62=1,'Motor PHS'!L62,""),"") | D34: =IF('Motor PHS'!E62=1,IF('Motor PHS'!F62=1,'Motor PHS'!M62,""),"") | E34: =IF('Motor PHS'!E62=1,IF('Motor PHS'!F62=1,'Motor PHS'!N62,""),"") | F34: ='Motor PHS'!AQ62
A35: =IF('Motor PHS'!E63=1,"T3 – "&'Motor PHS'!B63,"") | B35: =IF('Motor PHS'!E63=1,'Motor PHS'!C63,"") | C35: =IF('Motor PHS'!E63=1,IF('Motor PHS'!F63=1,'Motor PHS'!L63,""),"") | D35: =IF('Motor PHS'!E63=1,IF('Motor PHS'!F63=1,'Motor PHS'!M63,""),"") | E35: =IF('Motor PHS'!E63=1,IF('Motor PHS'!F63=1,'Motor PHS'!N63,""),"") | F35: ='Motor PHS'!AQ63
A36: =IF('Motor PHS'!E64=1,"T4 – "&'Motor PHS'!B64,"") | B36: =IF('Motor PHS'!E64=1,'Motor PHS'!C64,"") | C36: =IF('Motor PHS'!E64=1,IF('Motor PHS'!F64=1,'Motor PHS'!L64,""),"") | D36: =IF('Motor PHS'!E64=1,IF('Motor PHS'!F64=1,'Motor PHS'!M64,""),"") | E36: =IF('Motor PHS'!E64=1,IF('Motor PHS'!F64=1,'Motor PHS'!N64,""),"") | F36: ='Motor PHS'!AQ64
A37: =IF('Motor PHS'!E65=1,"T5 – "&'Motor PHS'!B65,"") | B37: =IF('Motor PHS'!E65=1,'Motor PHS'!C65,"") | C37: =IF('Motor PHS'!E65=1,IF('Motor PHS'!F65=1,'Motor PHS'!L65,""),"") | D37: =IF('Motor PHS'!E65=1,IF('Motor PHS'!F65=1,'Motor PHS'!M65,""),"") | E37: =IF('Motor PHS'!E65=1,IF('Motor PHS'!F65=1,'Motor PHS'!N65,""),"") | F37: ='Motor PHS'!AQ65
A38: =IF('Motor PHS'!E66=1,"T6 – "&'Motor PHS'!B66,"") | B38: =IF('Motor PHS'!E66=1,'Motor PHS'!C66,"") | C38: =IF('Motor PHS'!E66=1,IF('Motor PHS'!F66=1,'Motor PHS'!L66,""),"") | D38: =IF('Motor PHS'!E66=1,IF('Motor PHS'!F66=1,'Motor PHS'!M66,""),"") | E38: =IF('Motor PHS'!E66=1,IF('Motor PHS'!F66=1,'Motor PHS'!N66,""),"") | F38: ='Motor PHS'!AQ66
A39: =IF('Motor PHS'!E67=1,"T7 – "&'Motor PHS'!B67,"") | B39: =IF('Motor PHS'!E67=1,'Motor PHS'!C67,"") | C39: =IF('Motor PHS'!E67=1,IF('Motor PHS'!F67=1,'Motor PHS'!L67,""),"") | D39: =IF('Motor PHS'!E67=1,IF('Motor PHS'!F67=1,'Motor PHS'!M67,""),"") | E39: =IF('Motor PHS'!E67=1,IF('Motor PHS'!F67=1,'Motor PHS'!N67,""),"") | F39: ='Motor PHS'!AQ67
A40: =IF('Motor PHS'!E68=1,"T8 – "&'Motor PHS'!B68,"") | B40: =IF('Motor PHS'!E68=1,'Motor PHS'!C68,"") | C40: =IF('Motor PHS'!E68=1,IF('Motor PHS'!F68=1,'Motor PHS'!L68,""),"") | D40: =IF('Motor PHS'!E68=1,IF('Motor PHS'!F68=1,'Motor PHS'!M68,""),"") | E40: =IF('Motor PHS'!E68=1,IF('Motor PHS'!F68=1,'Motor PHS'!N68,""),"") | F40: ='Motor PHS'!AQ68
A42: NOTAS Y LIMITACIONES
A43: • Modelo: ISO 7933:2023 (Predicted Heat Strain). Las ecuaciones siguen la implementación de referencia de código abierto pythermalcomfort 4.6.0; hidratación libre (ingesta permitida) y temperatura rectal inicial de 36.8 °C.
A44: • Tr se calcula a partir de Tg, Tbs y velocidad del aire (ISO 7726) y Pa a partir de Tbs y HR. La tasa metabólica en W se convierte a W/m² con la superficie corporal (DuBois).
A45: • No aplica a ropa de protección especial (reflectiva total, enfriamiento activo o ventilación, monos impermeables o con barrera de vapor).
...

Sheet Plan de Control
A1: HeatStressRisk – Plan de Control Automático
A2: Genera recomendaciones a partir de la severidad ACGIH y, si está disponible, de PHS. Las reglas se pueden editar en la hoja 'Biblioteca de Controles'. Es una ayuda para el profesional: la decisión final es del higienista/SST responsable.
A4: ENTRADAS (celdas amarillas) | F4: CONDICIONES EVALUADAS | G4: Cumple | H4: Descripción
A5: Fuente de la evaluación ACGIH | D5: Evaluación (Método 1) | F5: S | G5: =1 | H5: Siempre
A6: Tipo de exposición | D6: Exterior con radiación solar | F6: EXT | G6: =IF($D$6='Datos de Referencia'!$G$17,1,0) | H6: Exterior con radiación solar
A7: ¿Hay trabajadores susceptibles o embarazadas? | D7: No | F7: RAD | G7: =IF($D$6='Datos de Referencia'!$G$18,1,0) | H7: Interior con fuente radiante
F8: INT | G8: =IF($D$6='Datos de Referencia'!$G$19,1,0) | H8: Interior sin fuente radiante
A9: RESULTADO DE LA EVALUACIÓN (automático) | F9: HUM | G9: =IF($D$6='Datos de Referencia'!$G$20,1,0) | H9: Interior húmedo (vapor/procesos)
A10: Severidad ACGIH | D10: =IF($D$5="Análisis Detallado",'Análisis Detallado'!B26,Evaluación!B20) | F10: INTERIOR | G10: =IF(OR(G7=1,G8=1,G9=1),1,0) | H10: Cualquier ambiente interior
A11: Nivel de severidad (0 = sin datos; 1 a 5) | D11: =IF(D10="ACEPTABLE",1,IF(D10="PRECAUCIÓN",2,IF(D10="MODERADO",3,IF(D10="ALTO",4,IF(D10="EXTREMADAMENTE ALTO",5,0))))) | F11: RADIANTE | G11: =IF(OR(G6=1,G7=1),1,0) | H11: Carga de calor radiante (exterior o fuente radiante)
A12: WBGT efectivo (°C) | D12: =IF($D$5="Análisis Detallado",'Análisis Detallado'!B25,Evaluación!B17) | F12: NOACL | G12: =IF(D17="",0,IF(D17="Aclimatado",0,1)) | H12: Trabajadores no (o parcialmente) aclimatados
A13: TLV ajustado (°C) | D13: =IF($D$5="Análisis Detallado",'Análisis Detallado'!B23,Evaluación!B15) | F13: ROPA | G13: =IF(N(D18)>=3,1,0) | H13: CAV ≥ 3 °C (ropa que restringe la disipación de calor)
A14: AL ajustado (°C) | D14: =IF($D$5="Análisis Detallado",'Análisis Detallado'!B24,Evaluación!B16) | F14: BARRERA | G14: =IF(N(D18)>=10,1,0) | H14: CAV ≥ 10 °C (barrera de vapor)
A15: Diferencia WBGT efectivo − TLV ajustado (°C) | D15: =IF(AND(ISNUMBER(D12),ISNUMBER(D13)),D12-D13,"") | F15: MET | G15: =IF(N(D16)>=300,1,0) | H15: Tasa metabólica ≥ 300 W
A16: Tasa metabólica (W) | D16: =IF($D$5="Análisis Detallado",'Análisis Detallado'!B15,Evaluación!B5) | F16: SUSC | G16: =IF(D7="Sí",1,0) | H16: Trabajadores susceptibles o embarazadas
A17: Aclimatación | D17: =IF($D$5="Análisis Detallado",'Análisis Detallado'!B18,Evaluación!B6)&"" | F17: PHS_OK | G17: =IF(OR('Motor PHS'!B45=1,'Motor PHS'!B45=2),1,0) | H17: PHS disponible y válido
A18: CAV de ropa (°C) | D18: =IF($D$5="Análisis Detallado",'Análisis Detallado'!B19,Evaluación!B7) | F18: PHS_LIM | G18: ='Motor PHS'!B51 | H18: PHS: límite fisiológico alcanzado
A19: Controles requeridos según severidad | D19: =IF(D11=0,"Sin datos",IF(D11=1,"Conciencia general",IF(D11=2,"Nivel 1",IF(D11=3,"Niveles 1 + 2",IF(D11=4,"Niveles 1 + 2 + 3","Todos los niveles + acción urgente"))))) | F19: PHS_SW_HIGH | G19: =IF(AND(G17=1,N('Motor PHS'!B56)>1.4),1,0) | H19: PHS: pérdida de agua > 1.4 L/h
A20: Resultado PHS (ISO 7933:2023) | D20: =IF('Motor PHS'!B45=0,"Sin resultados PHS (ver hoja PHS)",IF('Motor PHS'!B45=3,"PHS no aplicable (ver hoja PHS)",IF('Motor PHS'!B51=1,"PHS: límite fisiológico a los "&'Motor PHS'!B50&" min de "&'Motor PHS'!B25&" min","PHS: exposición tolerable durante "&'Motor PHS'!B25&" min")))
A22: RESUMEN
A23: =IF(D11=0,"Complete la evaluación ACGIH (hoja 'Evaluación' o 'Análisis Detallado') para generar el plan completo. Si ya ejecutó PHS, sus recomendaciones se muestran abajo.","Severidad "&D10&": WBGT efectivo "&ROUND(D12,1)&" °C frente a TLV ajustado "&ROUND(D13,1)&" °C ("&IF(D15>=0,"+","")&ROUND(D15,1)&" °C). Controles requeridos: "&D19&". "&D20&".")
A25: PLAN DE CONTROL RECOMENDADO
A26: N° | B26: Nivel | C26: Tipo de control | D26: Recomendación
A27: =IF(1<=COUNTIF('Biblioteca de Controles'!$H$5:$H$37,1),1,"") | B27: =IF($A27="","",INDEX('Biblioteca de Controles'!$B$5:$B$37,MATCH($A27,'Biblioteca de Controles'!$I$5:$I$37,0))) | C27: =IF($A27="","",INDEX('Biblioteca de Controles'!$C$5:$C$37,MATCH($A27,'Biblioteca de Controles'!$I$5:$I$37,0))) | D27: =IF($A27="","",INDEX('Biblioteca de Controles'!$D$5:$D$37,MATCH($A27,'Biblioteca de Controles'!$I$5:$I$37,0)))
A28: =IF(2<=COUNTIF('Biblioteca de Controles'!$H$5:$H$37,1),2,"") | B28: =IF($A28="","",INDEX('Biblioteca de Controles'!$B$5:$B$37,MATCH($A28,'Biblioteca de Controles'!$I$5:$I$37,0))) | C28: =IF($A28="","",INDEX('Biblioteca de Controles'!$C$5:$C$37,MATCH($A28,'Biblioteca de Controles'!$I$5:$I$37,0))) | D28: =IF($A28="","",INDEX('Biblioteca de Controles'!$D$5:$D$37,MATCH($A28,'Biblioteca de Controles'!$I$5:$I$37,0)))
A29: =IF(3<=COUNTIF('Biblioteca de Controles'!$H$5:$H$37,1),3,"") | B29: =IF($A29="","",INDEX('Biblioteca de Controles'!$B$5:$B$37,MATCH($A29,'Biblioteca de Controles'!$I$5:$I$37,0))) | C29: =IF($A29="","",INDEX('Biblioteca de Controles'!$C$5:$C$37,MATCH($A29,'Biblioteca de Controles'!$I$5:$I$37,0))) | D29: =IF($A29="","",INDEX('Biblioteca de Controles'!$D$5:$D$37,MATCH($A29,'Biblioteca de Controles'!$I$5:$I$37,0)))
A30: =IF(4<=COUNTIF('Biblioteca de Controles'!$H$5:$H$37,1),4,"") | B30: =IF($A30="","",INDEX('Biblioteca de Controles'!$B$5:$B$37,MATCH($A30,'Biblioteca de Controles'!$I$5:$I$37,0))) | C30: =IF($A30="","",INDEX('Biblioteca de Controles'!$C$5:$C$37,MATCH($A30,'Biblioteca de Controles'!$I$5:$I$37,0))) | D30: =IF($A30="","",INDEX('Biblioteca de Controles'!$D$5:$D$37,MATCH($A30,'Biblioteca de Controles'!$I$5:$I$37,0)))
A31: =IF(5<=COUNTIF('Biblioteca de Controles'!$H$5:$H$37,1),5,"") | B31: =IF($A31="","",INDEX('Biblioteca de Controles'!$B$5:$B$37,MATCH($A31,'Biblioteca de Controles'!$I$5:$I$37,0))) | C31: =IF($A31="","",INDEX('Biblioteca de Controles'!$C$5:$C$37,MATCH($A31,'Biblioteca de Controles'!$I$5:$I$37,0))) | D31: =IF($A31="","",INDEX('Biblioteca de Controles'!$D$5:$D$37,MATCH($A31,'Biblioteca de Controles'!$I$5:$I$37,0)))
A32: =IF(6<=COUNTIF('Biblioteca de Controles'!$H$5:$H$37,1),6,"") | B32: =IF($A32="","",INDEX('Biblioteca de Controles'!$B$5:$B$37,MATCH($A32,'Biblioteca de Controles'!$I$5:$I$37,0))) | C32: =IF($A32="","",INDEX('Biblioteca de Controles'!$C$5:$C$37,MATCH($A32,'Biblioteca de Controles'!$I$5:$I$37,0))) | D32: =IF($A32="","",INDEX('Biblioteca de Controles'!$D$5:$D$37,MATCH($A32,'Biblioteca de Controles'!$I$5:$I$37,0)))
A33: =IF(7<=COUNTIF('Biblioteca de Controles'!$H$5:$H$37,1),7,"") | B33: =IF($A33="","",INDEX('Biblioteca de Controles'!$B$5:$B$37,MATCH($A33,'Biblioteca de Controles'!$I$5:$I$37,0))) | C33: =IF($A33="","",INDEX('Biblioteca de Controles'!$C$5:$C$37,MATCH($A33,'Biblioteca de Controles'!$I$5:$I$37,0))) | D33: =IF($A33="","",INDEX('Biblioteca de Controles'!$D$5:$D$37,MATCH($A33,'Biblioteca de Controles'!$I$5:$I$37,0)))
A34: =IF(8<=COUNTIF('Biblioteca de Controles'!$H$5:$H$37,1),8,"") | B34: =IF($A34="","",INDEX('Biblioteca de Controles'!$B$5:$B$37,MATCH($A34,'Biblioteca de Controles'!$I$5:$I$37,0))) | C34: =IF($A34="","",INDEX('Biblioteca de Controles'!$C$5:$C$37,MATCH($A34,'Biblioteca de Controles'!$I$5:$I$37,0))) | D34: =IF($A34="","",INDEX('Biblioteca de Controles'!$D$5:$D$37,MATCH($A34,'Biblioteca de Controles'!$I$5:$I$37,0)))
A35: =IF(9<=COUNTIF('Biblioteca de Controles'!$H$5:$H$37,1),9,"") | B35: =IF($A35="","",INDEX('Biblioteca de Controles'!$B$5:$B$37,MATCH($A35,'Biblioteca de Controles'!$I$5:$I$37,0))) | C35: =IF($A35="","",INDEX('Biblioteca de Controles'!$C$5:$C$37,MATCH($A35,'Biblioteca de Controles'!$I$5:$I$37,0))) | D35: =IF($A35="","",INDEX('Biblioteca de Controles'!$D$5:$D$37,MATCH($A35,'Biblioteca de Controles'!$I$5:$I$37,0)))
A36: =IF(10<=COUNTIF('Biblioteca de Controles'!$H$5:$H$37,1),10,"") | B36: =IF($A36="","",INDEX('Biblioteca de Controles'!$B$5:$B$37,MATCH($A36,'Biblioteca de Controles'!$I$5:$I$37,0))) | C36: =IF($A36="","",INDEX('Biblioteca de Controles'!$C$5:$C$37,MATCH($A36,'Biblioteca de Controles'!$I$5:$I$37,0))) | D36: =IF($A36="","",INDEX('Biblioteca de Controles'!$D$5:$D$37,MATCH($A36,'Biblioteca de Controles'!$I$5:$I$37,0)))
A37: =IF(11<=COUNTIF('Biblioteca de Controles'!$H$5:$H$37,1),11,"") | B37: =IF($A37="","",INDEX('Biblioteca de Controles'!$B$5:$B$37,MATCH($A37,'Biblioteca de Controles'!$I$5:$I$37,0))) | C37: =IF($A37="","",INDEX('Biblioteca de Controles'!$C$5:$C$37,MATCH($A37,'Biblioteca de Controles'!$I$5:$I$37,0))) | D37: =IF($A37="","",INDEX('Biblioteca de Controles'!$D$5:$D$37,MATCH($A37,'Biblioteca de Controles'!$I$5:$I$37,0)))
A38: =IF(12<=COUNTIF('Biblioteca de Controles'!$H$5:$H$37,1),12,"") | B38: =IF($A38="","",INDEX('Biblioteca de Controles'!$B$5:$B$37,MATCH($A38,'Biblioteca de Controles'!$I$5:$I$37,0))) | C38: =IF($A38="","",INDEX('Biblioteca de Controles'!$C$5:$C$37,MATCH($A38,'Biblioteca de Controles'!$I$5:$I$37,0))) | D38: =IF($A38="","",INDEX('Biblioteca de Controles'!$D$5:$D$37,MATCH($A38,'Biblioteca de Controles'!$I$5:$I$37,0)))
A39: =IF(13<=COUNTIF('Biblioteca de Controles'!$H$5:$H$37,1),13,"") | B39: =IF($A39="","",INDEX('Biblioteca de Controles'!$B$5:$B$37,MATCH($A39,'Biblioteca de Controles'!$I$5:$I$37,0))) | C39: =IF($A39="","",INDEX('Biblioteca de Controles'!$C$5:$C$37,MATCH($A39,'Biblioteca de Controles'!$I$5:$I$37,0))) | D39: =IF($A39="","",INDEX('Biblioteca de Controles'!$D$5:$D$37,MATCH($A39,'Biblioteca de Controles'!$I$5:$I$37,0)))
A40: =IF(14<=COUNTIF('Biblioteca de Controles'!$H$5:$H$37,1),14,"") | B40: =IF($A40="","",INDEX('Biblioteca de Controles'!$B$5:$B$37,MATCH($A40,'Biblioteca de Controles'!$I$5:$I$37,0))) | C40: =IF($A40="","",INDEX('Biblioteca de Controles'!$C$5:$C$37,MATCH($A40,'Biblioteca de Controles'!$I$5:$I$37,0))) | D40: =IF($A40="","",INDEX('Biblioteca de Controles'!$D$5:$D$37,MATCH($A40,'Biblioteca de Controles'!$I$5:$I$37,0)))
A41: =IF(15<=COUNTIF('Biblioteca de Controles'!$H$5:$H$37,1),15,"") | B41: =IF($A41="","",INDEX('Biblioteca de Controles'!$B$5:$B$37,MATCH($A41,'Biblioteca de Controles'!$I$5:$I$37,0))) | C41: =IF($A41="","",INDEX('Biblioteca de Controles'!$C$5:$C$37,MATCH($A41,'Biblioteca de Controles'!$I$5:$I$37,0))) | D41: =IF($A41="","",INDEX('Biblioteca de Controles'!$D$5:$D$37,MATCH($A41,'Biblioteca de Controles'!$I$5:$I$37,0)))
A42: =IF(16<=COUNTIF('Biblioteca de Controles'!$H$5:$H$37,1),16,"") | B42: =IF($A42="","",INDEX('Biblioteca de Controles'!$B$5:$B$37,MATCH($A42,'Biblioteca de Controles'!$I$5:$I$37,0))) | C42: =IF($A42="","",INDEX('Biblioteca de Controles'!$C$5:$C$37,MATCH($A42,'Biblioteca de Controles'!$I$5:$I$37,0))) | D42: =IF($A42="","",INDEX('Biblioteca de Controles'!$D$5:$D$37,MATCH($A42,'Biblioteca de Controles'!$I$5:$I$37,0)))
A43: =IF(17<=COUNTIF('Biblioteca de Controles'!$H$5:$H$37,1),17,"") | B43: =IF($A43="","",INDEX('Biblioteca de Controles'!$B$5:$B$37,MATCH($A43,'Biblioteca de Controles'!$I$5:$I$37,0))) | C43: =IF($A43="","",INDEX('Biblioteca de Controles'!$C$5:$C$37,MATCH($A43,'Biblioteca de Controles'!$I$5:$I$37,0))) | D43: =IF($A43="","",INDEX('Biblioteca de Controles'!$D$5:$D$37,MATCH($A43,'Biblioteca de Controles'!$I$5:$I$37,0)))
...

Sheet Biblioteca de Controles
A1: Biblioteca de Controles – reglas del Plan de Control (editable)
A2: Cada fila es una recomendación. Se incluye en el plan cuando la severidad ACGIH ≥ 'Sev. mín.' y se cumplen las condiciones 1 y 2 (códigos de la hoja 'Plan de Control', columna F). Puede editar textos, agregar filas al final (copie las fórmulas de H e I) o cambiar los umbrales. Las celdas que empiezan con = son recomendaciones dinámicas.
A4: # | B4: Nivel | C4: Tipo de control | D4: Recomendación | E4: Sev. mín. | F4: Condición 1 | G4: Condición 2 | H4: Aplica | I4: N° en plan
A5: 1 | B5: Prioridad inmediata | C5: Tiempo de exposición (PHS) | D5: ="PHS: el modelo estima que se alcanza el límite fisiológico ("&PHS!$B$28&") a los "&'Motor PHS'!$B$50&" min de exposición continua, antes de completar los "&'Motor PHS'!$B$25&" min evaluados. Limite la exposición continua a un máximo de "&'Motor PHS'!$B$50&" min y programe recuperación en un área fresca antes de reanudar la tarea." | E5: 0 | F5: PHS_LIM | G5: S | H5: =IF(AND('Plan de Control'!$D$11>=E5,IFERROR(INDEX('Plan de Control'!$G$5:$G$19,MATCH(F5,'Plan de Control'!$F$5:$F$19,0)),0)=1,IFERROR(INDEX('Plan de Control'!$G$5:$G$19,MATCH(G5,'Plan de Control'!$F$5:$F$19,0)),0)=1),1,0) | I5: =IF(H5=1,COUNTIF(H$5:H5,1),0)
A6: 2 | B6: Prioridad inmediata | C6: Riesgo extremo | D6: Riesgo EXTREMADAMENTE ALTO: suspender o restringir la tarea hasta implementar controles de ingeniería significativos (rediseño del proceso, aislamiento de la fuente de calor, enfriamiento). Sin mejoras sustanciales la exposición puede ser insostenible; si debe continuar, solo con exposiciones cortas, enfriamiento intercalado y supervisión médica continua. | E6: 5 | F6: S | G6: S | H6: =IF(AND('Plan de Control'!$D$11>=E6,IFERROR(INDEX('Plan de Control'!$G$5:$G$19,MATCH(F6,'Plan de Control'!$F$5:$F$19,0)),0)=1,IFERROR(INDEX('Plan de Control'!$G$5:$G$19,MATCH(G6,'Plan de Control'!$F$5:$F$19,0)),0)=1),1,0) | I6: =IF(H6=1,COUNTIF(H$5:H6,1),0)
A7: 3 | B7: Prioridad inmediata | C7: Eliminación / Sustitución | D7: Evaluar eliminar o sustituir la exposición: automatización o teleoperación, mecanización, prefabricación en áreas frescas, o reprogramar trabajos no urgentes (p. ej., mantenimiento con equipos fríos o durante paradas de planta). | E7: 4 | F7: S | G7: S | H7: =IF(AND('Plan de Control'!$D$11>=E7,IFERROR(INDEX('Plan de Control'!$G$5:$G$19,MATCH(F7,'Plan de Control'!$F$5:$F$19,0)),0)=1,IFERROR(INDEX('Plan de Control'!$G$5:$G$19,MATCH(G7,'Plan de Control'!$F$5:$F$19,0)),0)=1),1,0) | I7: =IF(H7=1,COUNTIF(H$5:H7,1),0)
A8: 4 | B8: Prioridad inmediata | C8: EPP / Ropa | D8: Ropa con barrera de vapor (CAV ≥ 10 °C): limite su uso a lo estrictamente necesario, con tiempos de exposición cortos, enfriamiento personal (chalecos o prendas enfriadas) y monitoreo fisiológico. El modelo PHS no aplica a este tipo de ropa. | E8: 1 | F8: BARRERA | G8: S | H8: =IF(AND('Plan de Control'!$D$11>=E8,IFERROR(INDEX('Plan de Control'!$G$5:$G$19,MATCH(F8,'Plan de Control'!$F$5:$F$19,0)),0)=1,IFERROR(INDEX('Plan de Control'!$G$5:$G$19,MATCH(G8,'Plan de Control'!$F$5:$F$19,0)),0)=1),1,0) | I8: =IF(H8=1,COUNTIF(H$5:H8,1),0)
A9: 5 | B9: Nivel 1 – General | C9: Gestión | D9: Establecer o mantener un Programa de Gestión de Estrés Térmico (PGET) documentado: responsables, mediciones de línea base, controles por nivel, capacitación, vigilancia médica y respuesta a emergencias. | E9: 2 | F9: S | G9: S | H9: =IF(AND('Plan de Control'!$D$11>=E9,IFERROR(INDEX('Plan de Control'!$G$5:$G$19,MATCH(F9,'Plan de Control'!$F$5:$F$19,0)),0)=1,IFERROR(INDEX('Plan de Control'!$G$5:$G$19,MATCH(G9,'Plan de Control'!$F$5:$F$19,0)),0)=1),1,0) | I9: =IF(H9=1,COUNTIF(H$5:H9,1),0)
A10: 6 | B10: Nivel 1 – General | C10: Medición | D10: Medir el WBGT en el puesto de trabajo con instrumento calibrado (verificación anual) en los períodos pico de calor y ante cambios de proceso o de estación; registrar hora, lugar y condiciones climáticas. | E10: 2 | F10: S | G10: S | H10: =IF(AND('Plan de Control'!$D$11>=E10,IFERROR(INDEX('Plan de Control'!$G$5:$G$19,MATCH(F10,'Plan de Control'!$F$5:$F$19,0)),0)=1,IFERROR(INDEX('Plan de Control'!$G$5:$G$19,MATCH(G10,'Plan de Control'!$F$5:$F$19,0)),0)=1),1,0) | I10: =IF(H10=1,COUNTIF(H$5:H10,1),0)
A11: 7 | B11: Nivel 1 – General | C11: Hidratación | D11: Disponer de agua potable fresca, accesible y sin límite en el puesto de trabajo; promover el consumo periódico (≈ 1 vaso de 200–250 mL cada 15–20 min) sin superar ≈ 1.4 L/h. | E11: 1 | F11: S | G11: S | H11: =IF(AND('Plan de Control'!$D$11>=E11,IFERROR(INDEX('Plan de Control'!$G$5:$G$19,MATCH(F11,'Plan de Control'!$F$5:$F$19,0)),0)=1,IFERROR(INDEX('Plan de Control'!$G$5:$G$19,MATCH(G11,'Plan de Control'!$F$5:$F$19,0)),0)=1),1,0) | I11: =IF(H11=1,COUNTIF(H$5:H11,1),0)
A12: 8 | B12: Nivel 1 – General | C12: Administrativo | D12: Establecer pausas frecuentes en un área fresca, sombreada o climatizada cercana al puesto de trabajo (idealmente < 28 °C). | E12: 2 | F12: S | G12: S | H12: =IF(AND('Plan de Control'!$D$11>=E12,IFERROR(INDEX('Plan de Control'!$G$5:$G$19,MATCH(F12,'Plan de Control'!$F$5:$F$19,0)),0)=1,IFERROR(INDEX('Plan de Control'!$G$5:$G$19,MATCH(G12,'Plan de Control'!$F$5:$F$19,0)),0)=1),1,0) | I12: =IF(H12=1,COUNTIF(H$5:H12,1),0)
A13: 9 | B13: Nivel 1 – General | C13: Aclimatación | D13: Aplicar protocolo de aclimatación a trabajadores nuevos o que retornan tras una ausencia prolongada: 20 % de la carga de trabajo el día 1 y aumento de 20 % por día hasta llegar al 100 % (5 días). | E13: 1 | F13: NOACL | G13: S | H13: =IF(AND('Plan de Control'!$D$11>=E13,IFERROR(INDEX('Plan de Control'!$G$5:$G$19,MATCH(F13,'Plan de Control'!$F$5:$F$19,0)),0)=1,IFERROR(INDEX('Plan de Control'!$G$5:$G$19,MATCH(G13,'Plan de Control'!$F$5:$F$19,0)),0)=1),1,0) | I13: =IF(H13=1,COUNTIF(H$5:H13,1),0)
A14: 10 | B14: Nivel 1 – General | C14: Capacitación | D14: Capacitar a trabajadores y supervisores en reconocimiento de la enfermedad por calor (calambres, agotamiento, golpe de calor), primeros auxilios y sistema de compañeros; actualizar la capacitación cada año. | E14: 1 | F14: S | G14: S | H14: =IF(AND('Plan de Control'!$D$11>=E14,IFERROR(INDEX('Plan de Control'!$G$5:$G$19,MATCH(F14,'Plan de Control'!$F$5:$F$19,0)),0)=1,IFERROR(INDEX('Plan de Control'!$G$5:$G$19,MATCH(G14,'Plan de Control'!$F$5:$F$19,0)),0)=1),1,0) | I14: =IF(H14=1,COUNTIF(H$5:H14,1),0)
A15: 11 | B15: Nivel 1 – General | C15: Vigilancia de síntomas | D15: Vigilar durante la jornada los síntomas tempranos (fatiga, mareo, náuseas, cefalea) mediante supervisores y sistema de compañeros. | E15: 2 | F15: S | G15: S | H15: =IF(AND('Plan de Control'!$D$11>=E15,IFERROR(INDEX('Plan de Control'!$G$5:$G$19,MATCH(F15,'Plan de Control'!$F$5:$F$19,0)),0)=1,IFERROR(INDEX('Plan de Control'!$G$5:$G$19,MATCH(G15,'Plan de Control'!$F$5:$F$19,0)),0)=1),1,0) | I15: =IF(H15=1,COUNTIF(H$5:H15,1),0)
A16: 12 | B16: Nivel 1 – General | C16: Vigilancia médica | D16: Evaluación médica de ingreso y periódica con énfasis en factores de riesgo (edad, condiciones cardiovasculares o metabólicas, medicamentos, enfermedad reciente, hidratación) dentro de un programa de vigilancia médica. | E16: 2 | F16: S | G16: S | H16: =IF(AND('Plan de Control'!$D$11>=E16,IFERROR(INDEX('Plan de Control'!$G$5:$G$19,MATCH(F16,'Plan de Control'!$F$5:$F$19,0)),0)=1,IFERROR(INDEX('Plan de Control'!$G$5:$G$19,MATCH(G16,'Plan de Control'!$F$5:$F$19,0)),0)=1),1,0) | I16: =IF(H16=1,COUNTIF(H$5:H16,1),0)
A17: 13 | B17: Nivel 1 – General | C17: Emergencia | D17: Contar con procedimiento de emergencia para golpe de calor: enfriamiento inmediato (inmersión en agua fría o compresas de hielo), llamado a servicios de emergencia, comunicación en campo y agua con electrolitos preposicionada. | E17: 2 | F17: S | G17: S | H17: =IF(AND('Plan de Control'!$D$11>=E17,IFERROR(INDEX('Plan de Control'!$G$5:$G$19,MATCH(F17,'Plan de Control'!$F$5:$F$19,0)),0)=1,IFERROR(INDEX('Plan de Control'!$G$5:$G$19,MATCH(G17,'Plan de Control'!$F$5:$F$19,0)),0)=1),1,0) | I17: =IF(H17=1,COUNTIF(H$5:H17,1),0)
A18: 14 | B18: Nivel 1 – General | C18: Hidratación (PHS) | D18: ="Pérdida de agua estimada por PHS: "&ROUND('Motor PHS'!$B$55,1)&" L en "&'Motor PHS'!$B$25&" min (≈ "&ROUND('Motor PHS'!$B$56,1)&" L/h). Use este valor para planificar la disponibilidad de agua por turno." | E18: 0 | F18: PHS_OK | G18: S | H18: =IF(AND('Plan de Control'!$D$11>=E18,IFERROR(INDEX('Plan de Control'!$G$5:$G$19,MATCH(F18,'Plan de Control'!$F$5:$F$19,0)),0)=1,IFERROR(INDEX('Plan de Control'!$G$5:$G$19,MATCH(G18,'Plan de Control'!$F$5:$F$19,0)),0)=1),1,0) | I18: =IF(H18=1,COUNTIF(H$5:H18,1),0)
A19: 15 | B19: Nivel 1 – General | C19: Hidratación (PHS) | D19: ="La pérdida de agua estimada ("&ROUND('Motor PHS'!$B$56,1)&" L/h) supera la ingesta oral recomendada (≈ 1.4 L/h): la reposición completa no es viable. Reduzca la carga térmica o alterne exposición y recuperación en área fresca." | E19: 0 | F19: PHS_SW_HIGH | G19: S | H19: =IF(AND('Plan de Control'!$D$11>=E19,IFERROR(INDEX('Plan de Control'!$G$5:$G$19,MATCH(F19,'Plan de Control'!$F$5:$F$19,0)),0)=1,IFERROR(INDEX('Plan de Control'!$G$5:$G$19,MATCH(G19,'Plan de Control'!$F$5:$F$19,0)),0)=1),1,0) | I19: =IF(H19=1,COUNTIF(H$5:H19,1),0)
A20: 16 | B20: Nivel 2 – Específico | C20: Ingeniería | D20: Proveer sombra (toldos, carpas, cubiertas) en el frente de trabajo y en las áreas de descanso para labores a la intemperie. | E20: 3 | F20: EXT | G20: S | H20: =IF(AND('Plan de Control'!$D$11>=E20,IFERROR(INDEX('Plan de Control'!$G$5:$G$19,MATCH(F20,'Plan de Control'!$F$5:$F$19,0)),0)=1,IFERROR(INDEX('Plan de Control'!$G$5:$G$19,MATCH(G20,'Plan de Control'!$F$5:$F$19,0)),0)=1),1,0) | I20: =IF(H20=1,COUNTIF(H$5:H20,1),0)
A21: 17 | B21: Nivel 2 – Específico | C21: Ingeniería | D21: Instalar apantallamiento o barreras reflectivas y aislamiento en fuentes de calor radiante (hornos, calderas, superficies calientes); aumentar la distancia entre el trabajador y la fuente. | E21: 3 | F21: RAD | G21: S | H21: =IF(AND('Plan de Control'!$D$11>=E21,IFERROR(INDEX('Plan de Control'!$G$5:$G$19,MATCH(F21,'Plan de Control'!$F$5:$F$19,0)),0)=1,IFERROR(INDEX('Plan de Control'!$G$5:$G$19,MATCH(G21,'Plan de Control'!$F$5:$F$19,0)),0)=1),1,0) | I21: =IF(H21=1,COUNTIF(H$5:H21,1),0)
A22: 18 | B22: Nivel 2 – Específico | C22: Ingeniería | D22: Mejorar la ventilación general y usar extracción localizada en la fuente de calor o humedad. | E22: 3 | F22: INTERIOR | G22: S | H22: =IF(AND('Plan de Control'!$D$11>=E22,IFERROR(INDEX('Plan de Control'!$G$5:$G$19,MATCH(F22,'Plan de Control'!$F$5:$F$19,0)),0)=1,IFERROR(INDEX('Plan de Control'!$G$5:$G$19,MATCH(G22,'Plan de Control'!$F$5:$F$19,0)),0)=1),1,0) | I22: =IF(H22=1,COUNTIF(H$5:H22,1),0)
A23: 19 | B23: Nivel 2 – Específico | C23: Ingeniería | D23: Proporcionar enfriamiento del aire (aire acondicionado o enfriamiento evaporativo cuando la humedad lo permita) o enfriamiento localizado y ventiladores. Con aire cercano o por encima de la temperatura de la piel (≈ 35 °C) los ventiladores pueden no proteger: priorice enfriar el aire. | E23: 3 | F23: INTERIOR | G23: S | H23: =IF(AND('Plan de Control'!$D$11>=E23,IFERROR(INDEX('Plan de Control'!$G$5:$G$19,MATCH(F23,'Plan de Control'!$F$5:$F$19,0)),0)=1,IFERROR(INDEX('Plan de Control'!$G$5:$G$19,MATCH(G23,'Plan de Control'!$F$5:$F$19,0)),0)=1),1,0) | I23: =IF(H23=1,COUNTIF(H$5:H23,1),0)
A24: 20 | B24: Nivel 2 – Específico | C24: Ingeniería | D24: Controlar fuentes de vapor y humedad (fugas de vapor, procesos húmedos) y deshumidificar cuando sea viable: con alta humedad la evaporación del sudor es limitada y el enfriamiento del cuerpo es menos eficaz. | E24: 3 | F24: HUM | G24: S | H24: =IF(AND('Plan de Control'!$D$11>=E24,IFERROR(INDEX('Plan de Control'!$G$5:$G$19,MATCH(F24,'Plan de Control'!$F$5:$F$19,0)),0)=1,IFERROR(INDEX('Plan de Control'!$G$5:$G$19,MATCH(G24,'Plan de Control'!$F$5:$F$19,0)),0)=1),1,0) | I24: =IF(H24=1,COUNTIF(H$5:H24,1),0)
A25: 21 | B25: Nivel 2 – Específico | C25: Ingeniería | D25: Reducir la carga metabólica mediante diseño del trabajo: mecanización, ayudas para levantar y transportar, herramientas apropiadas y reducción de las demandas físicas donde sea factible. | E25: 3 | F25: S | G25: S | H25: =IF(AND('Plan de Control'!$D$11>=E25,IFERROR(INDEX('Plan de Control'!$G$5:$G$19,MATCH(F25,'Plan de Control'!$F$5:$F$19,0)),0)=1,IFERROR(INDEX('Plan de Control'!$G$5:$G$19,MATCH(G25,'Plan de Control'!$F$5:$F$19,0)),0)=1),1,0) | I25: =IF(H25=1,COUNTIF(H$5:H25,1),0)
A26: 22 | B26: Nivel 2 – Específico | C26: Administrativo | D26: Programar las tareas más pesadas en las horas de menor carga térmica (iniciar más temprano o más tarde) y alternarlas con tareas más frías. | E26: 3 | F26: EXT | G26: S | H26: =IF(AND('Plan de Control'!$D$11>=E26,IFERROR(INDEX('Plan de Control'!$G$5:$G$19,MATCH(F26,'Plan de Control'!$F$5:$F$19,0)),0)=1,IFERROR(INDEX('Plan de Control'!$G$5:$G$19,MATCH(G26,'Plan de Control'!$F$5:$F$19,0)),0)=1),1,0) | I26: =IF(H26=1,COUNTIF(H$5:H26,1),0)
A27: 23 | B27: Nivel 2 – Específico | C27: Administrativo | D27: Acortar la duración de los ciclos trabajo-descanso y rotar a los trabajadores entre ambientes calurosos y frescos. | E27: 3 | F27: S | G27: S | H27: =IF(AND('Plan de Control'!$D$11>=E27,IFERROR(INDEX('Plan de Control'!$G$5:$G$19,MATCH(F27,'Plan de Control'!$F$5:$F$19,0)),0)=1,IFERROR(INDEX('Plan de Control'!$G$5:$G$19,MATCH(G27,'Plan de Control'!$F$5:$F$19,0)),0)=1),1,0) | I27: =IF(H27=1,COUNTIF(H$5:H27,1),0)
A28: 24 | B28: Nivel 2 – Específico | C28: Administrativo | D28: Reforzar la supervisión y el monitoreo: verificar el cumplimiento de pausas, la disponibilidad de agua y la aparición de síntomas. | E28: 3 | F28: S | G28: S | H28: =IF(AND('Plan de Control'!$D$11>=E28,IFERROR(INDEX('Plan de Control'!$G$5:$G$19,MATCH(F28,'Plan de Control'!$F$5:$F$19,0)),0)=1,IFERROR(INDEX('Plan de Control'!$G$5:$G$19,MATCH(G28,'Plan de Control'!$F$5:$F$19,0)),0)=1),1,0) | I28: =IF(H28=1,COUNTIF(H$5:H28,1),0)
A29: 25 | B29: Nivel 2 – Específico | C29: Administrativo | D29: Alta demanda metabólica (≥ 300 W): distribuir el esfuerzo entre más personas, permitir ritmos de trabajo autorregulados y evitar picos de esfuerzo continuo. | E29: 2 | F29: MET | G29: S | H29: =IF(AND('Plan de Control'!$D$11>=E29,IFERROR(INDEX('Plan de Control'!$G$5:$G$19,MATCH(F29,'Plan de Control'!$F$5:$F$19,0)),0)=1,IFERROR(INDEX('Plan de Control'!$G$5:$G$19,MATCH(G29,'Plan de Control'!$F$5:$F$19,0)),0)=1),1,0) | I29: =IF(H29=1,COUNTIF(H$5:H29,1),0)
A30: 26 | B30: Nivel 2 – Específico | C30: Vigilancia médica | D30: Aumentar la frecuencia de la vigilancia médica y priorizar la revisión de los trabajadores más expuestos o susceptibles. | E30: 3 | F30: S | G30: S | H30: =IF(AND('Plan de Control'!$D$11>=E30,IFERROR(INDEX('Plan de Control'!$G$5:$G$19,MATCH(F30,'Plan de Control'!$F$5:$F$19,0)),0)=1,IFERROR(INDEX('Plan de Control'!$G$5:$G$19,MATCH(G30,'Plan de Control'!$F$5:$F$19,0)),0)=1),1,0) | I30: =IF(H30=1,COUNTIF(H$5:H30,1),0)
A31: 27 | B31: Nivel 2 – Específico | C31: EPP / Ropa | D31: Usar ropa reflectante o de color claro y protección facial/ocular para reducir la carga de calor radiante. | E31: 3 | F31: RADIANTE | G31: S | H31: =IF(AND('Plan de Control'!$D$11>=E31,IFERROR(INDEX('Plan de Control'!$G$5:$G$19,MATCH(F31,'Plan de Control'!$F$5:$F$19,0)),0)=1,IFERROR(INDEX('Plan de Control'!$G$5:$G$19,MATCH(G31,'Plan de Control'!$F$5:$F$19,0)),0)=1),1,0) | I31: =IF(H31=1,COUNTIF(H$5:H31,1),0)
... A37: 33 | B37: Nivel 3 – Monitoreo | C37: Criterios de suspensión | D37: DETENER el trabajo y llevar al trabajador a un área fresca ante cualquier criterio anterior; el supervisor no debe permitir que continúe aunque el trabajador lo solicite. Proporcionar evaluación médica, documentar el incidente y revisar los controles. | E37: 4 | F37: S | G37: S | H37: =IF(AND('Plan de Control'!$D$11>=E37,IFERROR(INDEX('Plan de Control'!$G$5:$G$19,MATCH(F37,'Plan de Control'!$F$5:$F$19,0)),0)=1,IFERROR(INDEX('Plan de Control'!$G$5:$G$19,MATCH(G37,'Plan de Control'!$F$5:$F$19,0)),0)=1),1,0) | I37: =IF(H37=1,COUNTIF(H$5:H37,1),0)

Sheet Motor PHS
A1: Motor PHS – ISO 7933:2023 (cálculo minuto a minuto)
A2: Hoja de cálculo interna: no edite. Los datos se ingresan en 'Análisis Detallado' y 'PHS'. Ecuaciones según la implementación de referencia de ISO 7933:2023 (pythermalcomfort 4.6.0). Máx. 720 min.
A3: PARÁMETROS GLOBALES | B3: Valor | C3: Nota
A4: Peso (kg) | B4: =IF(N(PHS!B5)>0,PHS!B5,75) | C4: Si está vacío se usa 75 kg
A5: Estatura (m) | B5: =IF(N(PHS!B6)>0,PHS!B6,1.8) | C5: Si está vacío se usa 1.80 m
A6: Superficie corporal DuBois (m²) | B6: =0.202*B4^0.425*B5^0.725
A7: Calor específico corporal (W·min/m²/°C) | B7: =58.15*B4/B6 | C7: 58.15 W/m² por met
A8: Postura | B8: =PHS!B7
A9: Área radiante (fracción DuBois) | B9: =IF(B8="Sentado",0.7,IF(B8="En cuclillas",0.67,0.77)) | C9: De pie 0.77; sentado 0.70; en cuclillas 0.67
A10: Aclimatado (1/0) | B10: =IF(PHS!B8="Aclimatado",1,0)
A11: Sudoración máxima (W/m²) | B11: =IF(B10=1,500,400) | C11: ISO 7933:2023
A12: Humedad de piel máxima | B12: =IF(B10=1,1,0.85)
A13: Aislamiento de ropa clo | B13: =IF(AND(ISNUMBER(PHS!B9),N(PHS!B9)>0),PHS!B9,0.6)
A14: Factor de área de ropa fcl | B14: =1+0.28*B13 | C14: ISO 7933:2023
A15: Aislamiento estático total (m²K/W) | B15: =B13*0.155+0.111/B14
A16: Índice de permeabilidad estática i_mst | B16: 0.38 | C16: Valor por defecto
A17: Fracción de área con ropa reflectiva a_p | B17: 0.54 | C17: Valor por defecto
A18: Coeficiente de reflexión f_r | B18: 0.42 | C18: Valor por defecto (2023)
A19: f_cl_r | B19: =(1-B17)*0.97+B17*(1-B18)
A20: Constante radiativa | B20: =5.67E-8*B9
A21: Pérdida de agua máx. tolerable (g) | B21: =0.05*B4*1000 | C21: 5 % del peso, hidratación libre
A22: Velocidad de caminata ingresada (m/s) | B22: =N(PHS!B10) | C22: 0 = estimada
A23: Diámetro del globo (m) | B23: =IF(N(PHS!B11)>0,PHS!B11/1000,0.15)
A24: Emisividad del globo | B24: =IF(N(PHS!B12)>0,PHS!B12,0.95)
A25: Duración total (min) | B25: =SUM(C61:C68) | C25: Suma de tareas
A26: Constante exp(-1/10) (Tcr eq.) | B26: =EXP(-1/10)
A27: Constante exp(-1/3) (Tsk) | B27: =EXP(-1/3)
A28: Constante exp(-1/10) (sudor) | B28: =EXP(-1/10)
A29: Tsk inicial (°C) | B29: 34.1
A30: Tcr inicial (°C) | B30: 36.8
A31: Tre inicial (°C) | B31: 36.8
A32: Tcr_eq inicial (°C) | B32: 36.8
A33: Peso Tsk/Tcr inicial | B33: 0.3
A34: Sudoración inicial (W/m²) | B34: 0
A35: Carga evaporativa inicial | B35: 0
A36: Límite de Tre (°C) | B36: 38 | C36: ISO 7933
A38: Tareas usadas | B38: =SUM($E$61:$E$68)
A39: Tareas con datos incompletos | B39: =SUMPRODUCT(($E$61:$E$68=1)*($F$61:$F$68=0))
A40: Datos completos y válidos para simular (1/0) | B40: =IF(AND(B25>0,B39=0,B25<=720,N(PHS!B5)>0,N(PHS!B6)>0),1,0)
A41: Tareas fuera de rango ISO 7933 | B41: =SUMPRODUCT(($E$61:$E$68=1)*($F$61:$F$68=1)*(1-$AP$61:$AP$68))
...

Sheet Instrucciones
A1: CÓMO USAR HEATSTRESSRISK
A2: 1. MÉTODO DE EVALUACIÓN | C2: Hoja: Evaluación
A3: - Ingrese WBGT temperatura medida o estimada
A4: - Seleccione o ingrese tasa metabólica
A5: - Seleccione estado de aclimatación
A6: - Ingrese valor de ajuste de ropa (CAV)
A7: - Los resultados se calculan automáticamente
A9: 2. CÁLCULOS AUTOMÁTICOS
A10: - TLV y AL se calculan según ecuaciones ACGIH
A11: - Severidad se clasifica automáticamente
A12: - Recomendaciones de nivel se basan en severidad
A14: 3. DATOS DE REFERENCIA | C14: Hoja: Datos de Referencia
A15: - Tasas metabólicas comunes
A16: - Valores de ajuste de ropa
A17: - Niveles de severidad
A19: 4. MÉTODO DETALLADO | C19: Hoja: Análisis Detallado
A20: - Para exposiciones heterogéneas con múltiples tareas
A21: - Ingrese cada tarea con duración y WBGT
A22: - Los promedios ponderados se calculan automáticamente
A24: 5. ANÁLISIS DETALLADO – CLASIFICACIÓN ACGIH (NUEVO V2) | C24: Hoja: Análisis Detallado
A25: - Ingrese aclimatación y CAV de ropa (B18:B19) debajo de los promedios ponderados
A26: - TLV/AL se calculan con el PPA de la tasa metabólica y se clasifica la severidad
A28: 6. PHS – TENSIÓN TÉRMICA PREDICHA, ISO 7933:2023 (NUEVO V2) | C28: Hoja: PHS
A29: - En 'Análisis Detallado' ingrese además Tbs, Tg, HR y velocidad del aire (columnas G–J) de cada tarea
A30: - En 'PHS' indique peso, estatura, postura y ropa (clo); Tr y Pa se calculan automáticamente
A31: - Resultados: Tre, pérdida de agua y tiempo máximo de exposición (Dlim); revise la validez y las notas
A33: 7. PLAN DE CONTROL AUTOMÁTICO (NUEVO V2) | C33: Hoja: Plan de Control
A34: - Elija la fuente de evaluación, el tipo de exposición y si hay trabajadores susceptibles
A35: - Se genera la lista de controles según severidad, ambiente, ropa, aclimatación y resultado PHS
A37: 8. BIBLIOTECA DE CONTROLES (EDITABLE) | C37: Hoja: Biblioteca de Controles
A38: - Cada fila es una regla: nivel, tipo, texto, severidad mínima y condiciones
A39: - La hoja 'Motor PHS' es de cálculo interno: no la modifique
