Workbook

Sheet Portada

Sheet Inicio
B2: NeumoRisk V1
B3: Evaluación y control del riesgo por agentes neumoconióticos: sílice cristalina, carbón y asbesto
B4: Herramienta gratuita · Sociedad Colombiana de Higienistas Ocupacionales (SCHO) · Autores: Álvaro de Jesús Araque García y Luis Guillermo Araque Muñoz · Versión 1.0 – octubre de 2026 · ARCHIVO DE EJEMPLO
B6: Propósito | C6: Aplicar en forma práctica las recomendaciones de higiene de la GATI-NEUMO (MPS, 2006) y de la Guía Técnica de Higiene y Seguridad para Sílice Cristalina Respirable (MinTrabajo, 2024 – Res. 2467 de 2022): identificación, evaluación cualitativa, muestreo por GES, estadística, decisión, periodicidad, controles, protección respiratoria y vigilancia médica.
B7: Flujo de trabajo | C7: 1) Agentes y VLP → 2) GES (identificación y valoración cualitativa) → 3) Muestreo → 4) Estadística GES (decisión) → 5) Plan de Control (con Biblioteca) → 6) Protección Respiratoria → 7) Exposición Acumulada → 8) Vigilancia Médica.
B8: Criterio de decisión | C8: Sílice cristalina: Res. 2467/2022 y Guía Técnica 2024 – Perfil de exposición PE = MG / TLV ajustado (≤0,5 bajo; 0,5–1 moderado; >1 alto); validez GES con DEG ≤ 2,5. Carbón y asbesto: GATI-NEUMO 2006 – Concentración relativa CR = MA / TLV ajustado (<0,5 controlada; ≥0,5 fuera de control); GES aceptable con DEG ≤ 2,0.
B9: Ajuste de jornada | C9: Brief & Scala: factor diario 8/hd·(24−hd)/16 y semanal 40/hs·(168−hs)/128; se aplica el más restrictivo (Guía Técnica 2024). Nunca se incrementa el TLV para jornadas cortas.
B10: Leyenda de celdas | C10: Amarillo con texto azul: datos que usted diligencia. Gris: cálculo automático (no editar). Las listas desplegables evitan errores de digitación.
B11: Valores límite | C11: TLV ACGIH editables en la hoja Agentes. Verifíquelos cada año contra la publicación vigente de ACGIH (GATI-NEUMO 7.1.4: aplicar el criterio que más favorezca la salud del trabajador).
B12: Advertencia | C12: La herramienta apoya, pero no reemplaza, el criterio del higienista ocupacional con licencia en SST. Las mediciones deben hacerse con métodos validados y laboratorios acreditados.
B13: Referencias | C13: GATI-NEUMO (Ministerio de la Protección Social, 2006; adoptada por Res. 2844/2007) · Res. 2467 de 2022 · Guía Técnica de Higiene y Seguridad para la Prevención y el Control del Riesgo por Exposición a Sílice Cristalina Respirable (MinTrabajo, 2024) · ACGIH TLVs and BEIs · OSHA 29 CFR 1910.134 · NIOSH Manual of Analytical Methods.
B15: Datos de la evaluación
B16: Empresa | C16: Agregados y Minerales del Ejemplo S.A.S.
B17: NIT | C17: 900.000.000-0
B18: Centro de trabajo / ciudad | C18: Planta y mina – Boyacá
B19: Actividad económica | C19: Extracción de carbón, trituración de agregados y fabricación de ladrillo
B20: Higienista responsable (licencia SST) | C20: Higienista Ocupacional (Lic. SST 0000)
B21: Fecha del estudio | C21: 2026-09-15
B22: Laboratorio (acreditación) | C22: Laboratorio acreditado ISO/IEC 17025

Sheet Agentes
A1: 1. Agentes neumoconióticos y valores límite permisibles
A2: TLV-TWA ACGIH (8 h/día – 40 h/semana). Columna F editable: actualícela con la publicación ACGIH vigente.
A3: NeumoRisk V1 · Sílice cristalina, carbón y asbesto · SCHO · Celdas amarillas con texto azul = datos a diligenciar; celdas grises = cálculo automático (no editar).
A5: Código | B5: Agente | C5: CAS | D5: Fracción | E5: Unidad | F5: TLV-TWA ACGIH | G5: Criterio de decisión | H5: Método de muestreo y análisis | I5: Enfermedad asociada | J5: Carcinogenicidad | K5: Nota
A6: SIL-Q | B6: Sílice cristalina – α-cuarzo | C6: 14808-60-7 | D6: Respirable | E6: mg/m³ | F6: 0.025 | G6: Res. 2467/2022 | H6: NIOSH 7500 (DRX, preferido); NIOSH 7602 (IR); NIOSH 7601 (VIS). Ciclón nylon 10 mm, 1,7 L/min, filtro PVC 37 mm 5 µm | I6: Silicosis (CIE-10 J62); cáncer de pulmón; EPOC; TB asociada | J6: ACGIH A2 · IARC 1 | K6: Aplica si sílice libre cristalina ≥ 1 % en peso (GATI 7.1.5)
A7: SIL-C | B7: Sílice cristalina – cristobalita | C7: 14464-46-1 | D7: Respirable | E7: mg/m³ | F7: 0.025 | G7: Res. 2467/2022 | H7: NIOSH 7500 (DRX) | I7: Silicosis (J62) | J7: ACGIH A2 · IARC 1 | K7: Se forma al calentar cuarzo o sílice amorfa (>1470 °C): fundición, refractarios, tierras diatomáceas calcinadas
A8: SIL-T | B8: Sílice cristalina – tridimita | C8: 15468-32-3 | D8: Respirable | E8: mg/m³ | F8: 0.025 | G8: Res. 2467/2022 | H8: NIOSH 7500 (DRX) | I8: Silicosis (J62) | J8: IARC 1 | K8: Guía Técnica 2024 agrupa cuarzo, cristobalita y tridimita con TLV 0,025 mg/m³
A9: CAR-A | B9: Polvo de carbón – antracita | C9: — | D9: Respirable | E9: mg/m³ | F9: 0.4 | G9: GATI-NEUMO 2006 | H9: NIOSH 0600 (gravimétrico, fracción respirable) + NIOSH 7500 para cuarzo en la muestra | I9: Neumoconiosis del minero de carbón (J60); FMP | J9: ACGIH A4 · IARC 3 | K9: Descartar sílice cristalina en la muestra: si ≥ 1 % evaluar también el cuarzo (columna de cuarzo)
A10: CAR-B | B10: Polvo de carbón – bituminoso o lignito | C10: — | D10: Respirable | E10: mg/m³ | F10: 0.9 | G10: GATI-NEUMO 2006 | H10: NIOSH 0600 + NIOSH 7500 para cuarzo | I10: Neumoconiosis del minero de carbón (J60); FMP | J10: ACGIH A4 · IARC 3 | K10: Idem antracita
A11: ASB | B11: Asbesto – todas las formas | C11: 1332-21-4 | D11: Fibras respirables (PCM) | E11: f/cm³ | F11: 0.1 | G11: GATI-NEUMO 2006 | H11: OSHA ID-160 (PCM) / NIOSH 7400; confirmación por TEM NIOSH 7402 cuando haya otras fibras | I11: Asbestosis (J61); mesotelioma; cáncer de pulmón | J11: ACGIH A1 · IARC 1 | K11: Fibra: L > 5 µm, D < 3 µm, L/D ≥ 3. Colombia: Ley 1968 de 2019 prohíbe el asbesto desde 2021 (aplica a remoción, demolición y mantenimiento)
A12: PNOS | B12: Polvo respirable sin asbesto y sílice < 1 % | C12: — | D12: Respirable | E12: mg/m³ | F12: 3 | G12: GATI-NEUMO 2006 | H12: NIOSH 0600 (gravimétrico) | I12: No neumoconiótico (partículas PNOS) | J12: — | K12: Partículas insolubles no especificadas (ACGIH: 3 mg/m³ R). Se tratarán en la futura herramienta DustRisk
A14: Parámetros
A15: Denominador DEG | C15: n | D15: «n» según Res. 2467/2022 y ejemplo 2 de la Guía Técnica 2024 (DEG = 1,15). Use «n-1» para la desviación muestral clásica.
A16: Volumen minuto respiratorio (L/min) | C16: 21 | D16: Trabajo moderado: 21 L/min (GATI-NEUMO 7.2.5). Usado para la vida útil de filtros.
A17: Carga de saturación del filtro (mg) | C17: 200 | D17: 200 mg: carga máxima del ensayo NIOSH 42 CFR 84 (GATI-NEUMO 7.2.5).
A19: Selección del valor límite (GATI-NEUMO 7.1.5)
A20: 1. ¿El aerosol es de origen mineral (con potencial de sílice cristalina o asbesto) u orgánico?
A21: 2. Mineral con sílice libre cristalina ≥ 1 % en peso → TLV de sílice cristalina (SIL-Q / SIL-C / SIL-T). Si contiene asbesto → TLV de asbesto (ASB).
A22: 3. Orgánico, o mineral con sílice < 1 % y sin asbesto → TLV de polvo respirable (PNOS, 3 mg/m³).
A23: 4. Polvo de carbón: aplicar TLV de carbón (CAR-A / CAR-B) y verificar por separado el cuarzo de la muestra con NIOSH 7500.
A26: Factores de protección asignados – APF (OSHA 29 CFR 1910.134)
A27: Nº | B27: Tipo de respirador | C27: APF
A28: 1 | B28: Pieza facial filtrante (desechable) N/R/P | C28: 10
A29: 2 | B29: Media cara elastomérica con filtros P100 | C29: 10
A30: 3 | B30: PAPR con capucha o careta holgada | C30: 25
A31: 4 | B31: Cara completa elastomérica con filtros P100 | C31: 50
A32: 5 | B32: PAPR con media cara | C32: 50
A33: 6 | B33: PAPR con cara completa / casco certificado | C33: 1000
A34: 7 | B34: Línea de aire flujo continuo, cara completa | C34: 1000
A35: 8 | B35: Equipo autocontenido (SCBA) a presión positiva | C35: 10000

Sheet GES
A1: 2. Grupos de Exposición Similar – identificación, valoración cualitativa y ajuste del TLV
A2: GATI-NEUMO Diagrama 2 y rec. 7.2.1 · Guía Técnica 2024 num. 3.1–3.2.1 (matriz AIHA: VC × VE) · Brief & Scala (rec. 7.1.6)
A3: NeumoRisk V1 · Sílice cristalina, carbón y asbesto · SCHO · Celdas amarillas con texto azul = datos a diligenciar; celdas grises = cálculo automático (no editar).
A5: Código GES | B5: Cargos / oficios del GES | C5: Área / proceso | D5: Fuentes y actividades generadoras | E5: Agente (código) | F5: Nº trabajadores | G5: Controles existentes | H5: Horas / día | I5: Horas / semana | J5: Minutos de exposición por jornada | K5: VC (circunstancia) | L5: VE (efecto) | M5: Riesgo potencial VE×VC | N5: Interpretación | O5: Muestras mínimas | P5: Categoría cualitativa (juicio del higienista) | Q5: TLV base | R5: Factor diario | S5: Factor semanal | T5: Factor aplicado | U5: TLV ajustado (B&S) | V5: Unidad
A6: G01 | B6: Operadores de trituradora y cribas | C6: Planta de agregados | D6: Trituración primaria y secundaria de roca arenisca; transferencia en bandas | E6: SIL-Q | F6: 12 | G6: Encerramiento parcial; aspersión en tolva (intermitente) | H6: 8 | I6: 48 | J6: 420 | K6: =IF(J6="","",IF(J6>=360,4,IF(J6>=120,3,IF(J6>=30,2,IF(J6>0,1,0))))) -> 4 | L6: =IF(E6="","",IF(E6="PNOS",2,4)) -> 4 | M6: =IF(OR(K6="",L6=""),"",K6*L6) -> 16 | N6: =IF(M6="","",IF(M6=0,"Incipiente",IF(M6<=4,"Bajo",IF(M6<=8,"Moderado",IF(M6<=12,"Alto","Muy alto"))))) -> Muy alto | O6: =IF(A6="","",IF(N(F6)>50,ROUNDUP(SQRT(F6),0),6)) -> 6 | P6: Alto | Q6: =IF(E6="","",IFERROR(INDEX(Agentes!$F$6:$F$12,MATCH(E6,Agentes!$A$6:$A$12,0)),"Agente?")) -> 0.025 | R6: =IF(N(H6)=0,"",8/H6*(24-H6)/16) -> 1 | S6: =IF(N(I6)=0,"",40/I6*(168-I6)/128) -> 0.78125 | T6: =IF(E6="","",MIN(1,IF(R6="",1,R6),IF(S6="",1,S6))) -> 0.78125 | U6: =IF(OR(Q6="",T6=""),"",Q6*T6) -> 0.01953125 | V6: =IF(E6="","",IFERROR(INDEX(Agentes!$E$6:$E$12,MATCH(E6,Agentes!$A$6:$A$12,0)),"")) -> mg/m³
A7: G02 | B7: Operarios de moldeo y prensado | C7: Ladrillera | D7: Mezcla de arcillas, moldeo y desmolde | E7: SIL-Q | F7: 8 | G7: Ventilación general natural; humectación de la arcilla | H7: 8 | I7: 48 | J7: 300 | K7: =IF(J7="","",IF(J7>=360,4,IF(J7>=120,3,IF(J7>=30,2,IF(J7>0,1,0))))) -> 3 | L7: =IF(E7="","",IF(E7="PNOS",2,4)) -> 4 | M7: =IF(OR(K7="",L7=""),"",K7*L7) -> 12 | N7: =IF(M7="","",IF(M7=0,"Incipiente",IF(M7<=4,"Bajo",IF(M7<=8,"Moderado",IF(M7<=12,"Alto","Muy alto"))))) -> Alto | O7: =IF(A7="","",IF(N(F7)>50,ROUNDUP(SQRT(F7),0),6)) -> 6 | P7: Moderado | Q7: =IF(E7="","",IFERROR(INDEX(Agentes!$F$6:$F$12,MATCH(E7,Agentes!$A$6:$A$12,0)),"Agente?")) -> 0.025 | R7: =IF(N(H7)=0,"",8/H7*(24-H7)/16) -> 1 | S7: =IF(N(I7)=0,"",40/I7*(168-I7)/128) -> 0.78125 | T7: =IF(E7="","",MIN(1,IF(R7="",1,R7),IF(S7="",1,S7))) -> 0.78125 | U7: =IF(OR(Q7="",T7=""),"",Q7*T7) -> 0.01953125 | V7: =IF(E7="","",IFERROR(INDEX(Agentes!$E$6:$E$12,MATCH(E7,Agentes!$A$6:$A$12,0)),"")) -> mg/m³
A8: G03 | B8: Pulidores de mármol y granito | C8: Taller de acabados | D8: Corte y pulido en húmedo de piezas de granito | E8: SIL-Q | F8: 12 | G8: Herramienta con agua; LEV en mesa de corte | H8: 8 | I8: 44 | J8: 400 | K8: =IF(J8="","",IF(J8>=360,4,IF(J8>=120,3,IF(J8>=30,2,IF(J8>0,1,0))))) -> 4 | L8: =IF(E8="","",IF(E8="PNOS",2,4)) -> 4 | M8: =IF(OR(K8="",L8=""),"",K8*L8) -> 16 | N8: =IF(M8="","",IF(M8=0,"Incipiente",IF(M8<=4,"Bajo",IF(M8<=8,"Moderado",IF(M8<=12,"Alto","Muy alto"))))) -> Muy alto | O8: =IF(A8="","",IF(N(F8)>50,ROUNDUP(SQRT(F8),0),6)) -> 6 | P8: Moderado | Q8: =IF(E8="","",IFERROR(INDEX(Agentes!$F$6:$F$12,MATCH(E8,Agentes!$A$6:$A$12,0)),"Agente?")) -> 0.025 | R8: =IF(N(H8)=0,"",8/H8*(24-H8)/16) -> 1 | S8: =IF(N(I8)=0,"",40/I8*(168-I8)/128) -> 0.88068182 | T8: =IF(E8="","",MIN(1,IF(R8="",1,R8),IF(S8="",1,S8))) -> 0.88068182 | U8: =IF(OR(Q8="",T8=""),"",Q8*T8) -> 0.022017045 | V8: =IF(E8="","",IFERROR(INDEX(Agentes!$E$6:$E$12,MATCH(E8,Agentes!$A$6:$A$12,0)),"")) -> mg/m³
A9: G04 | B9: Picadores y frenteros | C9: Mina subterránea de carbón | D9: Arranque con martillo picador, cargue y sostenimiento | E9: CAR-B | F9: 30 | G9: Ventilación principal; aspersión en frente | H9: 8 | I9: 48 | J9: 450 | K9: =IF(J9="","",IF(J9>=360,4,IF(J9>=120,3,IF(J9>=30,2,IF(J9>0,1,0))))) -> 4 | L9: =IF(E9="","",IF(E9="PNOS",2,4)) -> 4 | M9: =IF(OR(K9="",L9=""),"",K9*L9) -> 16 | N9: =IF(M9="","",IF(M9=0,"Incipiente",IF(M9<=4,"Bajo",IF(M9<=8,"Moderado",IF(M9<=12,"Alto","Muy alto"))))) -> Muy alto | O9: =IF(A9="","",IF(N(F9)>50,ROUNDUP(SQRT(F9),0),6)) -> 6 | P9: Crítico | Q9: =IF(E9="","",IFERROR(INDEX(Agentes!$F$6:$F$12,MATCH(E9,Agentes!$A$6:$A$12,0)),"Agente?")) -> 0.9 | R9: =IF(N(H9)=0,"",8/H9*(24-H9)/16) -> 1 | S9: =IF(N(I9)=0,"",40/I9*(168-I9)/128) -> 0.78125 | T9: =IF(E9="","",MIN(1,IF(R9="",1,R9),IF(S9="",1,S9))) -> 0.78125 | U9: =IF(OR(Q9="",T9=""),"",Q9*T9) -> 0.703125 | V9: =IF(E9="","",IFERROR(INDEX(Agentes!$E$6:$E$12,MATCH(E9,Agentes!$A$6:$A$12,0)),"")) -> mg/m³
A10: G05 | B10: Operadores de cargue y patio | C10: Patio de acopio de carbón | D10: Cargue de volquetas y apilamiento con cargador | E10: CAR-B | F10: 10 | G10: Cabina cerrada (sin presurizar); riego de vías | H10: 8 | I10: 48 | J10: 360 | K10: =IF(J10="","",IF(J10>=360,4,IF(J10>=120,3,IF(J10>=30,2,IF(J10>0,1,0))))) -> 4 | L10: =IF(E10="","",IF(E10="PNOS",2,4)) -> 4 | M10: =IF(OR(K10="",L10=""),"",K10*L10) -> 16 | N10: =IF(M10="","",IF(M10=0,"Incipiente",IF(M10<=4,"Bajo",IF(M10<=8,"Moderado",IF(M10<=12,"Alto","Muy alto"))))) -> Muy alto | O10: =IF(A10="","",IF(N(F10)>50,ROUNDUP(SQRT(F10),0),6)) -> 6 | P10: Moderado | Q10: =IF(E10="","",IFERROR(INDEX(Agentes!$F$6:$F$12,MATCH(E10,Agentes!$A$6:$A$12,0)),"Agente?")) -> 0.9 | R10: =IF(N(H10)=0,"",8/H10*(24-H10)/16) -> 1 | S10: =IF(N(I10)=0,"",40/I10*(168-I10)/128) -> 0.78125 | T10: =IF(E10="","",MIN(1,IF(R10="",1,R10),IF(S10="",1,S10))) -> 0.78125 | U10: =IF(OR(Q10="",T10=""),"",Q10*T10) -> 0.703125 | V10: =IF(E10="","",IFERROR(INDEX(Agentes!$E$6:$E$12,MATCH(E10,Agentes!$A$6:$A$12,0)),"")) -> mg/m³
A11: G06 | B11: Cuadrilla de demolición | C11: Mantenimiento de edificaciones | D11: Retiro de tejas y tanques de asbesto-cemento | E11: ASB | F11: 6 | G11: Humectación manual; respirador desechable | H11: 8 | I11: 48 | J11: 240 | K11: =IF(J11="","",IF(J11>=360,4,IF(J11>=120,3,IF(J11>=30,2,IF(J11>0,1,0))))) -> 3 | L11: =IF(E11="","",IF(E11="PNOS",2,4)) -> 4 | M11: =IF(OR(K11="",L11=""),"",K11*L11) -> 12 | N11: =IF(M11="","",IF(M11=0,"Incipiente",IF(M11<=4,"Bajo",IF(M11<=8,"Moderado",IF(M11<=12,"Alto","Muy alto"))))) -> Alto | O11: =IF(A11="","",IF(N(F11)>50,ROUNDUP(SQRT(F11),0),6)) -> 6 | P11: Alto | Q11: =IF(E11="","",IFERROR(INDEX(Agentes!$F$6:$F$12,MATCH(E11,Agentes!$A$6:$A$12,0)),"Agente?")) -> 0.1 | R11: =IF(N(H11)=0,"",8/H11*(24-H11)/16) -> 1 | S11: =IF(N(I11)=0,"",40/I11*(168-I11)/128) -> 0.78125 | T11: =IF(E11="","",MIN(1,IF(R11="",1,R11),IF(S11="",1,S11))) -> 0.78125 | U11: =IF(OR(Q11="",T11=""),"",Q11*T11) -> 0.078125 | V11: =IF(E11="","",IFERROR(INDEX(Agentes!$E$6:$E$12,MATCH(E11,Agentes!$A$6:$A$12,0)),"")) -> f/cm³
K12: =IF(J12="","",IF(J12>=360,4,IF(J12>=120,3,IF(J12>=30,2,IF(J12>0,1,0))))) | L12: =IF(E12="","",IF(E12="PNOS",2,4)) | M12: =IF(OR(K12="",L12=""),"",K12*L12) | N12: =IF(M12="","",IF(M12=0,"Incipiente",IF(M12<=4,"Bajo",IF(M12<=8,"Moderado",IF(M12<=12,"Alto","Muy alto"))))) | O12: =IF(A12="","",IF(N(F12)>50,ROUNDUP(SQRT(F12),0),6)) | Q12: =IF(E12="","",IFERROR(INDEX(Agentes!$F$6:$F$12,MATCH(E12,Agentes!$A$6:$A$12,0)),"Agente?")) | R12: =IF(N(H12)=0,"",8/H12*(24-H12)/16) | S12: =IF(N(I12)=0,"",40/I12*(168-I12)/128) | T12: =IF(E12="","",MIN(1,IF(R12="",1,R12),IF(S12="",1,S12))) | U12: =IF(OR(Q12="",T12=""),"",Q12*T12) | V12: =IF(E12="","",IFERROR(INDEX(Agentes!$E$6:$E$12,MATCH(E12,Agentes!$A$6:$A$12,0)),""))
K13: =IF(J13="","",IF(J13>=360,4,IF(J13>=120,3,IF(J13>=30,2,IF(J13>0,1,0))))) | L13: =IF(E13="","",IF(E13="PNOS",2,4)) | M13: =IF(OR(K13="",L13=""),"",K13*L13) | N13: =IF(M13="","",IF(M13=0,"Incipiente",IF(M13<=4,"Bajo",IF(M13<=8,"Moderado",IF(M13<=12,"Alto","Muy alto"))))) | O13: =IF(A13="","",IF(N(F13)>50,ROUNDUP(SQRT(F13),0),6)) | Q13: =IF(E13="","",IFERROR(INDEX(Agentes!$F$6:$F$12,MATCH(E13,Agentes!$A$6:$A$12,0)),"Agente?")) | R13: =IF(N(H13)=0,"",8/H13*(24-H13)/16) | S13: =IF(N(I13)=0,"",40/I13*(168-I13)/128) | T13: =IF(E13="","",MIN(1,IF(R13="",1,R13),IF(S13="",1,S13))) | U13: =IF(OR(Q13="",T13=""),"",Q13*T13) | V13: =IF(E13="","",IFERROR(INDEX(Agentes!$E$6:$E$12,MATCH(E13,Agentes!$A$6:$A$12,0)),""))
K14: =IF(J14="","",IF(J14>=360,4,IF(J14>=120,3,IF(J14>=30,2,IF(J14>0,1,0))))) | L14: =IF(E14="","",IF(E14="PNOS",2,4)) | M14: =IF(OR(K14="",L14=""),"",K14*L14) | N14: =IF(M14="","",IF(M14=0,"Incipiente",IF(M14<=4,"Bajo",IF(M14<=8,"Moderado",IF(M14<=12,"Alto","Muy alto"))))) | O14: =IF(A14="","",IF(N(F14)>50,ROUNDUP(SQRT(F14),0),6)) | Q14: =IF(E14="","",IFERROR(INDEX(Agentes!$F$6:$F$12,MATCH(E14,Agentes!$A$6:$A$12,0)),"Agente?")) | R14: =IF(N(H14)=0,"",8/H14*(24-H14)/16) | S14: =IF(N(I14)=0,"",40/I14*(168-I14)/128) | T14: =IF(E14="","",MIN(1,IF(R14="",1,R14),IF(S14="",1,S14))) | U14: =IF(OR(Q14="",T14=""),"",Q14*T14) | V14: =IF(E14="","",IFERROR(INDEX(Agentes!$E$6:$E$12,MATCH(E14,Agentes!$A$6:$A$12,0)),""))
K15: =IF(J15="","",IF(J15>=360,4,IF(J15>=120,3,IF(J15>=30,2,IF(J15>0,1,0))))) | L15: =IF(E15="","",IF(E15="PNOS",2,4)) | M15: =IF(OR(K15="",L15=""),"",K15*L15) | N15: =IF(M15="","",IF(M15=0,"Incipiente",IF(M15<=4,"Bajo",IF(M15<=8,"Moderado",IF(M15<=12,"Alto","Muy alto"))))) | O15: =IF(A15="","",IF(N(F15)>50,ROUNDUP(SQRT(F15),0),6)) | Q15: =IF(E15="","",IFERROR(INDEX(Agentes!$F$6:$F$12,MATCH(E15,Agentes!$A$6:$A$12,0)),"Agente?")) | R15: =IF(N(H15)=0,"",8/H15*(24-H15)/16) | S15: =IF(N(I15)=0,"",40/I15*(168-I15)/128) | T15: =IF(E15="","",MIN(1,IF(R15="",1,R15),IF(S15="",1,S15))) | U15: =IF(OR(Q15="",T15=""),"",Q15*T15) | V15: =IF(E15="","",IFERROR(INDEX(Agentes!$E$6:$E$12,MATCH(E15,Agentes!$A$6:$A$12,0)),""))
K16: =IF(J16="","",IF(J16>=360,4,IF(J16>=120,3,IF(J16>=30,2,IF(J16>0,1,0))))) | L16: =IF(E16="","",IF(E16="PNOS",2,4)) | M16: =IF(OR(K16="",L16=""),"",K16*L16) | N16: =IF(M16="","",IF(M16=0,"Incipiente",IF(M16<=4,"Bajo",IF(M16<=8,"Moderado",IF(M16<=12,"Alto","Muy alto"))))) | O16: =IF(A16="","",IF(N(F16)>50,ROUNDUP(SQRT(F16),0),6)) | Q16: =IF(E16="","",IFERROR(INDEX(Agentes!$F$6:$F$12,MATCH(E16,Agentes!$A$6:$A$12,0)),"Agente?")) | R16: =IF(N(H16)=0,"",8/H16*(24-H16)/16) | S16: =IF(N(I16)=0,"",40/I16*(168-I16)/128) | T16: =IF(E16="","",MIN(1,IF(R16="",1,R16),IF(S16="",1,S16))) | U16: =IF(OR(Q16="",T16=""),"",Q16*T16) | V16: =IF(E16="","",IFERROR(INDEX(Agentes!$E$6:$E$12,MATCH(E16,Agentes!$A$6:$A$12,0)),""))
K17: =IF(J17="","",IF(J17>=360,4,IF(J17>=120,3,IF(J17>=30,2,IF(J17>0,1,0))))) | L17: =IF(E17="","",IF(E17="PNOS",2,4)) | M17: =IF(OR(K17="",L17=""),"",K17*L17) | N17: =IF(M17="","",IF(M17=0,"Incipiente",IF(M17<=4,"Bajo",IF(M17<=8,"Moderado",IF(M17<=12,"Alto","Muy alto"))))) | O17: =IF(A17="","",IF(N(F17)>50,ROUNDUP(SQRT(F17),0),6)) | Q17: =IF(E17="","",IFERROR(INDEX(Agentes!$F$6:$F$12,MATCH(E17,Agentes!$A$6:$A$12,0)),"Agente?")) | R17: =IF(N(H17)=0,"",8/H17*(24-H17)/16) | S17: =IF(N(I17)=0,"",40/I17*(168-I17)/128) | T17: =IF(E17="","",MIN(1,IF(R17="",1,R17),IF(S17="",1,S17))) | U17: =IF(OR(Q17="",T17=""),"",Q17*T17) | V17: =IF(E17="","",IFERROR(INDEX(Agentes!$E$6:$E$12,MATCH(E17,Agentes!$A$6:$A$12,0)),""))
K18: =IF(J18="","",IF(J18>=360,4,IF(J18>=120,3,IF(J18>=30,2,IF(J18>0,1,0))))) | L18: =IF(E18="","",IF(E18="PNOS",2,4)) | M18: =IF(OR(K18="",L18=""),"",K18*L18) | N18: =IF(M18="","",IF(M18=0,"Incipiente",IF(M18<=4,"Bajo",IF(M18<=8,"Moderado",IF(M18<=12,"Alto","Muy alto"))))) | O18: =IF(A18="","",IF(N(F18)>50,ROUNDUP(SQRT(F18),0),6)) | Q18: =IF(E18="","",IFERROR(INDEX(Agentes!$F$6:$F$12,MATCH(E18,Agentes!$A$6:$A$12,0)),"Agente?")) | R18: =IF(N(H18)=0,"",8/H18*(24-H18)/16) | S18: =IF(N(I18)=0,"",40/I18*(168-I18)/128) | T18: =IF(E18="","",MIN(1,IF(R18="",1,R18),IF(S18="",1,S18))) | U18: =IF(OR(Q18="",T18=""),"",Q18*T18) | V18: =IF(E18="","",IFERROR(INDEX(Agentes!$E$6:$E$12,MATCH(E18,Agentes!$A$6:$A$12,0)),""))
K19: =IF(J19="","",IF(J19>=360,4,IF(J19>=120,3,IF(J19>=30,2,IF(J19>0,1,0))))) | L19: =IF(E19="","",IF(E19="PNOS",2,4)) | M19: =IF(OR(K19="",L19=""),"",K19*L19) | N19: =IF(M19="","",IF(M19=0,"Incipiente",IF(M19<=4,"Bajo",IF(M19<=8,"Moderado",IF(M19<=12,"Alto","Muy alto"))))) | O19: =IF(A19="","",IF(N(F19)>50,ROUNDUP(SQRT(F19),0),6)) | Q19: =IF(E19="","",IFERROR(INDEX(Agentes!$F$6:$F$12,MATCH(E19,Agentes!$A$6:$A$12,0)),"Agente?")) | R19: =IF(N(H19)=0,"",8/H19*(24-H19)/16) | S19: =IF(N(I19)=0,"",40/I19*(168-I19)/128) | T19: =IF(E19="","",MIN(1,IF(R19="",1,R19),IF(S19="",1,S19))) | U19: =IF(OR(Q19="",T19=""),"",Q19*T19) | V19: =IF(E19="","",IFERROR(INDEX(Agentes!$E$6:$E$12,MATCH(E19,Agentes!$A$6:$A$12,0)),""))
K20: =IF(J20="","",IF(J20>=360,4,IF(J20>=120,3,IF(J20>=30,2,IF(J20>0,1,0))))) | L20: =IF(E20="","",IF(E20="PNOS",2,4)) | M20: =IF(OR(K20="",L20=""),"",K20*L20) | N20: =IF(M20="","",IF(M20=0,"Incipiente",IF(M20<=4,"Bajo",IF(M20<=8,"Moderado",IF(M20<=12,"Alto","Muy alto"))))) | O20: =IF(A20="","",IF(N(F20)>50,ROUNDUP(SQRT(F20),0),6)) | Q20: =IF(E20="","",IFERROR(INDEX(Agentes!$F$6:$F$12,MATCH(E20,Agentes!$A$6:$A$12,0)),"Agente?")) | R20: =IF(N(H20)=0,"",8/H20*(24-H20)/16) | S20: =IF(N(I20)=0,"",40/I20*(168-I20)/128) | T20: =IF(E20="","",MIN(1,IF(R20="",1,R20),IF(S20="",1,S20))) | U20: =IF(OR(Q20="",T20=""),"",Q20*T20) | V20: =IF(E20="","",IFERROR(INDEX(Agentes!$E$6:$E$12,MATCH(E20,Agentes!$A$6:$A$12,0)),""))
K21: =IF(J21="","",IF(J21>=360,4,IF(J21>=120,3,IF(J21>=30,2,IF(J21>0,1,0))))) | L21: =IF(E21="","",IF(E21="PNOS",2,4)) | M21: =IF(OR(K21="",L21=""),"",K21*L21) | N21: =IF(M21="","",IF(M21=0,"Incipiente",IF(M21<=4,"Bajo",IF(M21<=8,"Moderado",IF(M21<=12,"Alto","Muy alto"))))) | O21: =IF(A21="","",IF(N(F21)>50,ROUNDUP(SQRT(F21),0),6)) | Q21: =IF(E21="","",IFERROR(INDEX(Agentes!$F$6:$F$12,MATCH(E21,Agentes!$A$6:$A$12,0)),"Agente?")) | R21: =IF(N(H21)=0,"",8/H21*(24-H21)/16) | S21: =IF(N(I21)=0,"",40/I21*(168-I21)/128) | T21: =IF(E21="","",MIN(1,IF(R21="",1,R21),IF(S21="",1,S21))) | U21: =IF(OR(Q21="",T21=""),"",Q21*T21) | V21: =IF(E21="","",IFERROR(INDEX(Agentes!$E$6:$E$12,MATCH(E21,Agentes!$A$6:$A$12,0)),""))
K22: =IF(J22="","",IF(J22>=360,4,IF(J22>=120,3,IF(J22>=30,2,IF(J22>0,1,0))))) | L22: =IF(E22="","",IF(E22="PNOS",2,4)) | M22: =IF(OR(K22="",L22=""),"",K22*L22) | N22: =IF(M22="","",IF(M22=0,"Incipiente",IF(M22<=4,"Bajo",IF(M22<=8,"Moderado",IF(M22<=12,"Alto","Muy alto"))))) | O22: =IF(A22="","",IF(N(F22)>50,ROUNDUP(SQRT(F22),0),6)) | Q22: =IF(E22="","",IFERROR(INDEX(Agentes!$F$6:$F$12,MATCH(E22,Agentes!$A$6:$A$12,0)),"Agente?")) | R22: =IF(N(H22)=0,"",8/H22*(24-H22)/16) | S22: =IF(N(I22)=0,"",40/I22*(168-I22)/128) | T22: =IF(E22="","",MIN(1,IF(R22="",1,R22),IF(S22="",1,S22))) | U22: =IF(OR(Q22="",T22=""),"",Q22*T22) | V22: =IF(E22="","",IFERROR(INDEX(Agentes!$E$6:$E$12,MATCH(E22,Agentes!$A$6:$A$12,0)),""))
K23: =IF(J23="","",IF(J23>=360,4,IF(J23>=120,3,IF(J23>=30,2,IF(J23>0,1,0))))) | L23: =IF(E23="","",IF(E23="PNOS",2,4)) | M23: =IF(OR(K23="",L23=""),"",K23*L23) | N23: =IF(M23="","",IF(M23=0,"Incipiente",IF(M23<=4,"Bajo",IF(M23<=8,"Moderado",IF(M23<=12,"Alto","Muy alto"))))) | O23: =IF(A23="","",IF(N(F23)>50,ROUNDUP(SQRT(F23),0),6)) | Q23: =IF(E23="","",IFERROR(INDEX(Agentes!$F$6:$F$12,MATCH(E23,Agentes!$A$6:$A$12,0)),"Agente?")) | R23: =IF(N(H23)=0,"",8/H23*(24-H23)/16) | S23: =IF(N(I23)=0,"",40/I23*(168-I23)/128) | T23: =IF(E23="","",MIN(1,IF(R23="",1,R23),IF(S23="",1,S23))) | U23: =IF(OR(Q23="",T23=""),"",Q23*T23) | V23: =IF(E23="","",IFERROR(INDEX(Agentes!$E$6:$E$12,MATCH(E23,Agentes!$A$6:$A$12,0)),""))
... K25: =IF(J25="","",IF(J25>=360,4,IF(J25>=120,3,IF(J25>=30,2,IF(J25>0,1,0))))) | L25: =IF(E25="","",IF(E25="PNOS",2,4)) | M25: =IF(OR(K25="",L25=""),"",K25*L25) | N25: =IF(M25="","",IF(M25=0,"Incipiente",IF(M25<=4,"Bajo",IF(M25<=8,"Moderado",IF(M25<=12,"Alto","Muy alto"))))) | O25: =IF(A25="","",IF(N(F25)>50,ROUNDUP(SQRT(F25),0),6)) | Q25: =IF(E25="","",IFERROR(INDEX(Agentes!$F$6:$F$12,MATCH(E25,Agentes!$A$6:$A$12,0)),"Agente?")) | R25: =IF(N(H25)=0,"",8/H25*(24-H25)/16) | S25: =IF(N(I25)=0,"",40/I25*(168-I25)/128) | T25: =IF(E25="","",MIN(1,IF(R25="",1,R25),IF(S25="",1,S25))) | U25: =IF(OR(Q25="",T25=""),"",Q25*T25) | V25: =IF(E25="","",IFERROR(INDEX(Agentes!$E$6:$E$12,MATCH(E25,Agentes!$A$6:$A$12,0)),""))

Sheet Muestreo
A1: 3. Registro de muestras personales
A2: Una fila por muestra. Ingrese masa + caudal + tiempo, o la concentración reportada por el laboratorio (columna J; obligatoria para asbesto en f/cm³). Valores < LD: registre LD/2.
A3: NeumoRisk V1 · Sílice cristalina, carbón y asbesto · SCHO · Celdas amarillas con texto azul = datos a diligenciar; celdas grises = cálculo automático (no editar).
A5: Nº | B5: Código GES | C5: Fecha | D5: Trabajador / cargo | E5: Tipo de muestra | F5: Caudal (L/min) | G5: Tiempo de muestreo (min) | H5: Volumen (m³) | I5: Masa del analito (mg) | J5: Concentración reportada por laboratorio | K5: % sílice cristalina en el polvo | L5: Concentración (mg/m³ o f/cm³) | M5: Agente | N5: Cuarzo derivado (mg/m³) | O5: TLV ajustado | P5: Índice C / TLV aj. | Q5: Verificación de rango (si DEG excede) | R5: Observaciones | S5: ln C (aux) | T5: (ln C − ln MG)² (aux) | U5: (C − MA)² (aux) | V5: > TLV (aux)
A6: 1 | B6: G01 | C6: 46266 | D6: Operador trituradora 1 | E6: Personal | F6: 1.7 | G6: 480 | H6: =IF(OR(F6="",G6=""),"",F6*G6/1000) -> 0.816 | I6: 0.03672 | L6: =IF(B6="","",IF(J6<>"",J6,IF(AND(N(I6)>0,N(H6)>0),I6/H6,""))) -> 0.045 | M6: =IF(B6="","",IFERROR(INDEX(GES!$E$6:$E$25,MATCH(B6,GES!$A$6:$A$25,0)),"GES?")) -> SIL-Q | N6: =IF(AND(ISNUMBER(L6),ISNUMBER(K6),LEFT(M6,3)="CAR"),L6*K6/100,"") | O6: =IF(B6="","",IFERROR(INDEX(GES!$U$6:$U$25,MATCH(B6,GES!$A$6:$A$25,0)),"")) -> 0.01953125 | P6: =IF(AND(ISNUMBER(L6),ISNUMBER(O6)),L6/O6,"") -> 2.304 | Q6: =IF(NOT(ISNUMBER(L6)),"",IFERROR(IF(INDEX(Estadística!$L$6:$L$25,MATCH(B6,Estadística!$A$6:$A$25,0))>INDEX(Estadística!$T$6:$T$25,MATCH(B6,Estadística!$A$6:$A$25,0)),IF(OR(L6<INDEX(Estadística!$I$6:$I$25,MATCH(B6,Estadística!$A$6:$A$25,0))/2,L6>2*INDEX(Estadística!$I$6:$I$25,MATCH(B6,Estadística!$A$6:$A$25,0))),"Fuera de ½MA–2MA: revisar","Dentro de ½MA–2MA"),"—"),"")) -> — | R6: Masa de cuarzo por DRX (NIOSH 7500) | S6: =IF(ISNUMBER(L6),IF(L6>0,LN(L6),""),"") -> -3.1010928 | T6: =IF(ISNUMBER(S6),IFERROR((S6-LN(INDEX(Estadística!$K$6:$K$25,MATCH(B6,Estadística!$A$6:$A$25,0))))^2,""),"") -> 0.022163042 | U6: =IF(ISNUMBER(L6),IFERROR((L6-INDEX(Estadística!$I$6:$I$25,MATCH(B6,Estadística!$A$6:$A$25,0)))^2,""),"") -> 6.9444444e-05 | V6: =IF(ISNUMBER(P6),IF(P6>1,1,0),"") -> 1
A7: 2 | B7: G01 | C7: 46267 | D7: Operador trituradora 2 | E7: Personal | F7: 1.7 | G7: 480 | H7: =IF(OR(F7="",G7=""),"",F7*G7/1000) -> 0.816 | I7: 0.05059 | L7: =IF(B7="","",IF(J7<>"",J7,IF(AND(N(I7)>0,N(H7)>0),I7/H7,""))) -> 0.061997549 | M7: =IF(B7="","",IFERROR(INDEX(GES!$E$6:$E$25,MATCH(B7,GES!$A$6:$A$25,0)),"GES?")) -> SIL-Q | N7: =IF(AND(ISNUMBER(L7),ISNUMBER(K7),LEFT(M7,3)="CAR"),L7*K7/100,"") | O7: =IF(B7="","",IFERROR(INDEX(GES!$U$6:$U$25,MATCH(B7,GES!$A$6:$A$25,0)),"")) -> 0.01953125 | P7: =IF(AND(ISNUMBER(L7),ISNUMBER(O7)),L7/O7,"") -> 3.1742745 | Q7: =IF(NOT(ISNUMBER(L7)),"",IFERROR(IF(INDEX(Estadística!$L$6:$L$25,MATCH(B7,Estadística!$A$6:$A$25,0))>INDEX(Estadística!$T$6:$T$25,MATCH(B7,Estadística!$A$6:$A$25,0)),IF(OR(L7<INDEX(Estadística!$I$6:$I$25,MATCH(B7,Estadística!$A$6:$A$25,0))/2,L7>2*INDEX(Estadística!$I$6:$I$25,MATCH(B7,Estadística!$A$6:$A$25,0))),"Fuera de ½MA–2MA: revisar","Dentro de ½MA–2MA"),"—"),"")) -> — | S7: =IF(ISNUMBER(L7),IF(L7>0,LN(L7),""),"") -> -2.7806604 | T7: =IF(ISNUMBER(S7),IFERROR((S7-LN(INDEX(Estadística!$K$6:$K$25,MATCH(B7,Estadística!$A$6:$A$25,0))))^2,""),"") -> 0.029432763 | U7: =IF(ISNUMBER(L7),IFERROR((L7-INDEX(Estadística!$I$6:$I$25,MATCH(B7,Estadística!$A$6:$A$25,0)))^2,""),"") -> 7.5068633e-05 | V7: =IF(ISNUMBER(P7),IF(P7>1,1,0),"") -> 1
A8: 3 | B8: G01 | C8: 46268 | D8: Operador trituradora 3 | E8: Personal | F8: 1.7 | G8: 480 | H8: =IF(OR(F8="",G8=""),"",F8*G8/1000) -> 0.816 | I8: 0.03101 | L8: =IF(B8="","",IF(J8<>"",J8,IF(AND(N(I8)>0,N(H8)>0),I8/H8,""))) -> 0.038002451 | M8: =IF(B8="","",IFERROR(INDEX(GES!$E$6:$E$25,MATCH(B8,GES!$A$6:$A$25,0)),"GES?")) -> SIL-Q | N8: =IF(AND(ISNUMBER(L8),ISNUMBER(K8),LEFT(M8,3)="CAR"),L8*K8/100,"") | O8: =IF(B8="","",IFERROR(INDEX(GES!$U$6:$U$25,MATCH(B8,GES!$A$6:$A$25,0)),"")) -> 0.01953125 | P8: =IF(AND(ISNUMBER(L8),ISNUMBER(O8)),L8/O8,"") -> 1.9457255 | Q8: =IF(NOT(ISNUMBER(L8)),"",IFERROR(IF(INDEX(Estadística!$L$6:$L$25,MATCH(B8,Estadística!$A$6:$A$25,0))>INDEX(Estadística!$T$6:$T$25,MATCH(B8,Estadística!$A$6:$A$25,0)),IF(OR(L8<INDEX(Estadística!$I$6:$I$25,MATCH(B8,Estadística!$A$6:$A$25,0))/2,L8>2*INDEX(Estadística!$I$6:$I$25,MATCH(B8,Estadística!$A$6:$A$25,0))),"Fuera de ½MA–2MA: revisar","Dentro de ½MA–2MA"),"—"),"")) -> — | S8: =IF(ISNUMBER(L8),IF(L8>0,LN(L8),""),"") -> -3.2701046 | T8: =IF(ISNUMBER(S8),IFERROR((S8-LN(INDEX(Estadística!$K$6:$K$25,MATCH(B8,Estadística!$A$6:$A$25,0))))^2,""),"") -> 0.10105049 | U8: =IF(ISNUMBER(L8),IFERROR((L8-INDEX(Estadística!$I$6:$I$25,MATCH(B8,Estadística!$A$6:$A$25,0)))^2,""),"") -> 0.00023503595 | V8: =IF(ISNUMBER(P8),IF(P8>1,1,0),"") -> 1
A9: 4 | B9: G01 | C9: 46269 | D9: Operador trituradora 4 | E9: Personal | F9: 1.7 | G9: 480 | H9: =IF(OR(F9="",G9=""),"",F9*G9/1000) -> 0.816 | I9: 0.05794 | L9: =IF(B9="","",IF(J9<>"",J9,IF(AND(N(I9)>0,N(H9)>0),I9/H9,""))) -> 0.071004902 | M9: =IF(B9="","",IFERROR(INDEX(GES!$E$6:$E$25,MATCH(B9,GES!$A$6:$A$25,0)),"GES?")) -> SIL-Q | N9: =IF(AND(ISNUMBER(L9),ISNUMBER(K9),LEFT(M9,3)="CAR"),L9*K9/100,"") | O9: =IF(B9="","",IFERROR(INDEX(GES!$U$6:$U$25,MATCH(B9,GES!$A$6:$A$25,0)),"")) -> 0.01953125 | P9: =IF(AND(ISNUMBER(L9),ISNUMBER(O9)),L9/O9,"") -> 3.635451 | Q9: =IF(NOT(ISNUMBER(L9)),"",IFERROR(IF(INDEX(Estadística!$L$6:$L$25,MATCH(B9,Estadística!$A$6:$A$25,0))>INDEX(Estadística!$T$6:$T$25,MATCH(B9,Estadística!$A$6:$A$25,0)),IF(OR(L9<INDEX(Estadística!$I$6:$I$25,MATCH(B9,Estadística!$A$6:$A$25,0))/2,L9>2*INDEX(Estadística!$I$6:$I$25,MATCH(B9,Estadística!$A$6:$A$25,0))),"Fuera de ½MA–2MA: revisar","Dentro de ½MA–2MA"),"—"),"")) -> — | S9: =IF(ISNUMBER(L9),IF(L9>0,LN(L9),""),"") -> -2.6450064 | T9: =IF(ISNUMBER(S9),IFERROR((S9-LN(INDEX(Estadística!$K$6:$K$25,MATCH(B9,Estadística!$A$6:$A$25,0))))^2,""),"") -> 0.094380354 | U9: =IF(ISNUMBER(L9),IFERROR((L9-INDEX(Estadística!$I$6:$I$25,MATCH(B9,Estadística!$A$6:$A$25,0)))^2,""),"") -> 0.00031228434 | V9: =IF(ISNUMBER(P9),IF(P9>1,1,0),"") -> 1
A10: 5 | B10: G01 | C10: 46270 | D10: Operador trituradora 5 | E10: Personal | F10: 1.7 | G10: 480 | H10: =IF(OR(F10="",G10=""),"",F10*G10/1000) -> 0.816 | I10: 0.04488 | L10: =IF(B10="","",IF(J10<>"",J10,IF(AND(N(I10)>0,N(H10)>0),I10/H10,""))) -> 0.055 | M10: =IF(B10="","",IFERROR(INDEX(GES!$E$6:$E$25,MATCH(B10,GES!$A$6:$A$25,0)),"GES?")) -> SIL-Q | N10: =IF(AND(ISNUMBER(L10),ISNUMBER(K10),LEFT(M10,3)="CAR"),L10*K10/100,"") | O10: =IF(B10="","",IFERROR(INDEX(GES!$U$6:$U$25,MATCH(B10,GES!$A$6:$A$25,0)),"")) -> 0.01953125 | P10: =IF(AND(ISNUMBER(L10),ISNUMBER(O10)),L10/O10,"") -> 2.816 | Q10: =IF(NOT(ISNUMBER(L10)),"",IFERROR(IF(INDEX(Estadística!$L$6:$L$25,MATCH(B10,Estadística!$A$6:$A$25,0))>INDEX(Estadística!$T$6:$T$25,MATCH(B10,Estadística!$A$6:$A$25,0)),IF(OR(L10<INDEX(Estadística!$I$6:$I$25,MATCH(B10,Estadística!$A$6:$A$25,0))/2,L10>2*INDEX(Estadística!$I$6:$I$25,MATCH(B10,Estadística!$A$6:$A$25,0))),"Fuera de ½MA–2MA: revisar","Dentro de ½MA–2MA"),"—"),"")) -> — | S10: =IF(ISNUMBER(L10),IF(L10>0,LN(L10),""),"") -> -2.9004221 | T10: =IF(ISNUMBER(S10),IFERROR((S10-LN(INDEX(Estadística!$K$6:$K$25,MATCH(B10,Estadística!$A$6:$A$25,0))))^2,""),"") -> 0.0026830459 | U10: =IF(ISNUMBER(L10),IFERROR((L10-INDEX(Estadística!$I$6:$I$25,MATCH(B10,Estadística!$A$6:$A$25,0)))^2,""),"") -> 2.7777778e-06 | V10: =IF(ISNUMBER(P10),IF(P10>1,1,0),"") -> 1
A11: 6 | B11: G01 | C11: 46271 | D11: Operador trituradora 6 | E11: Personal | F11: 1.7 | G11: 480 | H11: =IF(OR(F11="",G11=""),"",F11*G11/1000) -> 0.816 | I11: 0.03998 | L11: =IF(B11="","",IF(J11<>"",J11,IF(AND(N(I11)>0,N(H11)>0),I11/H11,""))) -> 0.048995098 | M11: =IF(B11="","",IFERROR(INDEX(GES!$E$6:$E$25,MATCH(B11,GES!$A$6:$A$25,0)),"GES?")) -> SIL-Q | N11: =IF(AND(ISNUMBER(L11),ISNUMBER(K11),LEFT(M11,3)="CAR"),L11*K11/100,"") | O11: =IF(B11="","",IFERROR(INDEX(GES!$U$6:$U$25,MATCH(B11,GES!$A$6:$A$25,0)),"")) -> 0.01953125 | P11: =IF(AND(ISNUMBER(L11),ISNUMBER(O11)),L11/O11,"") -> 2.508549 | Q11: =IF(NOT(ISNUMBER(L11)),"",IFERROR(IF(INDEX(Estadística!$L$6:$L$25,MATCH(B11,Estadística!$A$6:$A$25,0))>INDEX(Estadística!$T$6:$T$25,MATCH(B11,Estadística!$A$6:$A$25,0)),IF(OR(L11<INDEX(Estadística!$I$6:$I$25,MATCH(B11,Estadística!$A$6:$A$25,0))/2,L11>2*INDEX(Estadística!$I$6:$I$25,MATCH(B11,Estadística!$A$6:$A$25,0))),"Fuera de ½MA–2MA: revisar","Dentro de ½MA–2MA"),"—"),"")) -> — | S11: =IF(ISNUMBER(L11),IF(L11>0,LN(L11),""),"") -> -3.016035 | T11: =IF(ISNUMBER(S11),IFERROR((S11-LN(INDEX(Estadística!$K$6:$K$25,MATCH(B11,Estadística!$A$6:$A$25,0))))^2,""),"") -> 0.0040723295 | U11: =IF(ISNUMBER(L11),IFERROR((L11-INDEX(Estadística!$I$6:$I$25,MATCH(B11,Estadística!$A$6:$A$25,0)))^2,""),"") -> 1.8820285e-05 | V11: =IF(ISNUMBER(P11),IF(P11>1,1,0),"") -> 1
A12: 7 | B12: G02 | C12: 46272 | D12: Operario moldeo 1 | E12: Personal | F12: 1.7 | G12: 480 | H12: =IF(OR(F12="",G12=""),"",F12*G12/1000) -> 0.816 | J12: 0.009 | L12: =IF(B12="","",IF(J12<>"",J12,IF(AND(N(I12)>0,N(H12)>0),I12/H12,""))) -> 0.009 | M12: =IF(B12="","",IFERROR(INDEX(GES!$E$6:$E$25,MATCH(B12,GES!$A$6:$A$25,0)),"GES?")) -> SIL-Q | N12: =IF(AND(ISNUMBER(L12),ISNUMBER(K12),LEFT(M12,3)="CAR"),L12*K12/100,"") | O12: =IF(B12="","",IFERROR(INDEX(GES!$U$6:$U$25,MATCH(B12,GES!$A$6:$A$25,0)),"")) -> 0.01953125 | P12: =IF(AND(ISNUMBER(L12),ISNUMBER(O12)),L12/O12,"") -> 0.4608 | Q12: =IF(NOT(ISNUMBER(L12)),"",IFERROR(IF(INDEX(Estadística!$L$6:$L$25,MATCH(B12,Estadística!$A$6:$A$25,0))>INDEX(Estadística!$T$6:$T$25,MATCH(B12,Estadística!$A$6:$A$25,0)),IF(OR(L12<INDEX(Estadística!$I$6:$I$25,MATCH(B12,Estadística!$A$6:$A$25,0))/2,L12>2*INDEX(Estadística!$I$6:$I$25,MATCH(B12,Estadística!$A$6:$A$25,0))),"Fuera de ½MA–2MA: revisar","Dentro de ½MA–2MA"),"—"),"")) -> — | S12: =IF(ISNUMBER(L12),IF(L12>0,LN(L12),""),"") -> -4.7105307 | T12: =IF(ISNUMBER(S12),IFERROR((S12-LN(INDEX(Estadística!$K$6:$K$25,MATCH(B12,Estadística!$A$6:$A$25,0))))^2,""),"") -> 0.019770939 | U12: =IF(ISNUMBER(L12),IFERROR((L12-INDEX(Estadística!$I$6:$I$25,MATCH(B12,Estadística!$A$6:$A$25,0)))^2,""),"") -> 2.25e-06 | V12: =IF(ISNUMBER(P12),IF(P12>1,1,0),"") -> 0
A13: 8 | B13: G02 | C13: 46273 | D13: Operario moldeo 2 | E13: Personal | F13: 1.7 | G13: 480 | H13: =IF(OR(F13="",G13=""),"",F13*G13/1000) -> 0.816 | J13: 0.012 | L13: =IF(B13="","",IF(J13<>"",J13,IF(AND(N(I13)>0,N(H13)>0),I13/H13,""))) -> 0.012 | M13: =IF(B13="","",IFERROR(INDEX(GES!$E$6:$E$25,MATCH(B13,GES!$A$6:$A$25,0)),"GES?")) -> SIL-Q | N13: =IF(AND(ISNUMBER(L13),ISNUMBER(K13),LEFT(M13,3)="CAR"),L13*K13/100,"") | O13: =IF(B13="","",IFERROR(INDEX(GES!$U$6:$U$25,MATCH(B13,GES!$A$6:$A$25,0)),"")) -> 0.01953125 | P13: =IF(AND(ISNUMBER(L13),ISNUMBER(O13)),L13/O13,"") -> 0.6144 | Q13: =IF(NOT(ISNUMBER(L13)),"",IFERROR(IF(INDEX(Estadística!$L$6:$L$25,MATCH(B13,Estadística!$A$6:$A$25,0))>INDEX(Estadística!$T$6:$T$25,MATCH(B13,Estadística!$A$6:$A$25,0)),IF(OR(L13<INDEX(Estadística!$I$6:$I$25,MATCH(B13,Estadística!$A$6:$A$25,0))/2,L13>2*INDEX(Estadística!$I$6:$I$25,MATCH(B13,Estadística!$A$6:$A$25,0))),"Fuera de ½MA–2MA: revisar","Dentro de ½MA–2MA"),"—"),"")) -> — | S13: =IF(ISNUMBER(L13),IF(L13>0,LN(L13),""),"") -> -4.4228486 | T13: =IF(ISNUMBER(S13),IFERROR((S13-LN(INDEX(Estadística!$K$6:$K$25,MATCH(B13,Estadística!$A$6:$A$25,0))))^2,""),"") -> 0.021630438 | U13: =IF(ISNUMBER(L13),IFERROR((L13-INDEX(Estadística!$I$6:$I$25,MATCH(B13,Estadística!$A$6:$A$25,0)))^2,""),"") -> 2.25e-06 | V13: =IF(ISNUMBER(P13),IF(P13>1,1,0),"") -> 0
A14: 9 | B14: G02 | C14: 46274 | D14: Operario moldeo 3 | E14: Personal | F14: 1.7 | G14: 480 | H14: =IF(OR(F14="",G14=""),"",F14*G14/1000) -> 0.816 | J14: 0.008 | L14: =IF(B14="","",IF(J14<>"",J14,IF(AND(N(I14)>0,N(H14)>0),I14/H14,""))) -> 0.008 | M14: =IF(B14="","",IFERROR(INDEX(GES!$E$6:$E$25,MATCH(B14,GES!$A$6:$A$25,0)),"GES?")) -> SIL-Q | N14: =IF(AND(ISNUMBER(L14),ISNUMBER(K14),LEFT(M14,3)="CAR"),L14*K14/100,"") | O14: =IF(B14="","",IFERROR(INDEX(GES!$U$6:$U$25,MATCH(B14,GES!$A$6:$A$25,0)),"")) -> 0.01953125 | P14: =IF(AND(ISNUMBER(L14),ISNUMBER(O14)),L14/O14,"") -> 0.4096 | Q14: =IF(NOT(ISNUMBER(L14)),"",IFERROR(IF(INDEX(Estadística!$L$6:$L$25,MATCH(B14,Estadística!$A$6:$A$25,0))>INDEX(Estadística!$T$6:$T$25,MATCH(B14,Estadística!$A$6:$A$25,0)),IF(OR(L14<INDEX(Estadística!$I$6:$I$25,MATCH(B14,Estadística!$A$6:$A$25,0))/2,L14>2*INDEX(Estadística!$I$6:$I$25,MATCH(B14,Estadística!$A$6:$A$25,0))),"Fuera de ½MA–2MA: revisar","Dentro de ½MA–2MA"),"—"),"")) -> — | S14: =IF(ISNUMBER(L14),IF(L14>0,LN(L14),""),"") -> -4.8283137 | T14: =IF(ISNUMBER(S14),IFERROR((S14-LN(INDEX(Estadística!$K$6:$K$25,MATCH(B14,Estadística!$A$6:$A$25,0))))^2,""),"") -> 0.066766533 | U14: =IF(ISNUMBER(L14),IFERROR((L14-INDEX(Estadística!$I$6:$I$25,MATCH(B14,Estadística!$A$6:$A$25,0)))^2,""),"") -> 6.25e-06 | V14: =IF(ISNUMBER(P14),IF(P14>1,1,0),"") -> 0
A15: 10 | B15: G02 | C15: 46275 | D15: Operario moldeo 4 | E15: Personal | F15: 1.7 | G15: 480 | H15: =IF(OR(F15="",G15=""),"",F15*G15/1000) -> 0.816 | J15: 0.011 | L15: =IF(B15="","",IF(J15<>"",J15,IF(AND(N(I15)>0,N(H15)>0),I15/H15,""))) -> 0.011 | M15: =IF(B15="","",IFERROR(INDEX(GES!$E$6:$E$25,MATCH(B15,GES!$A$6:$A$25,0)),"GES?")) -> SIL-Q | N15: =IF(AND(ISNUMBER(L15),ISNUMBER(K15),LEFT(M15,3)="CAR"),L15*K15/100,"") | O15: =IF(B15="","",IFERROR(INDEX(GES!$U$6:$U$25,MATCH(B15,GES!$A$6:$A$25,0)),"")) -> 0.01953125 | P15: =IF(AND(ISNUMBER(L15),ISNUMBER(O15)),L15/O15,"") -> 0.5632 | Q15: =IF(NOT(ISNUMBER(L15)),"",IFERROR(IF(INDEX(Estadística!$L$6:$L$25,MATCH(B15,Estadística!$A$6:$A$25,0))>INDEX(Estadística!$T$6:$T$25,MATCH(B15,Estadística!$A$6:$A$25,0)),IF(OR(L15<INDEX(Estadística!$I$6:$I$25,MATCH(B15,Estadística!$A$6:$A$25,0))/2,L15>2*INDEX(Estadística!$I$6:$I$25,MATCH(B15,Estadística!$A$6:$A$25,0))),"Fuera de ½MA–2MA: revisar","Dentro de ½MA–2MA"),"—"),"")) -> — | S15: =IF(ISNUMBER(L15),IF(L15>0,LN(L15),""),"") -> -4.50986 | T15: =IF(ISNUMBER(S15),IFERROR((S15-LN(INDEX(Estadística!$K$6:$K$25,MATCH(B15,Estadística!$A$6:$A$25,0))))^2,""),"") -> 0.0036073867 | U15: =IF(ISNUMBER(L15),IFERROR((L15-INDEX(Estadística!$I$6:$I$25,MATCH(B15,Estadística!$A$6:$A$25,0)))^2,""),"") -> 2.5e-07 | V15: =IF(ISNUMBER(P15),IF(P15>1,1,0),"") -> 0
A16: 11 | B16: G02 | C16: 46276 | D16: Operario moldeo 5 | E16: Personal | F16: 1.7 | G16: 480 | H16: =IF(OR(F16="",G16=""),"",F16*G16/1000) -> 0.816 | J16: 0.01 | L16: =IF(B16="","",IF(J16<>"",J16,IF(AND(N(I16)>0,N(H16)>0),I16/H16,""))) -> 0.01 | M16: =IF(B16="","",IFERROR(INDEX(GES!$E$6:$E$25,MATCH(B16,GES!$A$6:$A$25,0)),"GES?")) -> SIL-Q | N16: =IF(AND(ISNUMBER(L16),ISNUMBER(K16),LEFT(M16,3)="CAR"),L16*K16/100,"") | O16: =IF(B16="","",IFERROR(INDEX(GES!$U$6:$U$25,MATCH(B16,GES!$A$6:$A$25,0)),"")) -> 0.01953125 | P16: =IF(AND(ISNUMBER(L16),ISNUMBER(O16)),L16/O16,"") -> 0.512 | Q16: =IF(NOT(ISNUMBER(L16)),"",IFERROR(IF(INDEX(Estadística!$L$6:$L$25,MATCH(B16,Estadística!$A$6:$A$25,0))>INDEX(Estadística!$T$6:$T$25,MATCH(B16,Estadística!$A$6:$A$25,0)),IF(OR(L16<INDEX(Estadística!$I$6:$I$25,MATCH(B16,Estadística!$A$6:$A$25,0))/2,L16>2*INDEX(Estadística!$I$6:$I$25,MATCH(B16,Estadística!$A$6:$A$25,0))),"Fuera de ½MA–2MA: revisar","Dentro de ½MA–2MA"),"—"),"")) -> — | S16: =IF(ISNUMBER(L16),IF(L16>0,LN(L16),""),"") -> -4.6051702 | T16: =IF(ISNUMBER(S16),IFERROR((S16-LN(INDEX(Estadística!$K$6:$K$25,MATCH(B16,Estadística!$A$6:$A$25,0))))^2,""),"") -> 0.0012424677 | U16: =IF(ISNUMBER(L16),IFERROR((L16-INDEX(Estadística!$I$6:$I$25,MATCH(B16,Estadística!$A$6:$A$25,0)))^2,""),"") -> 2.5e-07 | V16: =IF(ISNUMBER(P16),IF(P16>1,1,0),"") -> 0
A17: 12 | B17: G02 | C17: 46277 | D17: Operario moldeo 6 | E17: Personal | F17: 1.7 | G17: 480 | H17: =IF(OR(F17="",G17=""),"",F17*G17/1000) -> 0.816 | J17: 0.013 | L17: =IF(B17="","",IF(J17<>"",J17,IF(AND(N(I17)>0,N(H17)>0),I17/H17,""))) -> 0.013 | M17: =IF(B17="","",IFERROR(INDEX(GES!$E$6:$E$25,MATCH(B17,GES!$A$6:$A$25,0)),"GES?")) -> SIL-Q | N17: =IF(AND(ISNUMBER(L17),ISNUMBER(K17),LEFT(M17,3)="CAR"),L17*K17/100,"") | O17: =IF(B17="","",IFERROR(INDEX(GES!$U$6:$U$25,MATCH(B17,GES!$A$6:$A$25,0)),"")) -> 0.01953125 | P17: =IF(AND(ISNUMBER(L17),ISNUMBER(O17)),L17/O17,"") -> 0.6656 | Q17: =IF(NOT(ISNUMBER(L17)),"",IFERROR(IF(INDEX(Estadística!$L$6:$L$25,MATCH(B17,Estadística!$A$6:$A$25,0))>INDEX(Estadística!$T$6:$T$25,MATCH(B17,Estadística!$A$6:$A$25,0)),IF(OR(L17<INDEX(Estadística!$I$6:$I$25,MATCH(B17,Estadística!$A$6:$A$25,0))/2,L17>2*INDEX(Estadística!$I$6:$I$25,MATCH(B17,Estadística!$A$6:$A$25,0))),"Fuera de ½MA–2MA: revisar","Dentro de ½MA–2MA"),"—"),"")) -> — | S17: =IF(ISNUMBER(L17),IF(L17>0,LN(L17),""),"") -> -4.3428059 | T17: =IF(ISNUMBER(S17),IFERROR((S17-LN(INDEX(Estadística!$K$6:$K$25,MATCH(B17,Estadística!$A$6:$A$25,0))))^2,""),"") -> 0.0515815 | U17: =IF(ISNUMBER(L17),IFERROR((L17-INDEX(Estadística!$I$6:$I$25,MATCH(B17,Estadística!$A$6:$A$25,0)))^2,""),"") -> 6.25e-06 | V17: =IF(ISNUMBER(P17),IF(P17>1,1,0),"") -> 0
A18: 13 | B18: G03 | C18: 46266 | D18: Pulidor 1 | E18: Personal | F18: 1.7 | G18: 480 | H18: =IF(OR(F18="",G18=""),"",F18*G18/1000) -> 0.816 | J18: 0.018 | L18: =IF(B18="","",IF(J18<>"",J18,IF(AND(N(I18)>0,N(H18)>0),I18/H18,""))) -> 0.018 | M18: =IF(B18="","",IFERROR(INDEX(GES!$E$6:$E$25,MATCH(B18,GES!$A$6:$A$25,0)),"GES?")) -> SIL-Q | N18: =IF(AND(ISNUMBER(L18),ISNUMBER(K18),LEFT(M18,3)="CAR"),L18*K18/100,"") | O18: =IF(B18="","",IFERROR(INDEX(GES!$U$6:$U$25,MATCH(B18,GES!$A$6:$A$25,0)),"")) -> 0.022017045 | P18: =IF(AND(ISNUMBER(L18),ISNUMBER(O18)),L18/O18,"") -> 0.81754839 | Q18: =IF(NOT(ISNUMBER(L18)),"",IFERROR(IF(INDEX(Estadística!$L$6:$L$25,MATCH(B18,Estadística!$A$6:$A$25,0))>INDEX(Estadística!$T$6:$T$25,MATCH(B18,Estadística!$A$6:$A$25,0)),IF(OR(L18<INDEX(Estadística!$I$6:$I$25,MATCH(B18,Estadística!$A$6:$A$25,0))/2,L18>2*INDEX(Estadística!$I$6:$I$25,MATCH(B18,Estadística!$A$6:$A$25,0))),"Fuera de ½MA–2MA: revisar","Dentro de ½MA–2MA"),"—"),"")) -> — | R18: Serie de 5 muestras del ejemplo 1 de la Guía Técnica 2024 | S18: =IF(ISNUMBER(L18),IF(L18>0,LN(L18),""),"") -> -4.0173835 | T18: =IF(ISNUMBER(S18),IFERROR((S18-LN(INDEX(Estadística!$K$6:$K$25,MATCH(B18,Estadística!$A$6:$A$25,0))))^2,""),"") -> 0.0041554035 | U18: =IF(ISNUMBER(L18),IFERROR((L18-INDEX(Estadística!$I$6:$I$25,MATCH(B18,Estadística!$A$6:$A$25,0)))^2,""),"") -> 1.96e-06 | V18: =IF(ISNUMBER(P18),IF(P18>1,1,0),"") -> 0
A19: 14 | B19: G03 | C19: 46267 | D19: Pulidor 2 | E19: Personal | F19: 1.7 | G19: 480 | H19: =IF(OR(F19="",G19=""),"",F19*G19/1000) -> 0.816 | J19: 0.02 | L19: =IF(B19="","",IF(J19<>"",J19,IF(AND(N(I19)>0,N(H19)>0),I19/H19,""))) -> 0.02 | M19: =IF(B19="","",IFERROR(INDEX(GES!$E$6:$E$25,MATCH(B19,GES!$A$6:$A$25,0)),"GES?")) -> SIL-Q | N19: =IF(AND(ISNUMBER(L19),ISNUMBER(K19),LEFT(M19,3)="CAR"),L19*K19/100,"") | O19: =IF(B19="","",IFERROR(INDEX(GES!$U$6:$U$25,MATCH(B19,GES!$A$6:$A$25,0)),"")) -> 0.022017045 | P19: =IF(AND(ISNUMBER(L19),ISNUMBER(O19)),L19/O19,"") -> 0.9083871 | Q19: =IF(NOT(ISNUMBER(L19)),"",IFERROR(IF(INDEX(Estadística!$L$6:$L$25,MATCH(B19,Estadística!$A$6:$A$25,0))>INDEX(Estadística!$T$6:$T$25,MATCH(B19,Estadística!$A$6:$A$25,0)),IF(OR(L19<INDEX(Estadística!$I$6:$I$25,MATCH(B19,Estadística!$A$6:$A$25,0))/2,L19>2*INDEX(Estadística!$I$6:$I$25,MATCH(B19,Estadística!$A$6:$A$25,0))),"Fuera de ½MA–2MA: revisar","Dentro de ½MA–2MA"),"—"),"")) -> — | S19: =IF(ISNUMBER(L19),IF(L19>0,LN(L19),""),"") -> -3.912023 | T19: =IF(ISNUMBER(S19),IFERROR((S19-LN(INDEX(Estadística!$K$6:$K$25,MATCH(B19,Estadística!$A$6:$A$25,0))))^2,""),"") -> 0.0016726543 | U19: =IF(ISNUMBER(L19),IFERROR((L19-INDEX(Estadística!$I$6:$I$25,MATCH(B19,Estadística!$A$6:$A$25,0)))^2,""),"") -> 3.6e-07 | V19: =IF(ISNUMBER(P19),IF(P19>1,1,0),"") -> 0
A20: 15 | B20: G03 | C20: 46268 | D20: Pulidor 3 | E20: Personal | F20: 1.7 | G20: 480 | H20: =IF(OR(F20="",G20=""),"",F20*G20/1000) -> 0.816 | J20: 0.023 | L20: =IF(B20="","",IF(J20<>"",J20,IF(AND(N(I20)>0,N(H20)>0),I20/H20,""))) -> 0.023 | M20: =IF(B20="","",IFERROR(INDEX(GES!$E$6:$E$25,MATCH(B20,GES!$A$6:$A$25,0)),"GES?")) -> SIL-Q | N20: =IF(AND(ISNUMBER(L20),ISNUMBER(K20),LEFT(M20,3)="CAR"),L20*K20/100,"") | O20: =IF(B20="","",IFERROR(INDEX(GES!$U$6:$U$25,MATCH(B20,GES!$A$6:$A$25,0)),"")) -> 0.022017045 | P20: =IF(AND(ISNUMBER(L20),ISNUMBER(O20)),L20/O20,"") -> 1.0446452 | Q20: =IF(NOT(ISNUMBER(L20)),"",IFERROR(IF(INDEX(Estadística!$L$6:$L$25,MATCH(B20,Estadística!$A$6:$A$25,0))>INDEX(Estadística!$T$6:$T$25,MATCH(B20,Estadística!$A$6:$A$25,0)),IF(OR(L20<INDEX(Estadística!$I$6:$I$25,MATCH(B20,Estadística!$A$6:$A$25,0))/2,L20>2*INDEX(Estadística!$I$6:$I$25,MATCH(B20,Estadística!$A$6:$A$25,0))),"Fuera de ½MA–2MA: revisar","Dentro de ½MA–2MA"),"—"),"")) -> — | S20: =IF(ISNUMBER(L20),IF(L20>0,LN(L20),""),"") -> -3.7722611 | T20: =IF(ISNUMBER(S20),IFERROR((S20-LN(INDEX(Estadística!$K$6:$K$25,MATCH(B20,Estadística!$A$6:$A$25,0))))^2,""),"") -> 0.03263805 | U20: =IF(ISNUMBER(L20),IFERROR((L20-INDEX(Estadística!$I$6:$I$25,MATCH(B20,Estadística!$A$6:$A$25,0)))^2,""),"") -> 1.296e-05 | V20: =IF(ISNUMBER(P20),IF(P20>1,1,0),"") -> 1
A21: 16 | B21: G03 | C21: 46269 | D21: Pulidor 4 | E21: Personal | F21: 1.7 | G21: 480 | H21: =IF(OR(F21="",G21=""),"",F21*G21/1000) -> 0.816 | J21: 0.015 | L21: =IF(B21="","",IF(J21<>"",J21,IF(AND(N(I21)>0,N(H21)>0),I21/H21,""))) -> 0.015 | M21: =IF(B21="","",IFERROR(INDEX(GES!$E$6:$E$25,MATCH(B21,GES!$A$6:$A$25,0)),"GES?")) -> SIL-Q | N21: =IF(AND(ISNUMBER(L21),ISNUMBER(K21),LEFT(M21,3)="CAR"),L21*K21/100,"") | O21: =IF(B21="","",IFERROR(INDEX(GES!$U$6:$U$25,MATCH(B21,GES!$A$6:$A$25,0)),"")) -> 0.022017045 | P21: =IF(AND(ISNUMBER(L21),ISNUMBER(O21)),L21/O21,"") -> 0.68129032 | Q21: =IF(NOT(ISNUMBER(L21)),"",IFERROR(IF(INDEX(Estadística!$L$6:$L$25,MATCH(B21,Estadística!$A$6:$A$25,0))>INDEX(Estadística!$T$6:$T$25,MATCH(B21,Estadística!$A$6:$A$25,0)),IF(OR(L21<INDEX(Estadística!$I$6:$I$25,MATCH(B21,Estadística!$A$6:$A$25,0))/2,L21>2*INDEX(Estadística!$I$6:$I$25,MATCH(B21,Estadística!$A$6:$A$25,0))),"Fuera de ½MA–2MA: revisar","Dentro de ½MA–2MA"),"—"),"")) -> — | S21: =IF(ISNUMBER(L21),IF(L21>0,LN(L21),""),"") -> -4.1997051 | T21: =IF(ISNUMBER(S21),IFERROR((S21-LN(INDEX(Estadística!$K$6:$K$25,MATCH(B21,Estadística!$A$6:$A$25,0))))^2,""),"") -> 0.060902331 | U21: =IF(ISNUMBER(L21),IFERROR((L21-INDEX(Estadística!$I$6:$I$25,MATCH(B21,Estadística!$A$6:$A$25,0)))^2,""),"") -> 1.936e-05 | V21: =IF(ISNUMBER(P21),IF(P21>1,1,0),"") -> 0
A22: 17 | B22: G03 | C22: 46270 | D22: Pulidor 5 | E22: Personal | F22: 1.7 | G22: 480 | H22: =IF(OR(F22="",G22=""),"",F22*G22/1000) -> 0.816 | J22: 0.021 | L22: =IF(B22="","",IF(J22<>"",J22,IF(AND(N(I22)>0,N(H22)>0),I22/H22,""))) -> 0.021 | M22: =IF(B22="","",IFERROR(INDEX(GES!$E$6:$E$25,MATCH(B22,GES!$A$6:$A$25,0)),"GES?")) -> SIL-Q | N22: =IF(AND(ISNUMBER(L22),ISNUMBER(K22),LEFT(M22,3)="CAR"),L22*K22/100,"") | O22: =IF(B22="","",IFERROR(INDEX(GES!$U$6:$U$25,MATCH(B22,GES!$A$6:$A$25,0)),"")) -> 0.022017045 | P22: =IF(AND(ISNUMBER(L22),ISNUMBER(O22)),L22/O22,"") -> 0.95380645 | Q22: =IF(NOT(ISNUMBER(L22)),"",IFERROR(IF(INDEX(Estadística!$L$6:$L$25,MATCH(B22,Estadística!$A$6:$A$25,0))>INDEX(Estadística!$T$6:$T$25,MATCH(B22,Estadística!$A$6:$A$25,0)),IF(OR(L22<INDEX(Estadística!$I$6:$I$25,MATCH(B22,Estadística!$A$6:$A$25,0))/2,L22>2*INDEX(Estadística!$I$6:$I$25,MATCH(B22,Estadística!$A$6:$A$25,0))),"Fuera de ½MA–2MA: revisar","Dentro de ½MA–2MA"),"—"),"")) -> — | S22: =IF(ISNUMBER(L22),IF(L22>0,LN(L22),""),"") -> -3.8632328 | T22: =IF(ISNUMBER(S22),IFERROR((S22-LN(INDEX(Estadística!$K$6:$K$25,MATCH(B22,Estadística!$A$6:$A$25,0))))^2,""),"") -> 0.0080439841 | U22: =IF(ISNUMBER(L22),IFERROR((L22-INDEX(Estadística!$I$6:$I$25,MATCH(B22,Estadística!$A$6:$A$25,0)))^2,""),"") -> 2.56e-06 | V22: =IF(ISNUMBER(P22),IF(P22>1,1,0),"") -> 0
A23: 18 | B23: G04 | C23: 46271 | D23: Picador 1 | E23: Personal | F23: 1.7 | G23: 480 | H23: =IF(OR(F23="",G23=""),"",F23*G23/1000) -> 0.816 | J23: 0.95 | K23: 4 | L23: =IF(B23="","",IF(J23<>"",J23,IF(AND(N(I23)>0,N(H23)>0),I23/H23,""))) -> 0.95 | M23: =IF(B23="","",IFERROR(INDEX(GES!$E$6:$E$25,MATCH(B23,GES!$A$6:$A$25,0)),"GES?")) -> CAR-B | N23: =IF(AND(ISNUMBER(L23),ISNUMBER(K23),LEFT(M23,3)="CAR"),L23*K23/100,"") -> 0.038 | O23: =IF(B23="","",IFERROR(INDEX(GES!$U$6:$U$25,MATCH(B23,GES!$A$6:$A$25,0)),"")) -> 0.703125 | P23: =IF(AND(ISNUMBER(L23),ISNUMBER(O23)),L23/O23,"") -> 1.3511111 | Q23: =IF(NOT(ISNUMBER(L23)),"",IFERROR(IF(INDEX(Estadística!$L$6:$L$25,MATCH(B23,Estadística!$A$6:$A$25,0))>INDEX(Estadística!$T$6:$T$25,MATCH(B23,Estadística!$A$6:$A$25,0)),IF(OR(L23<INDEX(Estadística!$I$6:$I$25,MATCH(B23,Estadística!$A$6:$A$25,0))/2,L23>2*INDEX(Estadística!$I$6:$I$25,MATCH(B23,Estadística!$A$6:$A$25,0))),"Fuera de ½MA–2MA: revisar","Dentro de ½MA–2MA"),"—"),"")) -> — | S23: =IF(ISNUMBER(L23),IF(L23>0,LN(L23),""),"") -> -0.051293294 | T23: =IF(ISNUMBER(S23),IFERROR((S23-LN(INDEX(Estadística!$K$6:$K$25,MATCH(B23,Estadística!$A$6:$A$25,0))))^2,""),"") -> 0.00081891703 | U23: =IF(ISNUMBER(L23),IFERROR((L23-INDEX(Estadística!$I$6:$I$25,MATCH(B23,Estadística!$A$6:$A$25,0)))^2,""),"") -> 0.0025 | V23: =IF(ISNUMBER(P23),IF(P23>1,1,0),"") -> 1
A24: 19 | B24: G04 | C24: 46272 | D24: Picador 2 | E24: Personal | F24: 1.7 | G24: 480 | H24: =IF(OR(F24="",G24=""),"",F24*G24/1000) -> 0.816 | J24: 1.2 | K24: 5 | L24: =IF(B24="","",IF(J24<>"",J24,IF(AND(N(I24)>0,N(H24)>0),I24/H24,""))) -> 1.2 | M24: =IF(B24="","",IFERROR(INDEX(GES!$E$6:$E$25,MATCH(B24,GES!$A$6:$A$25,0)),"GES?")) -> CAR-B | N24: =IF(AND(ISNUMBER(L24),ISNUMBER(K24),LEFT(M24,3)="CAR"),L24*K24/100,"") -> 0.06 | O24: =IF(B24="","",IFERROR(INDEX(GES!$U$6:$U$25,MATCH(B24,GES!$A$6:$A$25,0)),"")) -> 0.703125 | P24: =IF(AND(ISNUMBER(L24),ISNUMBER(O24)),L24/O24,"") -> 1.7066667 | Q24: =IF(NOT(ISNUMBER(L24)),"",IFERROR(IF(INDEX(Estadística!$L$6:$L$25,MATCH(B24,Estadística!$A$6:$A$25,0))>INDEX(Estadística!$T$6:$T$25,MATCH(B24,Estadística!$A$6:$A$25,0)),IF(OR(L24<INDEX(Estadística!$I$6:$I$25,MATCH(B24,Estadística!$A$6:$A$25,0))/2,L24>2*INDEX(Estadística!$I$6:$I$25,MATCH(B24,Estadística!$A$6:$A$25,0))),"Fuera de ½MA–2MA: revisar","Dentro de ½MA–2MA"),"—"),"")) -> — | S24: =IF(ISNUMBER(L24),IF(L24>0,LN(L24),""),"") -> 0.18232156 | T24: =IF(ISNUMBER(S24),IFERROR((S24-LN(INDEX(Estadística!$K$6:$K$25,MATCH(B24,Estadística!$A$6:$A$25,0))))^2,""),"") -> 0.042024231 | U24: =IF(ISNUMBER(L24),IFERROR((L24-INDEX(Estadística!$I$6:$I$25,MATCH(B24,Estadística!$A$6:$A$25,0)))^2,""),"") -> 0.04 | V24: =IF(ISNUMBER(P24),IF(P24>1,1,0),"") -> 1
A25: 20 | B25: G04 | C25: 46273 | D25: Picador 3 | E25: Personal | F25: 1.7 | G25: 480 | H25: =IF(OR(F25="",G25=""),"",F25*G25/1000) -> 0.816 | J25: 0.8 | K25: 3 | L25: =IF(B25="","",IF(J25<>"",J25,IF(AND(N(I25)>0,N(H25)>0),I25/H25,""))) -> 0.8 | M25: =IF(B25="","",IFERROR(INDEX(GES!$E$6:$E$25,MATCH(B25,GES!$A$6:$A$25,0)),"GES?")) -> CAR-B | N25: =IF(AND(ISNUMBER(L25),ISNUMBER(K25),LEFT(M25,3)="CAR"),L25*K25/100,"") -> 0.024 | O25: =IF(B25="","",IFERROR(INDEX(GES!$U$6:$U$25,MATCH(B25,GES!$A$6:$A$25,0)),"")) -> 0.703125 | P25: =IF(AND(ISNUMBER(L25),ISNUMBER(O25)),L25/O25,"") -> 1.1377778 | Q25: =IF(NOT(ISNUMBER(L25)),"",IFERROR(IF(INDEX(Estadística!$L$6:$L$25,MATCH(B25,Estadística!$A$6:$A$25,0))>INDEX(Estadística!$T$6:$T$25,MATCH(B25,Estadística!$A$6:$A$25,0)),IF(OR(L25<INDEX(Estadística!$I$6:$I$25,MATCH(B25,Estadística!$A$6:$A$25,0))/2,L25>2*INDEX(Estadística!$I$6:$I$25,MATCH(B25,Estadística!$A$6:$A$25,0))),"Fuera de ½MA–2MA: revisar","Dentro de ½MA–2MA"),"—"),"")) -> — | S25: =IF(ISNUMBER(L25),IF(L25>0,LN(L25),""),"") -> -0.22314355 | T25: =IF(ISNUMBER(S25),IFERROR((S25-LN(INDEX(Estadística!$K$6:$K$25,MATCH(B25,Estadística!$A$6:$A$25,0))))^2,""),"") -> 0.040187011 | U25: =IF(ISNUMBER(L25),IFERROR((L25-INDEX(Estadística!$I$6:$I$25,MATCH(B25,Estadística!$A$6:$A$25,0)))^2,""),"") -> 0.04 | V25: =IF(ISNUMBER(P25),IF(P25>1,1,0),"") -> 1
A26: 21 | B26: G04 | C26: 46274 | D26: Picador 4 | E26: Personal | F26: 1.7 | G26: 480 | H26: =IF(OR(F26="",G26=""),"",F26*G26/1000) -> 0.816 | J26: 1.1 | K26: 6 | L26: =IF(B26="","",IF(J26<>"",J26,IF(AND(N(I26)>0,N(H26)>0),I26/H26,""))) -> 1.1 | M26: =IF(B26="","",IFERROR(INDEX(GES!$E$6:$E$25,MATCH(B26,GES!$A$6:$A$25,0)),"GES?")) -> CAR-B | N26: =IF(AND(ISNUMBER(L26),ISNUMBER(K26),LEFT(M26,3)="CAR"),L26*K26/100,"") -> 0.066 | O26: =IF(B26="","",IFERROR(INDEX(GES!$U$6:$U$25,MATCH(B26,GES!$A$6:$A$25,0)),"")) -> 0.703125 | P26: =IF(AND(ISNUMBER(L26),ISNUMBER(O26)),L26/O26,"") -> 1.5644444 | Q26: =IF(NOT(ISNUMBER(L26)),"",IFERROR(IF(INDEX(Estadística!$L$6:$L$25,MATCH(B26,Estadística!$A$6:$A$25,0))>INDEX(Estadística!$T$6:$T$25,MATCH(B26,Estadística!$A$6:$A$25,0)),IF(OR(L26<INDEX(Estadística!$I$6:$I$25,MATCH(B26,Estadística!$A$6:$A$25,0))/2,L26>2*INDEX(Estadística!$I$6:$I$25,MATCH(B26,Estadística!$A$6:$A$25,0))),"Fuera de ½MA–2MA: revisar","Dentro de ½MA–2MA"),"—"),"")) -> — | S26: =IF(ISNUMBER(L26),IF(L26>0,LN(L26),""),"") -> 0.09531018 | T26: =IF(ISNUMBER(S26),IFERROR((S26-LN(INDEX(Estadística!$K$6:$K$25,MATCH(B26,Estadística!$A$6:$A$25,0))))^2,""),"") -> 0.013920873 | U26: =IF(ISNUMBER(L26),IFERROR((L26-INDEX(Estadística!$I$6:$I$25,MATCH(B26,Estadística!$A$6:$A$25,0)))^2,""),"") -> 0.01 | V26: =IF(ISNUMBER(P26),IF(P26>1,1,0),"") -> 1
A27: 22 | B27: G04 | C27: 46275 | D27: Picador 5 | E27: Personal | F27: 1.7 | G27: 480 | H27: =IF(OR(F27="",G27=""),"",F27*G27/1000) -> 0.816 | J27: 1.35 | K27: 4 | L27: =IF(B27="","",IF(J27<>"",J27,IF(AND(N(I27)>0,N(H27)>0),I27/H27,""))) -> 1.35 | M27: =IF(B27="","",IFERROR(INDEX(GES!$E$6:$E$25,MATCH(B27,GES!$A$6:$A$25,0)),"GES?")) -> CAR-B | N27: =IF(AND(ISNUMBER(L27),ISNUMBER(K27),LEFT(M27,3)="CAR"),L27*K27/100,"") -> 0.054 | O27: =IF(B27="","",IFERROR(INDEX(GES!$U$6:$U$25,MATCH(B27,GES!$A$6:$A$25,0)),"")) -> 0.703125 | P27: =IF(AND(ISNUMBER(L27),ISNUMBER(O27)),L27/O27,"") -> 1.92 | Q27: =IF(NOT(ISNUMBER(L27)),"",IFERROR(IF(INDEX(Estadística!$L$6:$L$25,MATCH(B27,Estadística!$A$6:$A$25,0))>INDEX(Estadística!$T$6:$T$25,MATCH(B27,Estadística!$A$6:$A$25,0)),IF(OR(L27<INDEX(Estadística!$I$6:$I$25,MATCH(B27,Estadística!$A$6:$A$25,0))/2,L27>2*INDEX(Estadística!$I$6:$I$25,MATCH(B27,Estadística!$A$6:$A$25,0))),"Fuera de ½MA–2MA: revisar","Dentro de ½MA–2MA"),"—"),"")) -> — | S27: =IF(ISNUMBER(L27),IF(L27>0,LN(L27),""),"") -> 0.30010459 | T27: =IF(ISNUMBER(S27),IFERROR((S27-LN(INDEX(Estadística!$K$6:$K$25,MATCH(B27,Estadística!$A$6:$A$25,0))))^2,""),"") -> 0.10418768 | U27: =IF(ISNUMBER(L27),IFERROR((L27-INDEX(Estadística!$I$6:$I$25,MATCH(B27,Estadística!$A$6:$A$25,0)))^2,""),"") -> 0.1225 | V27: =IF(ISNUMBER(P27),IF(P27>1,1,0),"") -> 1
A28: 23 | B28: G04 | C28: 46276 | D28: Picador 6 | E28: Personal | F28: 1.7 | G28: 480 | H28: =IF(OR(F28="",G28=""),"",F28*G28/1000) -> 0.816 | J28: 0.7 | K28: 5 | L28: =IF(B28="","",IF(J28<>"",J28,IF(AND(N(I28)>0,N(H28)>0),I28/H28,""))) -> 0.7 | M28: =IF(B28="","",IFERROR(INDEX(GES!$E$6:$E$25,MATCH(B28,GES!$A$6:$A$25,0)),"GES?")) -> CAR-B | N28: =IF(AND(ISNUMBER(L28),ISNUMBER(K28),LEFT(M28,3)="CAR"),L28*K28/100,"") -> 0.035 | O28: =IF(B28="","",IFERROR(INDEX(GES!$U$6:$U$25,MATCH(B28,GES!$A$6:$A$25,0)),"")) -> 0.703125 | P28: =IF(AND(ISNUMBER(L28),ISNUMBER(O28)),L28/O28,"") -> 0.99555556 | Q28: =IF(NOT(ISNUMBER(L28)),"",IFERROR(IF(INDEX(Estadística!$L$6:$L$25,MATCH(B28,Estadística!$A$6:$A$25,0))>INDEX(Estadística!$T$6:$T$25,MATCH(B28,Estadística!$A$6:$A$25,0)),IF(OR(L28<INDEX(Estadística!$I$6:$I$25,MATCH(B28,Estadística!$A$6:$A$25,0))/2,L28>2*INDEX(Estadística!$I$6:$I$25,MATCH(B28,Estadística!$A$6:$A$25,0))),"Fuera de ½MA–2MA: revisar","Dentro de ½MA–2MA"),"—"),"")) -> — | S28: =IF(ISNUMBER(L28),IF(L28>0,LN(L28),""),"") -> -0.35667494 | T28: =IF(ISNUMBER(S28),IFERROR((S28-LN(INDEX(Estadística!$K$6:$K$25,MATCH(B28,Estadística!$A$6:$A$25,0))))^2,""),"") -> 0.11155492 | U28: =IF(ISNUMBER(L28),IFERROR((L28-INDEX(Estadística!$I$6:$I$25,MATCH(B28,Estadística!$A$6:$A$25,0)))^2,""),"") -> 0.09 | V28: =IF(ISNUMBER(P28),IF(P28>1,1,0),"") -> 0
A29: 24 | B29: G04 | C29: 46277 | D29: Picador 7 | E29: Personal | F29: 1.7 | G29: 480 | H29: =IF(OR(F29="",G29=""),"",F29*G29/1000) -> 0.816 | J29: 0.9 | K29: 4 | L29: =IF(B29="","",IF(J29<>"",J29,IF(AND(N(I29)>0,N(H29)>0),I29/H29,""))) -> 0.9 | M29: =IF(B29="","",IFERROR(INDEX(GES!$E$6:$E$25,MATCH(B29,GES!$A$6:$A$25,0)),"GES?")) -> CAR-B | N29: =IF(AND(ISNUMBER(L29),ISNUMBER(K29),LEFT(M29,3)="CAR"),L29*K29/100,"") -> 0.036 | O29: =IF(B29="","",IFERROR(INDEX(GES!$U$6:$U$25,MATCH(B29,GES!$A$6:$A$25,0)),"")) -> 0.703125 | P29: =IF(AND(ISNUMBER(L29),ISNUMBER(O29)),L29/O29,"") -> 1.28 | Q29: =IF(NOT(ISNUMBER(L29)),"",IFERROR(IF(INDEX(Estadística!$L$6:$L$25,MATCH(B29,Estadística!$A$6:$A$25,0))>INDEX(Estadística!$T$6:$T$25,MATCH(B29,Estadística!$A$6:$A$25,0)),IF(OR(L29<INDEX(Estadística!$I$6:$I$25,MATCH(B29,Estadística!$A$6:$A$25,0))/2,L29>2*INDEX(Estadística!$I$6:$I$25,MATCH(B29,Estadística!$A$6:$A$25,0))),"Fuera de ½MA–2MA: revisar","Dentro de ½MA–2MA"),"—"),"")) -> — | S29: =IF(ISNUMBER(L29),IF(L29>0,LN(L29),""),"") -> -0.10536052 | T29: =IF(ISNUMBER(S29),IFERROR((S29-LN(INDEX(Estadística!$K$6:$K$25,MATCH(B29,Estadística!$A$6:$A$25,0))))^2,""),"") -> 0.0068366352 | U29: =IF(ISNUMBER(L29),IFERROR((L29-INDEX(Estadística!$I$6:$I$25,MATCH(B29,Estadística!$A$6:$A$25,0)))^2,""),"") -> 0.01 | V29: =IF(ISNUMBER(P29),IF(P29>1,1,0),"") -> 1
A30: 25 | B30: G05 | C30: 46266 | D30: Operador cargue 1 | E30: Personal | F30: 1.7 | G30: 480 | H30: =IF(OR(F30="",G30=""),"",F30*G30/1000) -> 0.816 | J30: 0.25 | K30: 2 | L30: =IF(B30="","",IF(J30<>"",J30,IF(AND(N(I30)>0,N(H30)>0),I30/H30,""))) -> 0.25 | M30: =IF(B30="","",IFERROR(INDEX(GES!$E$6:$E$25,MATCH(B30,GES!$A$6:$A$25,0)),"GES?")) -> CAR-B | N30: =IF(AND(ISNUMBER(L30),ISNUMBER(K30),LEFT(M30,3)="CAR"),L30*K30/100,"") -> 0.005 | O30: =IF(B30="","",IFERROR(INDEX(GES!$U$6:$U$25,MATCH(B30,GES!$A$6:$A$25,0)),"")) -> 0.703125 | P30: =IF(AND(ISNUMBER(L30),ISNUMBER(O30)),L30/O30,"") -> 0.35555556 | Q30: =IF(NOT(ISNUMBER(L30)),"",IFERROR(IF(INDEX(Estadística!$L$6:$L$25,MATCH(B30,Estadística!$A$6:$A$25,0))>INDEX(Estadística!$T$6:$T$25,MATCH(B30,Estadística!$A$6:$A$25,0)),IF(OR(L30<INDEX(Estadística!$I$6:$I$25,MATCH(B30,Estadística!$A$6:$A$25,0))/2,L30>2*INDEX(Estadística!$I$6:$I$25,MATCH(B30,Estadística!$A$6:$A$25,0))),"Fuera de ½MA–2MA: revisar","Dentro de ½MA–2MA"),"—"),"")) -> — | S30: =IF(ISNUMBER(L30),IF(L30>0,LN(L30),""),"") -> -1.3862944 | T30: =IF(ISNUMBER(S30),IFERROR((S30-LN(INDEX(Estadística!$K$6:$K$25,MATCH(B30,Estadística!$A$6:$A$25,0))))^2,""),"") -> 0.0008583439 | U30: =IF(ISNUMBER(L30),IFERROR((L30-INDEX(Estadística!$I$6:$I$25,MATCH(B30,Estadística!$A$6:$A$25,0)))^2,""),"") -> 0.00017777778 | V30: =IF(ISNUMBER(P30),IF(P30>1,1,0),"") -> 0
