Workbook

Sheet Portada

Sheet Tabla NIOSH VP-SG
A1: TABLA DE CONSULTA NIOSH - PRESIÓN DE VAPOR (SUSTANCIAS LÍQUIDAS, 20°C)
A2: Fuente: NIOSH Pocket Guide to Chemical Hazards (cdc.gov/niosh/npg). Presión de vapor (VP) reportada por NIOSH a 68°F (20°C). Solo se incluyen sustancias que el NIOSH Pocket Guide describe como líquidas a condiciones normales (se excluyen gases y sólidos). Para sustancias o temperaturas distintas de 20°C, consultar: https://webbook.nist.gov/chemistry/
A4: Sustancia | B4: CAS | C4: Presión de Vapor (mmHg, 20°C)
A5: Ácido acético | B5: 64-19-7 | C5: 11
A6: Acetona | B6: 67-64-1 | C6: 180
A7: Anilina | B7: 62-53-3 | C7: 0.6
A8: Benceno | B8: 71-43-2 | C8: 75
A9: Tetracloruro de carbono | B9: 56-23-5 | C9: 91
A10: Cloroformo | B10: 67-66-3 | C10: 160
A11: Ciclohexano | B11: 110-82-7 | C11: 78
A12: Alcohol etílico | B12: 64-17-5 | C12: 44
A13: Cloruro de metileno (diclorometano) | B13: 75-09-2 | C13: 350
A14: Acetato de propilo | B14: 109-60-4 | C14: 25
A15: Tolueno | B15: 108-88-3 | C15: 21
A16: n-Hexano | B16: 110-54-3 | C16: 124
... A122: Dietanolamina | B122: 111-42-2 | C122: 0.58

Sheet Calculadora Antoine
A1: CALCULADORA DE PRESIÓN DE VAPOR (ECUACIÓN DE ANTOINE)
A2: Calcula la presión de vapor (mmHg) de una sustancia pura a la temperatura que el usuario ingrese, mediante la ecuación de Antoine: log10(VP) = A − B / (T + C), con T en °C. Constantes A, B, C válidas para el rango de temperatura habitual de trabajo en higiene industrial. Modifique la columna 'Temperatura (°C)' (celdas rosadas) para recalcular. Para sustancias no incluidas aquí, consulte la hoja 'Tabla NIOSH VP-SG' (valor fijo a 20°C) o https://webbook.nist.gov/chemistry/ (sección 'Antoine Equation Parameters' o 'Fluid Properties').
A4: Sustancia | B4: CAS | C4: A | D4: B | E4: C | F4: Temperatura (°C) | G4: Presión de Vapor (mmHg)
A5: Ácido acético | B5: 64-19-7 | C5: 7.8 | D5: 1651.2 | E5: 225 | F5: 20 | G5: =10^(C5-(D5/(F5+E5))) -> 11.492332
A6: Acetona | B6: 67-64-1 | C6: 7.12 | D6: 1210.6 | E6: 229.66 | F6: 20 | G6: =10^(C6-(D6/(F6+E6))) -> 186.64028
A7: Anilina | B7: 62-53-3 | C7: 7.24 | D7: 1675.3 | E7: 200 | F7: 20 | G7: =10^(C7-(D7/(F7+E7))) -> 0.4216965
A8: Benceno | B8: 71-43-2 | C8: 6.90565 | D8: 1211.033 | E8: 220.79 | F8: 20 | G8: =10^(C8-(D8/(F8+E8))) -> 75.202855
A9: Alcohol bencílico | B9: 100-51-6 | C9: 7.82 | D9: 1950.3 | E9: 194.36 | F9: 20 | G9: =10^(C9-(D9/(F9+E9))) -> 0.052693138
A10: Bifenilo | B10: 92-52-4 | C10: 7.25 | D10: 1998.73 | E10: 202.73 | F10: 20 | G10: =10^(C10-(D10/(F10+E10))) -> 0.018889484
A11: Cloruro de n-butilo | B11: 109-69-3 | C11: 6.84 | D11: 1173.79 | E11: 218.13 | F11: 20 | G11: =10^(C11-(D11/(F11+E11))) -> 81.43323
A12: Mercaptano de terc-butilo | B12: 75-66-1 | C12: 6.79 | D12: 1115.57 | E12: 211.31 | F12: 20 | G12: =10^(C12-(D12/(F12+E12))) -> 92.718168
A13: Tetracloruro de carbono | B13: 56-23-5 | C13: 6.93 | D13: 1242.43 | E13: 230 | F13: 20 | G13: =10^(C13-(D13/(F13+E13))) -> 91.259902
A14: Cloroformo | B14: 67-66-3 | C14: 6.9 | D14: 1163.03 | E14: 227.4 | F14: 20 | G14: =10^(C14-(D14/(F14+E14))) -> 158.12098
A15: Ciclohexano | B15: 110-82-7 | C15: 6.84 | D15: 1203.53 | E15: 222.86 | F15: 20 | G15: =10^(C15-(D15/(F15+E15))) -> 76.620774
A16: o-Diclorobenceno | B16: 95-50-1 | C16: 6.92 | D16: 1538.3 | E16: 200 | F16: 20 | G16: =10^(C16-(D16/(F16+E16))) -> 0.84669554
... A38: Agua | B38: 7732-18-5 | C38: 8.037104 | D38: 1705.854 | E38: 230.911 | F38: 20 | G38: =10^(C38-(D38/(F38+E38))) -> 17.316585

Sheet VaporRisk
A1: LIQUIDOS | S1: SOLIDOS | V1: CONTROL PROPUESTO | W1: FASE 2: VENTILACIÓN GENERAL (ACH) | AD1: DILUCIÓN QUÍMICA (CONSUMO G) | AI1: EXTRACCIÓN LOCALIZADA (LEV)
A2: CAS | B2: Sustancia | C2: % Peso Ficha de Datos de Seguridad | D2: TLV-TWA | E2: Peso Molecular | F2: Presion de Vapor (mmHg) | G2: Moles | H2: Fraccion Molar | I2: Presion de Vapor Ajustada | J2: Razon de Riesgo de Vapor Ajustado | K2: Ratio de Riesgo (%) | M2: Sustancia | N2: CAS | O2: TLV-TWA | P2: PM | Q2: CAS | R2: PV | S2: TLV-TWA | T2: Concentracion Medida | U2: Indice de Exposicion | W2: Ancho (m) | X2: Largo (m) | Y2: Alto (m) | Z2: Volumen (m³) | AA2: ACH Requerido | AB2: Caudal (m³/h) | AC2: Caudal (CFM) | AD2: Consumo G (L/h) | AE2: Densidad Sustancia (kg/L) | AF2: Factor K | AG2: Q Dilución (m³/h) | AH2: Q Dilución (CFM) | AI2: Tipo de Campana | AJ2: Distancia x (m) | AK2: Área Campana A (m²) | AL2: Velocidad Captura Recomendada (ACGIH) Vc (m/s) | AM2: Q Captura (m³/h) | AN2: Q Captura (CFM) | AO2: Velocidad Ducto Vd (m/s) | AP2: Diámetro Ducto (pulg)
M3: Acetaldehído | N3: 75-07-0 | Q3: 71-43-2 | R3: 119.25 | AM3: Q Captura (m³/h) | AN3: Q Captura (CFM) | AP3: Diámetro Ducto (pulg)
M4: Acetamida | N4: 60-35-5 | Q4: 108-88-3 | R4: 36.66 | AM4: Q Captura (m³/h) | AN4: Q Captura (CFM) | AP4: Diámetro Ducto (pulg)
M5: Acetamiprida | N5: 135410-20-7 | O5: 0.05 | AM5: Q Captura (m³/h) | AN5: Q Captura (CFM) | AP5: Diámetro Ducto (pulg)
M6: Ácido acético | N6: 64-19-7 | O6: 10 | AM6: Q Captura (m³/h) | AN6: Q Captura (CFM) | AP6: Diámetro Ducto (pulg)
A7: 111-11-1 | B7: Solvente A | C7: 32.5 | D7: 100 | E7: 72.15 | F7: 145.8 | G7: =IF(A7="", "", IF(E7="", "", C7/E7)) -> 0.45045045 | H7: =IF(G7="", "", G7/SUM(G$7:G$14)) -> 0.40419864 | I7: =IF(H7="", "", H7*F7) -> 58.932162 | J7: =IF(OR(I7="",D7=""), "", (I7*1000000)/(760*D7)) -> 775.42318 | K7: =IF(J7="", "", J7/SUM(J$7:J$14)) -> 0.52833594 | L7: =IF(OR(I7="",D7=""), "", I7/D7) -> 0.58932162 | M7: Anhídrido acético | N7: 108-24-7 | O7: 1 | P7: 78.11 | U7: =IF(AND(S7<>"", T7<>""), T7/S7, "") | V7: =IF(A7="", "", IF(U7<>"", IF(U7<=0.5, "Banda 1: Ventilación General", IF(U7<=1, "Banda 2: Extracción Local (LEV)", "Banda 3: Aislamiento / HEPA")), IF(J7<>"", IF(J7<=100, "Banda 1: Dilución (ACH)", IF(J7<=10000, "Banda 2: Extracción Local (LEV)", "Banda 3: Encerramiento")), ""))) -> Banda 2: Extracción Local (LEV) | W7: 10 | X7: 8 | Y7: 3 | Z7: =IF(OR(W7="", X7="", Y7=""), "", W7*X7*Y7) -> 240 | AA7: 6 | AB7: =IF(OR(Z7="", AA7=""), "", Z7*AA7) -> 1440 | AC7: =IF(AB7="", "", AB7*0.5886) -> 847.584 | AD7: =AD$18 * (C7 / 100) -> 0.845 | AE7: =AE$18 -> 0.85 | AF7: =AF$18 -> 5 | AG7: =IF(OR(AD7="", D7="", E7=""), "", (24450000 * AD7 * IF(AE7="", 1, AE7) * IF(AF7="", 5, AF7)) / (E7 * D7)) -> 12169.932 | AH7: =IF(AG7="", "", AG7 * 0.5886) -> 7163.2222 | AI7: Campana con Pestaña | AJ7: 0.2 | AK7: 1.2 | AL7: 0.5 | AM7: =IF(OR(AJ7="", AK7="", AL7=""), "", IF(AI7="Campana Simple", AL7 * (10 * (AJ7^2) + AK7) * 3600, IF(AI7="Campana con Pestaña", 0.75 * AL7 * (10 * (AJ7^2) + AK7) * 3600, IF(AI7="Cabina", AL7 * AK7 * 3600, IF(AI7="Campana Elevada", 1.4 * (4 * SQRT(AK7)) * AL7 * AJ7 * 3600, AL7 * (10 * (AJ7^2) + AK7) * 3600))))) -> 2160 | AN7: =IF(AM7="", "", AM7 * 0.5886) -> 1271.376 | AO7: 10 | AP7: =IF(OR(AM7="", AO7=""), "", SQRT((4 * (AM7 / 3600)) / (PI() * AO7)) * 39.3701) -> 10.881711
A8: 222-22-2 | B8: Solvente B | C8: 21 | D8: 50 | E8: 88.43 | F8: 62.4 | G8: =IF(A8="", "", IF(E8="", "", C8/E8)) -> 0.23747597 | H8: =IF(G8="", "", G8/SUM(G$7:G$14)) -> 0.21309217 | I8: =IF(H8="", "", H8*F8) -> 13.296951 | J8: =IF(OR(I8="",D8=""), "", (I8*1000000)/(760*D8)) -> 349.91977 | K8: =IF(J8="", "", J8/SUM(J$7:J$14)) -> 0.23841845 | L8: =IF(OR(I8="",D8=""), "", I8/D8) -> 0.26593903 | M8: Anhídrido acético | N8: 108-24-8 | O8: 1 | P8: 78.11 | U8: =IF(AND(S8<>"", T8<>""), T8/S8, "") | V8: =IF(A8="", "", IF(U8<>"", IF(U8<=0.5, "Banda 1: Ventilación General", IF(U8<=1, "Banda 2: Extracción Local (LEV)", "Banda 3: Aislamiento / HEPA")), IF(J8<>"", IF(J8<=100, "Banda 1: Dilución (ACH)", IF(J8<=10000, "Banda 2: Extracción Local (LEV)", "Banda 3: Encerramiento")), ""))) -> Banda 2: Extracción Local (LEV) | AB8: =IF(OR(Z8="", AA8=""), "", Z8*AA8) | AC8: =IF(AB8="", "", AB8*0.5886) | AD8: =AD$18 * (C8 / 100) -> 0.546 | AE8: =AE$18 -> 0.85 | AF8: =AF$18 -> 5 | AG8: =IF(OR(AD8="", D8="", E8=""), "", (24450000 * AD8 * IF(AE8="", 1, AE8) * IF(AF8="", 5, AF8)) / (E8 * D8)) -> 12831.895 | AH8: =IF(AG8="", "", AG8 * 0.5886) -> 7552.8536
A9: 333-33-3 | B9: Solvente C | C9: 15.8 | D9: 25 | E9: 104.2 | F9: 18.7 | G9: =IF(A9="", "", IF(E9="", "", C9/E9)) -> 0.15163148 | H9: =IF(G9="", "", G9/SUM(G$7:G$14)) -> 0.13606211 | I9: =IF(H9="", "", H9*F9) -> 2.5443614 | J9: =IF(OR(I9="",D9=""), "", (I9*1000000)/(760*D9)) -> 133.91376 | K9: =IF(J9="", "", J9/SUM(J$7:J$14)) -> 0.091242372 | L9: =IF(OR(I9="",D9=""), "", I9/D9) -> 0.10177446 | M9: Anhídrido acético | N9: 108-24-9 | O9: 1 | P9: 78.11 | U9: =IF(AND(S9<>"", T9<>""), T9/S9, "") | V9: =IF(A9="", "", IF(U9<>"", IF(U9<=0.5, "Banda 1: Ventilación General", IF(U9<=1, "Banda 2: Extracción Local (LEV)", "Banda 3: Aislamiento / HEPA")), IF(J9<>"", IF(J9<=100, "Banda 1: Dilución (ACH)", IF(J9<=10000, "Banda 2: Extracción Local (LEV)", "Banda 3: Encerramiento")), ""))) -> Banda 2: Extracción Local (LEV) | AB9: =IF(OR(Z9="", AA9=""), "", Z9*AA9) | AC9: =IF(AB9="", "", AB9*0.5886) | AD9: =AD$18 * (C9 / 100) -> 0.4108 | AE9: =AE$18 -> 0.85 | AF9: =AF$18 -> 5 | AG9: =IF(OR(AD9="", D9="", E9=""), "", (24450000 * AD9 * IF(AE9="", 1, AE9) * IF(AF9="", 5, AF9)) / (E9 * D9)) -> 16386.662 | AH9: =IF(AG9="", "", AG9 * 0.5886) -> 9645.1894
A10: 444-44-4 | B10: Resina X | C10: 12 | D10: 10 | E10: 156.3 | F10: 2.1 | G10: =IF(A10="", "", IF(E10="", "", C10/E10)) -> 0.076775432 | H10: =IF(G10="", "", G10/SUM(G$7:G$14)) -> 0.068892206 | I10: =IF(H10="", "", H10*F10) -> 0.14467363 | J10: =IF(OR(I10="",D10=""), "", (I10*1000000)/(760*D10)) -> 19.036004 | K10: =IF(J10="", "", J10/SUM(J$7:J$14)) -> 0.012970215 | L10: =IF(OR(I10="",D10=""), "", I10/D10) -> 0.014467363 | M10: Anhídrido acético | N10: 108-24-10 | O10: 1 | P10: 78.11 | U10: =IF(AND(S10<>"", T10<>""), T10/S10, "") | V10: =IF(A10="", "", IF(U10<>"", IF(U10<=0.5, "Banda 1: Ventilación General", IF(U10<=1, "Banda 2: Extracción Local (LEV)", "Banda 3: Aislamiento / HEPA")), IF(J10<>"", IF(J10<=100, "Banda 1: Dilución (ACH)", IF(J10<=10000, "Banda 2: Extracción Local (LEV)", "Banda 3: Encerramiento")), ""))) -> Banda 1: Dilución (ACH) | AB10: =IF(OR(Z10="", AA10=""), "", Z10*AA10) | AC10: =IF(AB10="", "", AB10*0.5886) | AD10: =AD$18 * (C10 / 100) -> 0.312 | AE10: =AE$18 -> 0.85 | AF10: =AF$18 -> 5 | AG10: =IF(OR(AD10="", D10="", E10=""), "", (24450000 * AD10 * IF(AE10="", 1, AE10) * IF(AF10="", 5, AF10)) / (E10 * D10)) -> 20742.61 | AH10: =IF(AG10="", "", AG10 * 0.5886) -> 12209.1
A11: 555-55-5 | B11: Aditivo Y | C11: 8.7 | D11: 75 | E11: 94.85 | F11: 35.6 | G11: =IF(A11="", "", IF(E11="", "", C11/E11)) -> 0.091723774 | H11: =IF(G11="", "", G11/SUM(G$7:G$14)) -> 0.082305667 | I11: =IF(H11="", "", H11*F11) -> 2.9300818 | J11: =IF(OR(I11="",D11=""), "", (I11*1000000)/(760*D11)) -> 51.404943 | K11: =IF(J11="", "", J11/SUM(J$7:J$14)) -> 0.035024848 | L11: =IF(OR(I11="",D11=""), "", I11/D11) -> 0.039067757 | M11: Anhídrido acético | N11: 108-24-11 | O11: 1 | P11: 78.11 | U11: =IF(AND(S11<>"", T11<>""), T11/S11, "") | V11: =IF(A11="", "", IF(U11<>"", IF(U11<=0.5, "Banda 1: Ventilación General", IF(U11<=1, "Banda 2: Extracción Local (LEV)", "Banda 3: Aislamiento / HEPA")), IF(J11<>"", IF(J11<=100, "Banda 1: Dilución (ACH)", IF(J11<=10000, "Banda 2: Extracción Local (LEV)", "Banda 3: Encerramiento")), ""))) -> Banda 1: Dilución (ACH) | AB11: =IF(OR(Z11="", AA11=""), "", Z11*AA11) | AC11: =IF(AB11="", "", AB11*0.5886) | AD11: =AD$18 * (C11 / 100) -> 0.2262 | AE11: =AE$18 -> 0.85 | AF11: =AF$18 -> 5 | AG11: =IF(OR(AD11="", D11="", E11=""), "", (24450000 * AD11 * IF(AE11="", 1, AE11) * IF(AF11="", 5, AF11)) / (E11 * D11)) -> 3304.1655 | AH11: =IF(AG11="", "", AG11 * 0.5886) -> 1944.8318
A12: 666-66-6 | B12: Estabilizante Z | C12: 5 | D12: 150 | E12: 67.22 | F12: 210.3 | G12: =IF(A12="", "", IF(E12="", "", C12/E12)) -> 0.074382624 | H12: =IF(G12="", "", G12/SUM(G$7:G$14)) -> 0.066745089 | I12: =IF(H12="", "", H12*F12) -> 14.036492 | J12: =IF(OR(I12="",D12=""), "", (I12*1000000)/(760*D12)) -> 123.12713 | K12: =IF(J12="", "", J12/SUM(J$7:J$14)) -> 0.083892881 | L12: =IF(OR(I12="",D12=""), "", I12/D12) -> 0.093576615 | M12: Anhídrido acético | N12: 108-24-12 | O12: 1 | P12: 78.11 | U12: =IF(AND(S12<>"", T12<>""), T12/S12, "") | V12: =IF(A12="", "", IF(U12<>"", IF(U12<=0.5, "Banda 1: Ventilación General", IF(U12<=1, "Banda 2: Extracción Local (LEV)", "Banda 3: Aislamiento / HEPA")), IF(J12<>"", IF(J12<=100, "Banda 1: Dilución (ACH)", IF(J12<=10000, "Banda 2: Extracción Local (LEV)", "Banda 3: Encerramiento")), ""))) -> Banda 2: Extracción Local (LEV) | AB12: =IF(OR(Z12="", AA12=""), "", Z12*AA12) | AC12: =IF(AB12="", "", AB12*0.5886) | AD12: =AD$18 * (C12 / 100) -> 0.13 | AE12: =AE$18 -> 0.85 | AF12: =AF$18 -> 5 | AG12: =IF(OR(AD12="", D12="", E12=""), "", (24450000 * AD12 * IF(AE12="", 1, AE12) * IF(AF12="", 5, AF12)) / (E12 * D12)) -> 1339.7426 | AH12: =IF(AG12="", "", AG12 * 0.5886) -> 788.57252
A13: 777-77-7 | B13: Catalizador K | C13: 3 | D13: 5 | E13: 180.55 | F13: 0.8 | G13: =IF(A13="", "", IF(E13="", "", C13/E13)) -> 0.016615896 | H13: =IF(G13="", "", G13/SUM(G$7:G$14)) -> 0.014909792 | I13: =IF(H13="", "", H13*F13) -> 0.011927834 | J13: =IF(OR(I13="",D13=""), "", (I13*1000000)/(760*D13)) -> 3.1389036 | K13: =IF(J13="", "", J13/SUM(J$7:J$14)) -> 0.0021386974 | L13: =IF(OR(I13="",D13=""), "", I13/D13) -> 0.0023855667 | M13: Anhídrido acético | N13: 108-24-13 | O13: 1 | P13: 78.11 | U13: =IF(AND(S13<>"", T13<>""), T13/S13, "") | V13: =IF(A13="", "", IF(U13<>"", IF(U13<=0.5, "Banda 1: Ventilación General", IF(U13<=1, "Banda 2: Extracción Local (LEV)", "Banda 3: Aislamiento / HEPA")), IF(J13<>"", IF(J13<=100, "Banda 1: Dilución (ACH)", IF(J13<=10000, "Banda 2: Extracción Local (LEV)", "Banda 3: Encerramiento")), ""))) -> Banda 1: Dilución (ACH) | AB13: =IF(OR(Z13="", AA13=""), "", Z13*AA13) | AC13: =IF(AB13="", "", AB13*0.5886) | AD13: =AD$18 * (C13 / 100) -> 0.078 | AE13: =AE$18 -> 0.85 | AF13: =AF$18 -> 5 | AG13: =IF(OR(AD13="", D13="", E13=""), "", (24450000 * AD13 * IF(AE13="", 1, AE13) * IF(AF13="", 5, AF13)) / (E13 * D13)) -> 8978.3163 | AH13: =IF(AG13="", "", AG13 * 0.5886) -> 5284.6369
A14: 888-88-8 | B14: Impureza M | C14: 2 | D14: 20 | E14: 130.1 | F14: 12.9 | G14: =IF(A14="", "", IF(E14="", "", C14/E14)) -> 0.01537279 | H14: =IF(G14="", "", G14/SUM(G$7:G$14)) -> 0.013794327 | I14: =IF(H14="", "", H14*F14) -> 0.17794682 | J14: =IF(OR(I14="",D14=""), "", (I14*1000000)/(760*D14)) -> 11.707028 | K14: =IF(J14="", "", J14/SUM(J$7:J$14)) -> 0.0079766037 | L14: =IF(OR(I14="",D14=""), "", I14/D14) -> 0.008897341 | M14: Anhídrido acético | N14: 108-24-14 | O14: 1 | P14: 78.11 | U14: =IF(AND(S14<>"", T14<>""), T14/S14, "") | V14: =IF(A14="", "", IF(U14<>"", IF(U14<=0.5, "Banda 1: Ventilación General", IF(U14<=1, "Banda 2: Extracción Local (LEV)", "Banda 3: Aislamiento / HEPA")), IF(J14<>"", IF(J14<=100, "Banda 1: Dilución (ACH)", IF(J14<=10000, "Banda 2: Extracción Local (LEV)", "Banda 3: Encerramiento")), ""))) -> Banda 1: Dilución (ACH) | AB14: =IF(OR(Z14="", AA14=""), "", Z14*AA14) | AC14: =IF(AB14="", "", AB14*0.5886) | AD14: =AD$18 * (C14 / 100) -> 0.052 | AE14: =AE$18 -> 0.85 | AF14: =AF$18 -> 5 | AG14: =IF(OR(AD14="", D14="", E14=""), "", (24450000 * AD14 * IF(AE14="", 1, AE14) * IF(AF14="", 5, AF14)) / (E14 * D14)) -> 2076.6526 | AH14: =IF(AG14="", "", AG14 * 0.5886) -> 1222.3177
M15: Acroleína | N15: 0107-02-08 | AG15: =SUM(AG7:AG14) -> 77829.977 | AH15: =IF(AG15="", "", AG15 * 0.5886) -> 45810.725
M16: Acrilamida | N16: 79-06-1 | O16: 0.03
M17: Ácido acrílico | N17: 79-10-7 | O17: 2 | AD17: Consumo Total Mezcla (L/h) | AE17: Densidad Mezcla (kg/L) | AF17: Factor K Global
M18: Acrilonitrilo | N18: 107-13-1 | O18: 2 | AD18: 2.6 | AE18: 0.85 | AF18: 5
M19: Ácido adípico | N19: 0124-04-09 | O19: 5
M20: Adiponitrilo | N20: 111-69-3 | O20: 2
M21: Alacloro | N21: 15972-60-8 | O21: 1
M22: Aldicarb | N22: 0116-06-03 | O22: 0.005
M23: Aldrín | N23: 309-00-2 | O23: 0.05
M24: alcohol alílico | N24: 107-18-6 | O24: 0.5
M25: bromuro de alilo | N25: 106-95-6 | O25: 0.1
M26: cloruro de alilo | N26: 0107-05-01 | O26: 1
M27: Éter alílico glicidílico | N27: 106-92-3 | O27: 1
M28: metacrilato de alilo | N28: 96-05-9 | O28: 1
M29: disulfuro de alilpropilo | N29: 2179-59-1 | O29: 0.5
M30: Metal de aluminio | N30: 7429-90-5 | O30: 1
M31: 4-aminodifenilo | N31: 92-67-1
M32: 2-aminopiridina | N32: 504-29-0 | O32: 0.5
M33: Amitrol | N33: 61-82-5 | O33: 0.2
M34: Amoníaco | N34: 7664-41-7 | O34: 25
M35: Cloruro de amonio, humo | N35: 1212-02-09 | O35: 10
M36: Perfluorooctanoato de amonio | N36: 3825-26-1 | O36: 0.01
M37: sulfamato de amonio | N37: 7773-06-0 | O37: 10
M38: éter metílico de terc-amilo | N38: 0994-05-08 | O38: 20
M39: Anilina | N39: 62-53-3 | O39: 2
M40: Isómero orto de anisidina (2002) | N40: 90-04-0 | O40: 0.5
...

Sheet Monitoreo y Mezcla
A1: MONITOREO AMBIENTAL Y REGLA DE MEZCLAS (ACGIH)
A2: CAS | B2: Sustancia | C2: TLV-TWA (ppm) | D2: Concentración Medida (ppm) | E2: Índice Individual (C/TLV) | F2: % Aporte al Índice
A3: 111-11-1 | B3: Solvente A | C3: 100 | D3: 1200 | E3: =IF(OR(C3="",D3=""), "", D3/C3) -> 12 | F3: =IF(E3="", "", E3/SUM(E$3:E$10)) -> 0.70588235
A4: 222-22-2 | B4: Solvente B | C4: 50 | D4: 85 | E4: =IF(OR(C4="",D4=""), "", D4/C4) -> 1.7 | F4: =IF(E4="", "", E4/SUM(E$3:E$10)) -> 0.1
A5: 333-33-3 | B5: Solvente C | C5: 25 | D5: 30 | E5: =IF(OR(C5="",D5=""), "", D5/C5) -> 1.2 | F5: =IF(E5="", "", E5/SUM(E$3:E$10)) -> 0.070588235
A6: 444-44-4 | B6: Resina X | C6: 10 | D6: 6 | E6: =IF(OR(C6="",D6=""), "", D6/C6) -> 0.6 | F6: =IF(E6="", "", E6/SUM(E$3:E$10)) -> 0.035294118
A7: 555-55-5 | B7: Aditivo Y | C7: 75 | D7: 40 | E7: =IF(OR(C7="",D7=""), "", D7/C7) -> 0.53333333 | F7: =IF(E7="", "", E7/SUM(E$3:E$10)) -> 0.031372549
A8: 666-66-6 | B8: Estabilizante Z | C8: 150 | D8: 70 | E8: =IF(OR(C8="",D8=""), "", D8/C8) -> 0.46666667 | F8: =IF(E8="", "", E8/SUM(E$3:E$10)) -> 0.02745098
A9: 777-77-7 | B9: Catalizador K | C9: 5 | D9: 1.5 | E9: =IF(OR(C9="",D9=""), "", D9/C9) -> 0.3 | F9: =IF(E9="", "", E9/SUM(E$3:E$10)) -> 0.017647059
A10: 888-88-8 | B10: Impureza M | C10: 20 | D10: 4 | E10: =IF(OR(C10="",D10=""), "", D10/C10) -> 0.2 | F10: =IF(E10="", "", E10/SUM(E$3:E$10)) -> 0.011764706
B12: ÍNDICE DE MEZCLA TOTAL (Σ Ci/TLVi) | E12: =SUM(E3:E10) -> 17
B13: % del Criterio ACGIH (Índice = 100%) | E13: =E12*100 -> 1700
B14: Clasificación de Severidad | E14: =IF(E12="", "", IF(E12<0.5,"ACEPTABLE",IF(E12<1,"PRECAUCIÓN",IF(E12<2,"MODERADO",IF(E12<4,"ALTO","EXTREMADAMENTE ALTO"))))) -> EXTREMADAMENTE ALTO
B15: Cumplimiento (criterio ACGIH: índice ≤ 1) | E15: =IF(E12="", "", IF(E12<=1, "CUMPLE CRITERIO", "EXCEDE CRITERIO")) -> EXCEDE CRITERIO
A18: Nivel | B18: Índice de Mezcla | C18: % del Criterio
A19: ACEPTABLE | B19: < 0,50 | C19: < 50 %
A20: PRECAUCIÓN | B20: 0,50 a < 1,00 | C20: 50 % a < 100 %
A21: MODERADO | B21: 1,00 a < 2,00 | C21: 100 % a < 200 %
A22: ALTO | B22: 2,00 a < 4,00 | C22: 200 % a < 400 %
A23: EXTREMADAMENTE ALTO | B23: ≥ 4,00 | C23: ≥ 400 %
A26: Nota técnica: el Índice de Mezcla aplica la regla de mezclas de la ACGIH (Σ Ci/TLVi ≤ 1) asumiendo efectos tóxicos aditivos entre sustancias — el criterio recomendado cuando no se dispone de evidencia toxicológica de que los componentes actúan de forma independiente. Diligencie la Concentración Medida solo cuando exista monitoreo ambiental real (personal o de área); este módulo evalúa cumplimiento normativo, a diferencia del Control Banding de la hoja "VaporRisk" (columna V), que es una estimación de tamizaje previa a la medición, basada en la presión de vapor.

Sheet Proteccion Respiratoria
A1: SELECCIÓN Y EVALUACIÓN DE PROTECCIÓN RESPIRATORIA (APF)
A2: Sustancia | B2: Concentración Medida (ppm) | C2: TLV-TWA (ppm) | D2: Tipo de Respirador | E2: APF | F2: Concentración Efectiva (ppm) | G2: Evaluación
A3: =IF('Monitoreo y Mezcla'!B3="", "", 'Monitoreo y Mezcla'!B3) -> Solvente A | B3: =IF('Monitoreo y Mezcla'!D3="", "", 'Monitoreo y Mezcla'!D3) -> 1200 | C3: =IF('Monitoreo y Mezcla'!C3="", "", 'Monitoreo y Mezcla'!C3) -> 100 | D3: Media máscara con cartucho para vapores orgánicos | E3: =IFERROR(_xlfn.IFS(D3="Media máscara con cartucho para vapores orgánicos",10,D3="Máscara completa con cartucho para vapores orgánicos",50,D3="Respirador purificador de aire motorizado (PAPR) - capucha/casco",25,D3="Respirador purificador de aire motorizado (PAPR) - máscara completa",1000,D3="Línea de aire (SAR), modo demanda, máscara completa",50,D3="Línea de aire (SAR), modo presión-demanda, máscara completa",1000,D3="Equipo autónomo (SCBA), modo presión-demanda",10000), "") -> 10 | F3: =IF(OR(B3="",E3=""), "", B3/E3) -> 120 | G3: =IF(OR(F3="",C3=""), "", IF(F3<=C3, "ADECUADA", "INSUFICIENTE")) -> INSUFICIENTE
A4: =IF('Monitoreo y Mezcla'!B4="", "", 'Monitoreo y Mezcla'!B4) -> Solvente B | B4: =IF('Monitoreo y Mezcla'!D4="", "", 'Monitoreo y Mezcla'!D4) -> 85 | C4: =IF('Monitoreo y Mezcla'!C4="", "", 'Monitoreo y Mezcla'!C4) -> 50 | D4: Media máscara con cartucho para vapores orgánicos | E4: =IFERROR(_xlfn.IFS(D4="Media máscara con cartucho para vapores orgánicos",10,D4="Máscara completa con cartucho para vapores orgánicos",50,D4="Respirador purificador de aire motorizado (PAPR) - capucha/casco",25,D4="Respirador purificador de aire motorizado (PAPR) - máscara completa",1000,D4="Línea de aire (SAR), modo demanda, máscara completa",50,D4="Línea de aire (SAR), modo presión-demanda, máscara completa",1000,D4="Equipo autónomo (SCBA), modo presión-demanda",10000), "") -> 10 | F4: =IF(OR(B4="",E4=""), "", B4/E4) -> 8.5 | G4: =IF(OR(F4="",C4=""), "", IF(F4<=C4, "ADECUADA", "INSUFICIENTE")) -> ADECUADA
A5: =IF('Monitoreo y Mezcla'!B5="", "", 'Monitoreo y Mezcla'!B5) -> Solvente C | B5: =IF('Monitoreo y Mezcla'!D5="", "", 'Monitoreo y Mezcla'!D5) -> 30 | C5: =IF('Monitoreo y Mezcla'!C5="", "", 'Monitoreo y Mezcla'!C5) -> 25 | D5: Media máscara con cartucho para vapores orgánicos | E5: =IFERROR(_xlfn.IFS(D5="Media máscara con cartucho para vapores orgánicos",10,D5="Máscara completa con cartucho para vapores orgánicos",50,D5="Respirador purificador de aire motorizado (PAPR) - capucha/casco",25,D5="Respirador purificador de aire motorizado (PAPR) - máscara completa",1000,D5="Línea de aire (SAR), modo demanda, máscara completa",50,D5="Línea de aire (SAR), modo presión-demanda, máscara completa",1000,D5="Equipo autónomo (SCBA), modo presión-demanda",10000), "") -> 10 | F5: =IF(OR(B5="",E5=""), "", B5/E5) -> 3 | G5: =IF(OR(F5="",C5=""), "", IF(F5<=C5, "ADECUADA", "INSUFICIENTE")) -> ADECUADA
A6: =IF('Monitoreo y Mezcla'!B6="", "", 'Monitoreo y Mezcla'!B6) -> Resina X | B6: =IF('Monitoreo y Mezcla'!D6="", "", 'Monitoreo y Mezcla'!D6) -> 6 | C6: =IF('Monitoreo y Mezcla'!C6="", "", 'Monitoreo y Mezcla'!C6) -> 10 | D6: Media máscara con cartucho para vapores orgánicos | E6: =IFERROR(_xlfn.IFS(D6="Media máscara con cartucho para vapores orgánicos",10,D6="Máscara completa con cartucho para vapores orgánicos",50,D6="Respirador purificador de aire motorizado (PAPR) - capucha/casco",25,D6="Respirador purificador de aire motorizado (PAPR) - máscara completa",1000,D6="Línea de aire (SAR), modo demanda, máscara completa",50,D6="Línea de aire (SAR), modo presión-demanda, máscara completa",1000,D6="Equipo autónomo (SCBA), modo presión-demanda",10000), "") -> 10 | F6: =IF(OR(B6="",E6=""), "", B6/E6) -> 0.6 | G6: =IF(OR(F6="",C6=""), "", IF(F6<=C6, "ADECUADA", "INSUFICIENTE")) -> ADECUADA
A7: =IF('Monitoreo y Mezcla'!B7="", "", 'Monitoreo y Mezcla'!B7) -> Aditivo Y | B7: =IF('Monitoreo y Mezcla'!D7="", "", 'Monitoreo y Mezcla'!D7) -> 40 | C7: =IF('Monitoreo y Mezcla'!C7="", "", 'Monitoreo y Mezcla'!C7) -> 75 | D7: Media máscara con cartucho para vapores orgánicos | E7: =IFERROR(_xlfn.IFS(D7="Media máscara con cartucho para vapores orgánicos",10,D7="Máscara completa con cartucho para vapores orgánicos",50,D7="Respirador purificador de aire motorizado (PAPR) - capucha/casco",25,D7="Respirador purificador de aire motorizado (PAPR) - máscara completa",1000,D7="Línea de aire (SAR), modo demanda, máscara completa",50,D7="Línea de aire (SAR), modo presión-demanda, máscara completa",1000,D7="Equipo autónomo (SCBA), modo presión-demanda",10000), "") -> 10 | F7: =IF(OR(B7="",E7=""), "", B7/E7) -> 4 | G7: =IF(OR(F7="",C7=""), "", IF(F7<=C7, "ADECUADA", "INSUFICIENTE")) -> ADECUADA
A8: =IF('Monitoreo y Mezcla'!B8="", "", 'Monitoreo y Mezcla'!B8) -> Estabilizante Z | B8: =IF('Monitoreo y Mezcla'!D8="", "", 'Monitoreo y Mezcla'!D8) -> 70 | C8: =IF('Monitoreo y Mezcla'!C8="", "", 'Monitoreo y Mezcla'!C8) -> 150 | D8: Media máscara con cartucho para vapores orgánicos | E8: =IFERROR(_xlfn.IFS(D8="Media máscara con cartucho para vapores orgánicos",10,D8="Máscara completa con cartucho para vapores orgánicos",50,D8="Respirador purificador de aire motorizado (PAPR) - capucha/casco",25,D8="Respirador purificador de aire motorizado (PAPR) - máscara completa",1000,D8="Línea de aire (SAR), modo demanda, máscara completa",50,D8="Línea de aire (SAR), modo presión-demanda, máscara completa",1000,D8="Equipo autónomo (SCBA), modo presión-demanda",10000), "") -> 10 | F8: =IF(OR(B8="",E8=""), "", B8/E8) -> 7 | G8: =IF(OR(F8="",C8=""), "", IF(F8<=C8, "ADECUADA", "INSUFICIENTE")) -> ADECUADA
A9: =IF('Monitoreo y Mezcla'!B9="", "", 'Monitoreo y Mezcla'!B9) -> Catalizador K | B9: =IF('Monitoreo y Mezcla'!D9="", "", 'Monitoreo y Mezcla'!D9) -> 1.5 | C9: =IF('Monitoreo y Mezcla'!C9="", "", 'Monitoreo y Mezcla'!C9) -> 5 | D9: Media máscara con cartucho para vapores orgánicos | E9: =IFERROR(_xlfn.IFS(D9="Media máscara con cartucho para vapores orgánicos",10,D9="Máscara completa con cartucho para vapores orgánicos",50,D9="Respirador purificador de aire motorizado (PAPR) - capucha/casco",25,D9="Respirador purificador de aire motorizado (PAPR) - máscara completa",1000,D9="Línea de aire (SAR), modo demanda, máscara completa",50,D9="Línea de aire (SAR), modo presión-demanda, máscara completa",1000,D9="Equipo autónomo (SCBA), modo presión-demanda",10000), "") -> 10 | F9: =IF(OR(B9="",E9=""), "", B9/E9) -> 0.15 | G9: =IF(OR(F9="",C9=""), "", IF(F9<=C9, "ADECUADA", "INSUFICIENTE")) -> ADECUADA
A10: =IF('Monitoreo y Mezcla'!B10="", "", 'Monitoreo y Mezcla'!B10) -> Impureza M | B10: =IF('Monitoreo y Mezcla'!D10="", "", 'Monitoreo y Mezcla'!D10) -> 4 | C10: =IF('Monitoreo y Mezcla'!C10="", "", 'Monitoreo y Mezcla'!C10) -> 20 | D10: Media máscara con cartucho para vapores orgánicos | E10: =IFERROR(_xlfn.IFS(D10="Media máscara con cartucho para vapores orgánicos",10,D10="Máscara completa con cartucho para vapores orgánicos",50,D10="Respirador purificador de aire motorizado (PAPR) - capucha/casco",25,D10="Respirador purificador de aire motorizado (PAPR) - máscara completa",1000,D10="Línea de aire (SAR), modo demanda, máscara completa",50,D10="Línea de aire (SAR), modo presión-demanda, máscara completa",1000,D10="Equipo autónomo (SCBA), modo presión-demanda",10000), "") -> 10 | F10: =IF(OR(B10="",E10=""), "", B10/E10) -> 0.4 | G10: =IF(OR(F10="",C10=""), "", IF(F10<=C10, "ADECUADA", "INSUFICIENTE")) -> ADECUADA
A13: Tipo de Respirador | D13: APF
A14: Media máscara con cartucho para vapores orgánicos | D14: 10
A15: Máscara completa con cartucho para vapores orgánicos | D15: 50
A16: Respirador purificador de aire motorizado (PAPR) - capucha/casco | D16: 25
A17: Respirador purificador de aire motorizado (PAPR) - máscara completa | D17: 1000
A18: Línea de aire (SAR), modo demanda, máscara completa | D18: 50
A19: Línea de aire (SAR), modo presión-demanda, máscara completa | D19: 1000
A20: Equipo autónomo (SCBA), modo presión-demanda | D20: 10000
A23: Fuente: Factores de Protección Asignada (APF) según OSHA 29 CFR 1910.134, Tabla 1. La Concentración Efectiva estima la exposición residual tras el uso del respirador (Concentración Medida ÷ APF); si supera el TLV-TWA, el respirador seleccionado es insuficiente para esa sustancia y debe reevaluarse la selección (mayor APF) o priorizar el control de ingeniería. El APF es una estimación de fábrica: no reemplaza la prueba de ajuste (fit-testing) individual ni el programa de protección respiratoria documentado.

Sheet Biblioteca de Controles
A1: BIBLIOTECA DE CONTROLES (EDITABLE)
A2: Categoría | B2: Condición de Activación | C2: Recomendación
A3: Eliminación / Sustitución | B3: Índice de mezcla EXTREMADAMENTE ALTO (≥ 400 %) | C3: Evaluar sustitución del producto o de las sustancias de mayor Ratio de Riesgo por alternativas de menor volatilidad o toxicidad, o eliminar la operación si es técnicamente viable.
A4: Ingeniería — Encerramiento | B4: Alguna sustancia en Banda 3 (hoja VaporRisk, columna V) | C4: Diseñar encerramiento o aislamiento total del proceso; la extracción localizada por sí sola puede ser insuficiente para el nivel de riesgo estimado.
A5: Ingeniería — Extracción Localizada (LEV) | B5: Alguna sustancia en Banda 2 (hoja VaporRisk, columna V) | C5: Instalar o verificar el sistema de extracción localizada dimensionado en la hoja "VaporRisk" (módulo LEV, columnas AI-AP) para el punto de emisión de mayor Ratio de Riesgo.
A6: Ingeniería — Ventilación General | B6: Todas las sustancias en Banda 1 (hoja VaporRisk, columna V) | C6: Verificar que el caudal de dilución general instalado sea igual o superior al calculado en el módulo de dilución (columnas AD-AH); mantener registro de mantenimiento del sistema.
A7: Administrativo | B7: Índice de mezcla ALTO o superior (≥ 200 %) | C7: Reducir el tiempo de exposición del personal en la tarea, rotar personal entre puestos, y restringir el acceso al área mientras se implementan los controles de ingeniería.
A8: EPP — Protección Respiratoria | B8: Alguna evaluación INSUFICIENTE (hoja Proteccion Respiratoria, columna G) | C8: Seleccionar un respirador de mayor Factor de Protección Asignado (APF) para la sustancia marcada como insuficiente, según la tabla de referencia de la hoja "Proteccion Respiratoria".
A9: EPP — Programa de Protección Respiratoria | B9: Se requiere el uso de cualquier respirador | C9: Documentar el programa de protección respiratoria (selección, prueba de ajuste, capacitación, mantenimiento) conforme a la normatividad vigente.
A10: Monitoreo y Vigilancia | B10: Siempre que se evalúe una mezcla | C10: Programar monitoreo ambiental periódico (personal y/o de área) y vigilancia médica ocupacional (espirometría y demás pruebas pertinentes según las sustancias involucradas).

Sheet Plan de Control
A1: PLAN DE CONTROL AUTOMÁTICO
A2: Prioridad | B2: Categoría | C2: Recomendación
A3: Prioridad inmediata | B3: Eliminación / Sustitución | C3: =IF('Monitoreo y Mezcla'!E12>=4,'Biblioteca de Controles'!C3,"—") -> Evaluar sustitución del producto o de las sustancias de mayor Ratio de Riesgo por alternativas de menor volatilidad o toxicidad, o eliminar la operación si es técnicamente viable.
A4: Prioridad inmediata | B4: EPP — Protección Respiratoria | C4: =IF(COUNTIF('Proteccion Respiratoria'!G3:G10,"INSUFICIENTE")>0,'Biblioteca de Controles'!C8,"—") -> Seleccionar un respirador de mayor Factor de Protección Asignado (APF) para la sustancia marcada como insuficiente, según la tabla de referencia de la hoja "Proteccion Respiratoria".
A5: Nivel 1 | B5: Ingeniería — Encerramiento | C5: =IF(COUNTIF(VaporRisk!V7:V14,"Banda 3: Encerramiento")+COUNTIF(VaporRisk!V7:V14,"Banda 3: Aislamiento / HEPA")>0,'Biblioteca de Controles'!C4,"—") -> —
A6: Nivel 1 | B6: Ingeniería — Extracción Localizada (LEV) | C6: =IF(COUNTIF(VaporRisk!V7:V14,"Banda 2: Extracción Local (LEV)")>0,'Biblioteca de Controles'!C5,"—") -> Instalar o verificar el sistema de extracción localizada dimensionado en la hoja "VaporRisk" (módulo LEV, columnas AI-AP) para el punto de emisión de mayor Ratio de Riesgo.
A7: Nivel 1 | B7: Ingeniería — Ventilación General | C7: =IF(AND(COUNTIF(VaporRisk!V7:V14,"Banda 1: Dilución (ACH)")+COUNTIF(VaporRisk!V7:V14,"Banda 1: Ventilación General")>0,COUNTIF(VaporRisk!V7:V14,"Banda 2: Extracción Local (LEV)")+COUNTIF(VaporRisk!V7:V14,"Banda 3: Encerramiento")+COUNTIF(VaporRisk!V7:V14,"Banda 3: Aislamiento / HEPA")=0),'Biblioteca de Controles'!C6,"—") -> —
A8: Nivel 2 | B8: Administrativo | C8: =IF('Monitoreo y Mezcla'!E12>=2,'Biblioteca de Controles'!C7,"—") -> Reducir el tiempo de exposición del personal en la tarea, rotar personal entre puestos, y restringir el acceso al área mientras se implementan los controles de ingeniería.
A9: Nivel 3 | B9: EPP — Programa de Protección Respiratoria | C9: =IF(COUNTIF('Proteccion Respiratoria'!G3:G10,"ADECUADA")+COUNTIF('Proteccion Respiratoria'!G3:G10,"INSUFICIENTE")>0,'Biblioteca de Controles'!C9,"—") -> Documentar el programa de protección respiratoria (selección, prueba de ajuste, capacitación, mantenimiento) conforme a la normatividad vigente.
A10: Nivel 3 | B10: Monitoreo y Vigilancia | C10: ='Biblioteca de Controles'!C10 -> Programar monitoreo ambiental periódico (personal y/o de área) y vigilancia médica ocupacional (espirometría y demás pruebas pertinentes según las sustancias involucradas).
A12: Aviso: las recomendaciones del Plan de Control se generan a partir de reglas editables en la hoja "Biblioteca de Controles" y son orientativas; no sustituyen el criterio del profesional en higiene ocupacional ni la evaluación médica. Un guion (—) indica que la condición de esa fila no se cumple con los datos actuales.
